Workbook
Name BuildYear: Parameters!$B$5
Name Scenario: 'Funding Check'!$B$1

Sheet Parameters
A1: VERSION | B1: 2.1
A3: Parameter | B3: Value | D3: Link updated? | E3: No
A4: Token
A5: Year From | B5: 2023/24
A6: Api Url Root | B6: https://api.impplanner.co.uk
A7: Date Last Amended | B7: 45212
A8: Start Date | B8: 46054 | D8: Strand 2 Start Date
A9: Apprentice levy code - Teaching | B9: 675100 | D9: Finance code for Apprentice levy budget rows
A10: Apprentice levy code - Support | B10: 675110
A11: File Path - Pre 16
A12: File Path - Post 16

Sheet Notes
A1: Process Notes
A3: Updating API
A5: Step
A6: 1 | B6: Add API code to parameter tab
A28: 2 | B28: Navigate to the queries and connections in Data tab
A51: 3 | B51: This will bring up a side menu
A104: 4 | B104: Right click on the API folder and click "Refresh"
A147: 5 | B147: If the below pop-up appears please tick the "Ignore Privacy Levels" box and then click the "Save" button.
A164: 6 | B164: If the below pop-up appears please click the "Don't Update" button.
A174: Local Authorities and Schools
A176: Step
A177: 1 | B177: "LA" Column, of local authorities, needs to be updated with the code LAX with X being a count of each LA. E.g. LA0, LA1, LA2, LA3 etc.
A190: 2 | B190: London Weighting Type needs to be updated with the correct type from the drop down. This is based on the Local authority, whose weighting can be found in column "Teachers IL/OL/FRI" of the "Local Authorities - standard codes" document.
A206: #VALUE!
A250: 3 | B250: School Type needs to be updated with the correct type from the drop down. The type in the purple API section can be used but it is worth double checking them against the Funding statement as the trust may label a school as "Secondary" but it is actually a special school.
B267: Below is an extract of a funding statement which can help identify the school type by whether they have funding for Primary, KS3 and KS4
A279: Finance codes S3
A281: Step
A282: 1 | B282: Once Local authorities and Schools have been updated, you will then need to update Finance codes S3. This can be done by right clicking on the table, in tab "Finance codes S3", and clicking refresh.
A324: Staff Role Groups
A326: Step
A327: 1 | B327: The StfRoleGroup tab will need to be linked to the Strand 2 workbook. This is achieved by double clicking on the SRG query in "Queries & Connections".
A378: 2 | B378: Then double click on source and click browse.
A410: 3 | B410: This will bring up the file browser. Navigate to the strand 2 workbook in the relevant customer folder and click import.
A456: 4 | B456: Then click the save and load button
A479: 5 | B479: This should load the codes, used by the Strand 2 builder in staff role groups. This will need to be updated once the stand 2 builder has completed Staff role groups. You can do this by right clicking on the table and clicking refresh.
A510: Strand 3
A512: Step
A513: 1 | B513: To update the strand 3 tabs, navigate to the queries & connections in data
A535: 2 | B535: Navigate to the Template Prep Refresh folder
A573: 3 | B573: Right click on the folder and click refresh

Sheet Strand 3 Checklist
A1: Checklist
A2: Task | B2: Note | C2: Check
A3: Check for Month Profile Issue | C3: =SUM(MONTHPRF[Will import if zero]) -> 0
A4: Check for Calculator Issue | C4: =SUM(Calculators[Will import if 0]) -> 58
A5: Check for Statistics Issue | C5: =SUM(Statistics_import[Will Import if 0]) -> #N/A
A6: Check for Pupil Numbers Issue | C6: =SUM(Pupils_import[Will Import if 0]) -> #N/A
A7: Check for Funding Issue | C7: =SUM(Funding_import[Will Import if 0]) -> 0
A8: Check for Income Issue | C8: =SUM(Income_import[Will Import if 0]) -> #N/A
A9: Check for Expenditure Issue | C9: =SUM(Expenditure_import[Will Import if 0]) -> #N/A
A10: Check for Brought Forward Balances Issue | C10: =SUM(BF_import[Will Import if 0]) -> #N/A
A11: Check for Approved budget Issue | C11: =SUM(APBUD[Will Import if 0]) -> #N/A
A12: Check for Finance codes S3 Issue | C12: =SUM(FC_import[Will Import if 0]) -> 75
A13: Check Income built for all locations | C13: =COUNTA(SCHOOLS[SchoolCode])-COUNTA(_xlfn.UNIQUE(Income_import[SchoolCode])) -> 7
A14: Check Expenditure built for all locations | C14: =COUNTA(SCHOOLS[SchoolCode])-COUNTA(_xlfn.UNIQUE(Expenditure_import[SchoolCode])) -> 0
A15: Check Funding built for all Schools | C15: =COUNTA(SCHOOLS[SchoolCode])-COUNTA(_xlfn.UNIQUE(Funding_import[SchoolCode]))-1 -> 8
A16: Total Tab Check | C16: =SUM(C3:C11) -> #N/A
A17: Has Build Information Questions been reviewed?
A18: Refresh All Queries (twice) to update ScenarioSummary, ScenarioRows and ScenarioYearValues
A19: Has Scenario Summary been reviewed for reasonableness? | B19: Any remaining errors or unusual row/value variances
A20: Have you set up all Scenario's used in ScenarioApBud? | B20: Create scenario in planner "Scenario control"
A21: If requested, have we used month profiles? | B21: Month breakdown in budget or customer guidance on profiles
A22: Rows Missing Funds | C22: =IF(C23="Yes",COUNTBLANK(Income_import[FundCode])+COUNTBLANK(Expenditure_import[FundCode])+COUNTBLANK(BF_import[FundCode])+COUNTBLANK(APBUD[FundCode]),0) -> 0
A23: If Funds are used at Scenario Row Level then has the setting been changed on Planner? | B23: Planner - Setup - Options - SCENARIOROWFUNDS | C23: NA
A24: If Funds are used at Scenario Row Level have they been added to the budget and BFwd Balances rows? | B24: Funds column on Income, Expenditure, BF Balances and ScenarioApBud
A25: Have we completed any/all additional calcs requested by customer? | B25: Found in Build Information
A26: Have we Updated Finance code string for Levy_CALC and Levy_ALL? | B26: Create a string of finance codes used in StfRoleGroup Gross Finance code column for Levy_CALC and AnnualFTE Finance code column for LEVY_ALL.
A27: Update Finance codes used in ESFA_TOTAL, MPPFL_ADJ_CALC and ESFA_POST16_TOTAL | B27: ESFA_TOTAL should be all funding codes used for pre 16 GAG funding and ESFA_POST16_TOTAL should only be funding codes used for post 16 GAG funding. MPPFL_ADJ_CALC should be all finance codes used in pre 16 GAG funding
A28: Use Funding Check Tab to check funding statement total against budget values
A29: In ScenarioSummary Tab, Enter Customer Budget Values and check they match the scenario totals in ScenarioApBud | B29: Scenario Summary budget values. If they do not match provide reasonable explanation.
A30: Make sure the description used in Income for GAG funding has "GAG" at the start. | B30: E.g. GAG Pre 16 Funding
A31: Have we checked customers budget notes for relevant information? | B31: E.g. Pupil premium budget row has a note that it includes a recovery premium value of £5000. So we will need to make sure we have the recovery premium calculator attached to this finance code.
A32: Have we checked what has been changed since this templates version? | B32: E.g. In a later version of the template we added a calculator for MPPFL, which will need to be added to this template
A33: Have we removed unnecessary rows in the below sections?
A34: Finance codes | B34: E.g. FUNDED_KS5 but no 6th form in trust
A35: Calculators | B35: E.g. High needs calculator but no special provision
A36: Statistic's | B36: E.g. Paygrant Inner London but no schools in that area
A37: Funding | B37: E.g. Paygrant lines but no nursery/6th form/special schools
A38: Pupils | B38: E.g. PUPIL_CEN_12 but no 6th form at school.
A39: Have we updated generic titles/codes/descriptions in finance codes and calculators? | B39: E.g. Funding 01 changed to Funding Pre 16 GAG
A40: Have notes been added to Import Checklist Tab for any build specific potential import issues? | B40: Will not always be aware before import.
...

Sheet Build Checks Dashboard
A1: BUILD CHECKS DASHBOARD
A3: CONFIGURATION | F3: SUMMARY STATUS
A4: Enter school codes below. All checks will automatically include listed schools.
F5: Check | G5: Passed | H5: Failed | I5: Status
A6: School Code | B6: School Name (auto) | F6: 1. Pupil Numbers (vs FS) | G6: =COUNTIF(N40:N59,"PASS") -> 10 | H6: =COUNTIF(N40:N59,"FAIL") -> 0 | I6: =IF(H6=0,"✓ ALL PASSED","⚠ CHECK") -> ✓ ALL PASSED
A7: TLT | B7: =IF(A7="","",IFERROR(VLOOKUP(A7,Schools!K:N,4,FALSE()),"Not found")) -> Together Learning Trust | F7: 2. Pupil Totals (vs Cust) | G7: =COUNTIF(L65:L144,"PASS") -> 40 | H7: =COUNTIF(L65:L144,"FAIL") -> 0 | I7: =IF(H7=0,"✓ ALL PASSED","⚠ CHECK") -> ✓ ALL PASSED
A8: BBP | B8: =IF(A8="","",IFERROR(VLOOKUP(A8,Schools!K:N,4,FALSE()),"Not found")) -> Bolton Brow Primary Academy | F8: 3. Funding Statement | G8: =COUNTIF(H150:H169,"PASS") -> 10 | H8: =COUNTIF(H150:H169,"FAIL") -> 0 | I8: =IF(H8=0,"✓ ALL PASSED","⚠ CHECK") -> ✓ ALL PASSED
A9: LCP | B9: =IF(A9="","",IFERROR(VLOOKUP(A9,Schools!K:N,4,FALSE()),"Not found")) -> Linthwaite Clough Primary School | F9: 4. Budget Values | G9: =COUNTIF(E175:E194,"PASS") -> 10 | H9: =COUNTIF(E175:E194,"FAIL") -> 0 | I9: =IF(H9=0,"✓ ALL PASSED","⚠ CHECK") -> ✓ ALL PASSED
A10: MMP | B10: =IF(A10="","",IFERROR(VLOOKUP(A10,Schools!K:N,4,FALSE()),"Not found")) -> Meltham Moor Primary School
A11: NIN | B11: =IF(A11="","",IFERROR(VLOOKUP(A11,Schools!K:N,4,FALSE()),"Not found")) -> Netherton Infant and Nursery School
A12: SRA | B12: =IF(A12="","",IFERROR(VLOOKUP(A12,Schools!K:N,4,FALSE()),"Not found")) -> Scout Road Academy
A13: BBS | B13: =IF(A13="","",IFERROR(VLOOKUP(A13,Schools!K:N,4,FALSE()),"Not found")) -> The Brooksbank School
A14: HHS | B14: =IF(A14="","",IFERROR(VLOOKUP(A14,Schools!K:N,4,FALSE()),"Not found")) -> Honley High School
A15: RVS | B15: =IF(A15="","",IFERROR(VLOOKUP(A15,Schools!K:N,4,FALSE()),"Not found")) -> Ryburn Valley High School
A16: CHS | B16: =IF(A16="","",IFERROR(VLOOKUP(A16,Schools!K:N,4,FALSE()),"Not found")) -> Castle Hill School
B17: =IF(A17="","",IFERROR(VLOOKUP(A17,Schools!K:N,4,FALSE()),"Not found"))
B18: =IF(A18="","",IFERROR(VLOOKUP(A18,Schools!K:N,4,FALSE()),"Not found"))
B19: =IF(A19="","",IFERROR(VLOOKUP(A19,Schools!K:N,4,FALSE()),"Not found"))
B20: =IF(A20="","",IFERROR(VLOOKUP(A20,Schools!K:N,4,FALSE()),"Not found"))
B21: =IF(A21="","",IFERROR(VLOOKUP(A21,Schools!K:N,4,FALSE()),"Not found"))
B22: =IF(A22="","",IFERROR(VLOOKUP(A22,Schools!K:N,4,FALSE()),"Not found"))
B23: =IF(A23="","",IFERROR(VLOOKUP(A23,Schools!K:N,4,FALSE()),"Not found"))
B24: =IF(A24="","",IFERROR(VLOOKUP(A24,Schools!K:N,4,FALSE()),"Not found"))
B25: =IF(A25="","",IFERROR(VLOOKUP(A25,Schools!K:N,4,FALSE()),"Not found"))
B26: =IF(A26="","",IFERROR(VLOOKUP(A26,Schools!K:N,4,FALSE()),"Not found"))
A28: Finance Code Config
A29: Pre-16 Code 1 | B29: 510100
A30: Pre-16 Code 2 | B30: 510150
A31: Pre-16 Code 3
A32: Post-16 Code 1 | B32: 510700
A33: Post-16 Code 2
A34: Post-16 Code 3
A37: 1. PUPIL NUMBER CHECKS (Autumn Census 24/25 vs Funding Statement 25/26)
A39: School | B39: Pri (Cen) | C39: Pri (FS) | D39: Pri Var | E39: KS3 (Cen) | F39: KS3 (FS) | G39: KS3 Var | H39: KS4 (Cen) | I39: KS4 (FS) | J39: KS4 Var | K39: KS5 (Cen) | L39: KS5 (FS) | M39: KS5 Var | N39: Status
A40: =IF($A$7="","",$A$7) -> TLT | B40: =IF($A$7="","",SUMIFS('Pupils Insert Table'!J:J,'Pupils Insert Table'!D:D,$A$7,'Pupils Insert Table'!E:E,"PUPIL_CEN_00")+SUMIFS('Pupils Insert Table'!J:J,'Pupils Insert Table'!D:D,$A$7,'Pupils Insert Table'!E:E,"PUPIL_CEN_01")+SUMIFS('Pupils Insert Table'!J:J,'Pupils Insert Table'!D:D,$A$7,'Pupils Insert Table'!E:E,"PUPIL_CEN_02")+SUMIFS('Pupils Insert Table'!J:J,'Pupils Insert Table'!D:D,$A$7,'Pupils Insert Table'!E:E,"PUPIL_CEN_03")+SUMIFS('Pupils Insert Table'!J:J,'Pupils Insert Table'!D:D,$A$7,'Pupils Insert Table'!E:E,"PUPIL_CEN_04")+SUMIFS('Pupils Insert Table'!J:J,'Pupils Insert Table'!D:D,$A$7,'Pupils Insert Table'!E:E,"PUPIL_CEN_05")+SUMIFS('Pupils Insert Table'!J:J,'Pupils Insert Table'!D:D,$A$7,'Pupils Insert Table'!E:E,"PUPIL_CEN_06")) -> 0 | D40: =IF($A$7="","",B40-C40) -> 0 | E40: =IF($A$7="","",SUMIFS('Pupils Insert Table'!J:J,'Pupils Insert Table'!D:D,$A$7,'Pupils Insert Table'!E:E,"PUPIL_CEN_07")+SUMIFS('Pupils Insert Table'!J:J,'Pupils Insert Table'!D:D,$A$7,'Pupils Insert Table'!E:E,"PUPIL_CEN_08")+SUMIFS('Pupils Insert Table'!J:J,'Pupils Insert Table'!D:D,$A$7,'Pupils Insert Table'!E:E,"PUPIL_CEN_09")) -> 0 | G40: =IF($A$7="","",E40-F40) -> 0 | H40: =IF($A$7="","",SUMIFS('Pupils Insert Table'!J:J,'Pupils Insert Table'!D:D,$A$7,'Pupils Insert Table'!E:E,"PUPIL_CEN_10")+SUMIFS('Pupils Insert Table'!J:J,'Pupils Insert Table'!D:D,$A$7,'Pupils Insert Table'!E:E,"PUPIL_CEN_11")) -> 0 | J40: =IF($A$7="","",H40-I40) -> 0 | K40: =IF($A$7="","",SUMIFS('Pupils Insert Table'!J:J,'Pupils Insert Table'!D:D,$A$7,'Pupils Insert Table'!E:E,"PUPIL_CEN_12")+SUMIFS('Pupils Insert Table'!J:J,'Pupils Insert Table'!D:D,$A$7,'Pupils Insert Table'!E:E,"PUPIL_CEN_13")) -> 0 | M40: =IF($A$7="","",K40-L40) -> 0 | N40: =IF($A$7="","",IF(AND(ABS(D40)<=10,ABS(G40)<=10,ABS(J40)<=10,ABS(M40)<=10),"PASS","FAIL")) -> PASS
A41: =IF($A$8="","",$A$8) -> BBP | B41: =IF($A$8="","",SUMIFS('Pupils Insert Table'!J:J,'Pupils Insert Table'!D:D,$A$8,'Pupils Insert Table'!E:E,"PUPIL_CEN_00")+SUMIFS('Pupils Insert Table'!J:J,'Pupils Insert Table'!D:D,$A$8,'Pupils Insert Table'!E:E,"PUPIL_CEN_01")+SUMIFS('Pupils Insert Table'!J:J,'Pupils Insert Table'!D:D,$A$8,'Pupils Insert Table'!E:E,"PUPIL_CEN_02")+SUMIFS('Pupils Insert Table'!J:J,'Pupils Insert Table'!D:D,$A$8,'Pupils Insert Table'!E:E,"PUPIL_CEN_03")+SUMIFS('Pupils Insert Table'!J:J,'Pupils Insert Table'!D:D,$A$8,'Pupils Insert Table'!E:E,"PUPIL_CEN_04")+SUMIFS('Pupils Insert Table'!J:J,'Pupils Insert Table'!D:D,$A$8,'Pupils Insert Table'!E:E,"PUPIL_CEN_05")+SUMIFS('Pupils Insert Table'!J:J,'Pupils Insert Table'!D:D,$A$8,'Pupils Insert Table'!E:E,"PUPIL_CEN_06")) -> 0 | D41: =IF($A$8="","",B41-C41) -> 0 | E41: =IF($A$8="","",SUMIFS('Pupils Insert Table'!J:J,'Pupils Insert Table'!D:D,$A$8,'Pupils Insert Table'!E:E,"PUPIL_CEN_07")+SUMIFS('Pupils Insert Table'!J:J,'Pupils Insert Table'!D:D,$A$8,'Pupils Insert Table'!E:E,"PUPIL_CEN_08")+SUMIFS('Pupils Insert Table'!J:J,'Pupils Insert Table'!D:D,$A$8,'Pupils Insert Table'!E:E,"PUPIL_CEN_09")) -> 0 | G41: =IF($A$8="","",E41-F41) -> 0 | H41: =IF($A$8="","",SUMIFS('Pupils Insert Table'!J:J,'Pupils Insert Table'!D:D,$A$8,'Pupils Insert Table'!E:E,"PUPIL_CEN_10")+SUMIFS('Pupils Insert Table'!J:J,'Pupils Insert Table'!D:D,$A$8,'Pupils Insert Table'!E:E,"PUPIL_CEN_11")) -> 0 | J41: =IF($A$8="","",H41-I41) -> 0 | K41: =IF($A$8="","",SUMIFS('Pupils Insert Table'!J:J,'Pupils Insert Table'!D:D,$A$8,'Pupils Insert Table'!E:E,"PUPIL_CEN_12")+SUMIFS('Pupils Insert Table'!J:J,'Pupils Insert Table'!D:D,$A$8,'Pupils Insert Table'!E:E,"PUPIL_CEN_13")) -> 0 | M41: =IF($A$8="","",K41-L41) -> 0 | N41: =IF($A$8="","",IF(AND(ABS(D41)<=10,ABS(G41)<=10,ABS(J41)<=10,ABS(M41)<=10),"PASS","FAIL")) -> PASS
A42: =IF($A$9="","",$A$9) -> LCP | B42: =IF($A$9="","",SUMIFS('Pupils Insert Table'!J:J,'Pupils Insert Table'!D:D,$A$9,'Pupils Insert Table'!E:E,"PUPIL_CEN_00")+SUMIFS('Pupils Insert Table'!J:J,'Pupils Insert Table'!D:D,$A$9,'Pupils Insert Table'!E:E,"PUPIL_CEN_01")+SUMIFS('Pupils Insert Table'!J:J,'Pupils Insert Table'!D:D,$A$9,'Pupils Insert Table'!E:E,"PUPIL_CEN_02")+SUMIFS('Pupils Insert Table'!J:J,'Pupils Insert Table'!D:D,$A$9,'Pupils Insert Table'!E:E,"PUPIL_CEN_03")+SUMIFS('Pupils Insert Table'!J:J,'Pupils Insert Table'!D:D,$A$9,'Pupils Insert Table'!E:E,"PUPIL_CEN_04")+SUMIFS('Pupils Insert Table'!J:J,'Pupils Insert Table'!D:D,$A$9,'Pupils Insert Table'!E:E,"PUPIL_CEN_05")+SUMIFS('Pupils Insert Table'!J:J,'Pupils Insert Table'!D:D,$A$9,'Pupils Insert Table'!E:E,"PUPIL_CEN_06")) -> 0 | D42: =IF($A$9="","",B42-C42) -> 0 | E42: =IF($A$9="","",SUMIFS('Pupils Insert Table'!J:J,'Pupils Insert Table'!D:D,$A$9,'Pupils Insert Table'!E:E,"PUPIL_CEN_07")+SUMIFS('Pupils Insert Table'!J:J,'Pupils Insert Table'!D:D,$A$9,'Pupils Insert Table'!E:E,"PUPIL_CEN_08")+SUMIFS('Pupils Insert Table'!J:J,'Pupils Insert Table'!D:D,$A$9,'Pupils Insert Table'!E:E,"PUPIL_CEN_09")) -> 0 | G42: =IF($A$9="","",E42-F42) -> 0 | H42: =IF($A$9="","",SUMIFS('Pupils Insert Table'!J:J,'Pupils Insert Table'!D:D,$A$9,'Pupils Insert Table'!E:E,"PUPIL_CEN_10")+SUMIFS('Pupils Insert Table'!J:J,'Pupils Insert Table'!D:D,$A$9,'Pupils Insert Table'!E:E,"PUPIL_CEN_11")) -> 0 | J42: =IF($A$9="","",H42-I42) -> 0 | K42: =IF($A$9="","",SUMIFS('Pupils Insert Table'!J:J,'Pupils Insert Table'!D:D,$A$9,'Pupils Insert Table'!E:E,"PUPIL_CEN_12")+SUMIFS('Pupils Insert Table'!J:J,'Pupils Insert Table'!D:D,$A$9,'Pupils Insert Table'!E:E,"PUPIL_CEN_13")) -> 0 | M42: =IF($A$9="","",K42-L42) -> 0 | N42: =IF($A$9="","",IF(AND(ABS(D42)<=10,ABS(G42)<=10,ABS(J42)<=10,ABS(M42)<=10),"PASS","FAIL")) -> PASS
A43: =IF($A$10="","",$A$10) -> MMP | B43: =IF($A$10="","",SUMIFS('Pupils Insert Table'!J:J,'Pupils Insert Table'!D:D,$A$10,'Pupils Insert Table'!E:E,"PUPIL_CEN_00")+SUMIFS('Pupils Insert Table'!J:J,'Pupils Insert Table'!D:D,$A$10,'Pupils Insert Table'!E:E,"PUPIL_CEN_01")+SUMIFS('Pupils Insert Table'!J:J,'Pupils Insert Table'!D:D,$A$10,'Pupils Insert Table'!E:E,"PUPIL_CEN_02")+SUMIFS('Pupils Insert Table'!J:J,'Pupils Insert Table'!D:D,$A$10,'Pupils Insert Table'!E:E,"PUPIL_CEN_03")+SUMIFS('Pupils Insert Table'!J:J,'Pupils Insert Table'!D:D,$A$10,'Pupils Insert Table'!E:E,"PUPIL_CEN_04")+SUMIFS('Pupils Insert Table'!J:J,'Pupils Insert Table'!D:D,$A$10,'Pupils Insert Table'!E:E,"PUPIL_CEN_05")+SUMIFS('Pupils Insert Table'!J:J,'Pupils Insert Table'!D:D,$A$10,'Pupils Insert Table'!E:E,"PUPIL_CEN_06")) -> 0 | D43: =IF($A$10="","",B43-C43) -> 0 | E43: =IF($A$10="","",SUMIFS('Pupils Insert Table'!J:J,'Pupils Insert Table'!D:D,$A$10,'Pupils Insert Table'!E:E,"PUPIL_CEN_07")+SUMIFS('Pupils Insert Table'!J:J,'Pupils Insert Table'!D:D,$A$10,'Pupils Insert Table'!E:E,"PUPIL_CEN_08")+SUMIFS('Pupils Insert Table'!J:J,'Pupils Insert Table'!D:D,$A$10,'Pupils Insert Table'!E:E,"PUPIL_CEN_09")) -> 0 | G43: =IF($A$10="","",E43-F43) -> 0 | H43: =IF($A$10="","",SUMIFS('Pupils Insert Table'!J:J,'Pupils Insert Table'!D:D,$A$10,'Pupils Insert Table'!E:E,"PUPIL_CEN_10")+SUMIFS('Pupils Insert Table'!J:J,'Pupils Insert Table'!D:D,$A$10,'Pupils Insert Table'!E:E,"PUPIL_CEN_11")) -> 0 | J43: =IF($A$10="","",H43-I43) -> 0 | K43: =IF($A$10="","",SUMIFS('Pupils Insert Table'!J:J,'Pupils Insert Table'!D:D,$A$10,'Pupils Insert Table'!E:E,"PUPIL_CEN_12")+SUMIFS('Pupils Insert Table'!J:J,'Pupils Insert Table'!D:D,$A$10,'Pupils Insert Table'!E:E,"PUPIL_CEN_13")) -> 0 | M43: =IF($A$10="","",K43-L43) -> 0 | N43: =IF($A$10="","",IF(AND(ABS(D43)<=10,ABS(G43)<=10,ABS(J43)<=10,ABS(M43)<=10),"PASS","FAIL")) -> PASS
A44: =IF($A$11="","",$A$11) -> NIN | B44: =IF($A$11="","",SUMIFS('Pupils Insert Table'!J:J,'Pupils Insert Table'!D:D,$A$11,'Pupils Insert Table'!E:E,"PUPIL_CEN_00")+SUMIFS('Pupils Insert Table'!J:J,'Pupils Insert Table'!D:D,$A$11,'Pupils Insert Table'!E:E,"PUPIL_CEN_01")+SUMIFS('Pupils Insert Table'!J:J,'Pupils Insert Table'!D:D,$A$11,'Pupils Insert Table'!E:E,"PUPIL_CEN_02")+SUMIFS('Pupils Insert Table'!J:J,'Pupils Insert Table'!D:D,$A$11,'Pupils Insert Table'!E:E,"PUPIL_CEN_03")+SUMIFS('Pupils Insert Table'!J:J,'Pupils Insert Table'!D:D,$A$11,'Pupils Insert Table'!E:E,"PUPIL_CEN_04")+SUMIFS('Pupils Insert Table'!J:J,'Pupils Insert Table'!D:D,$A$11,'Pupils Insert Table'!E:E,"PUPIL_CEN_05")+SUMIFS('Pupils Insert Table'!J:J,'Pupils Insert Table'!D:D,$A$11,'Pupils Insert Table'!E:E,"PUPIL_CEN_06")) -> 0 | D44: =IF($A$11="","",B44-C44) -> 0 | E44: =IF($A$11="","",SUMIFS('Pupils Insert Table'!J:J,'Pupils Insert Table'!D:D,$A$11,'Pupils Insert Table'!E:E,"PUPIL_CEN_07")+SUMIFS('Pupils Insert Table'!J:J,'Pupils Insert Table'!D:D,$A$11,'Pupils Insert Table'!E:E,"PUPIL_CEN_08")+SUMIFS('Pupils Insert Table'!J:J,'Pupils Insert Table'!D:D,$A$11,'Pupils Insert Table'!E:E,"PUPIL_CEN_09")) -> 0 | G44: =IF($A$11="","",E44-F44) -> 0 | H44: =IF($A$11="","",SUMIFS('Pupils Insert Table'!J:J,'Pupils Insert Table'!D:D,$A$11,'Pupils Insert Table'!E:E,"PUPIL_CEN_10")+SUMIFS('Pupils Insert Table'!J:J,'Pupils Insert Table'!D:D,$A$11,'Pupils Insert Table'!E:E,"PUPIL_CEN_11")) -> 0 | J44: =IF($A$11="","",H44-I44) -> 0 | K44: =IF($A$11="","",SUMIFS('Pupils Insert Table'!J:J,'Pupils Insert Table'!D:D,$A$11,'Pupils Insert Table'!E:E,"PUPIL_CEN_12")+SUMIFS('Pupils Insert Table'!J:J,'Pupils Insert Table'!D:D,$A$11,'Pupils Insert Table'!E:E,"PUPIL_CEN_13")) -> 0 | M44: =IF($A$11="","",K44-L44) -> 0 | N44: =IF($A$11="","",IF(AND(ABS(D44)<=10,ABS(G44)<=10,ABS(J44)<=10,ABS(M44)<=10),"PASS","FAIL")) -> PASS
A45: =IF($A$12="","",$A$12) -> SRA | B45: =IF($A$12="","",SUMIFS('Pupils Insert Table'!J:J,'Pupils Insert Table'!D:D,$A$12,'Pupils Insert Table'!E:E,"PUPIL_CEN_00")+SUMIFS('Pupils Insert Table'!J:J,'Pupils Insert Table'!D:D,$A$12,'Pupils Insert Table'!E:E,"PUPIL_CEN_01")+SUMIFS('Pupils Insert Table'!J:J,'Pupils Insert Table'!D:D,$A$12,'Pupils Insert Table'!E:E,"PUPIL_CEN_02")+SUMIFS('Pupils Insert Table'!J:J,'Pupils Insert Table'!D:D,$A$12,'Pupils Insert Table'!E:E,"PUPIL_CEN_03")+SUMIFS('Pupils Insert Table'!J:J,'Pupils Insert Table'!D:D,$A$12,'Pupils Insert Table'!E:E,"PUPIL_CEN_04")+SUMIFS('Pupils Insert Table'!J:J,'Pupils Insert Table'!D:D,$A$12,'Pupils Insert Table'!E:E,"PUPIL_CEN_05")+SUMIFS('Pupils Insert Table'!J:J,'Pupils Insert Table'!D:D,$A$12,'Pupils Insert Table'!E:E,"PUPIL_CEN_06")) -> 0 | D45: =IF($A$12="","",B45-C45) -> 0 | E45: =IF($A$12="","",SUMIFS('Pupils Insert Table'!J:J,'Pupils Insert Table'!D:D,$A$12,'Pupils Insert Table'!E:E,"PUPIL_CEN_07")+SUMIFS('Pupils Insert Table'!J:J,'Pupils Insert Table'!D:D,$A$12,'Pupils Insert Table'!E:E,"PUPIL_CEN_08")+SUMIFS('Pupils Insert Table'!J:J,'Pupils Insert Table'!D:D,$A$12,'Pupils Insert Table'!E:E,"PUPIL_CEN_09")) -> 0 | G45: =IF($A$12="","",E45-F45) -> 0 | H45: =IF($A$12="","",SUMIFS('Pupils Insert Table'!J:J,'Pupils Insert Table'!D:D,$A$12,'Pupils Insert Table'!E:E,"PUPIL_CEN_10")+SUMIFS('Pupils Insert Table'!J:J,'Pupils Insert Table'!D:D,$A$12,'Pupils Insert Table'!E:E,"PUPIL_CEN_11")) -> 0 | J45: =IF($A$12="","",H45-I45) -> 0 | K45: =IF($A$12="","",SUMIFS('Pupils Insert Table'!J:J,'Pupils Insert Table'!D:D,$A$12,'Pupils Insert Table'!E:E,"PUPIL_CEN_12")+SUMIFS('Pupils Insert Table'!J:J,'Pupils Insert Table'!D:D,$A$12,'Pupils Insert Table'!E:E,"PUPIL_CEN_13")) -> 0 | M45: =IF($A$12="","",K45-L45) -> 0 | N45: =IF($A$12="","",IF(AND(ABS(D45)<=10,ABS(G45)<=10,ABS(J45)<=10,ABS(M45)<=10),"PASS","FAIL")) -> PASS
...

Sheet Import Checklist
A1: Checklist
A2: Task | B2: Number of Rows to Import | C2: Number of Rows Imported | D2: Import Checked | E2: LC Import Notes | F2: Builder Import Notes | G2: Importer Notes/Issues
A3: If this is not zero - return to builder | B3: =SUM('Strand 3 Checklist'!C16) -> #N/A
A4: Finance codes S3 | B4: =COUNTA(FC_import[FinanceCode]) -> 75 | D4: =IF(B4=C4,TRUE,FALSE) -> FALSE
A5: Calculators | B5: =COUNTA(Calculators[CalculatorEnabled]) -> 94 | D5: =IF(B5=C5,TRUE,FALSE) -> FALSE
A6: Month Profiles | B6: =COUNTA(MONTHPRF[Code]) -> 23 | D6: =IF(B6=C6,TRUE,FALSE) -> FALSE
A7: ScenarioRows | B7: =COUNTA(ScenarioRows[FinanceCode]) -> 58 | D7: =IF(B7=C7,TRUE,FALSE) -> FALSE
A8: ScenarioYearValue | B8: =COUNTA(ScenarioYearValues[FinanceCode]) -> 91 | D8: =IF(B8=C8,TRUE,FALSE) -> FALSE
A9: Set up Scenario for Approved Budget | D9: =IF(B9=C9,TRUE,FALSE) -> TRUE

Sheet System Grouping Codes
A1: groupingCodeCode | B1: title | C1: groupingCodeTypeCode
A2: 510100 | B2: IN: DfE Revenue Grants: GAG (not stud supp and trust grants) | C2: A
A3: 510110 | B3: IN: DfE Revenue Grants: GAG (student support) | C3: A
A4: 510120 | B4: IN: DfE Revenue Grants: GAG (start up grants) | C4: A
A5: 510130 | B5: IN: DfE Revenue Grants: Trust level grants | C5: A
A6: 510140 | B6: IN: DfE Revenue Grants: Pupil number adjustment | C6: A
A7: 510150 | B7: IN: DfE Revenue Grants: Rates reclaim | C7: A
A8: 510200 | B8: IN: DfE Revenue Grants: Pupil Premium | C8: A
A9: 510250 | B9: IN: DfE Revenue Grants: Universal Inf Free School Meals | C9: A
A10: 510300 | B10: IN: DfE Revenue Grants: Insurance top up | C10: A
A11: 510350 | B11: IN: DfE Revenue Grants: Sponsor capacity grant | C11: A
A12: 510400 | B12: IN: DfE Revenue Grants: PE & Sports grant | C12: A
... A509: ZZZ | B509: Not Applicable | C509: ZZZ

Sheet Funds
G1: API - Do not edit
A2: Code is Blank | B2: Title is Blank | C2: Enabled is blank | D2: Code length Check | E2: Title length check | F2: Will import if zero | G2: FundCode | H2: Title | I2: FundEnabled
A3: =ISBLANK(FUNDS[[#This Row],[FundCode]]) -> TRUE | B3: =ISBLANK(FUNDS[[#This Row],[Title]]) -> TRUE | C3: =ISBLANK(FUNDS[[#This Row],[FundEnabled]]) -> FALSE | D3: =IF(LEN(FUNDS[[#This Row],[FundCode]])<100,FALSE,TRUE) -> FALSE | E3: =IF(LEN(FUNDS[[#This Row],[Title]])<100,FALSE,TRUE) -> FALSE | F3: =COUNTIF(FUNDS[[#This Row],[Code is Blank]:[Title length check]],"TRUE") -> 2 | I3: TRUE

Sheet Activity
G1: API - Do not edit
A2: Code is Blank | B2: Title is Blank | C2: Code length Check | D2: Title length check | E2: Enabled is blank | F2: Will import if zero | G2: ActivityCode | H2: Title | I2: ActivityEnabled
A3: =ISBLANK(ACTIVITIES[[#This Row],[ActivityCode]]) -> TRUE | B3: =ISBLANK(ACTIVITIES[[#This Row],[Title]]) -> TRUE | C3: =IF(LEN(ACTIVITIES[[#This Row],[ActivityCode]])<100,FALSE,TRUE) -> FALSE | D3: =IF(LEN(ACTIVITIES[[#This Row],[Title]])<100,FALSE,TRUE) -> FALSE | E3: =ISBLANK(ACTIVITIES[[#This Row],[ActivityEnabled]]) -> FALSE | F3: =COUNTIF(ACTIVITIES[[#This Row],[Code is Blank]:[Enabled is blank]],"TRUE") -> 2 | I3: TRUE

Sheet Ledger
G1: API - Do not edit
A2: Code is Blank | B2: Title is Blank | C2: Enabled is blank | D2: Code length Check | E2: Title length check | F2: Will import if zero | G2: LedgerCode | H2: Title | I2: LedgerEnabled
A3: =ISBLANK(LEDGER[[#This Row],[LedgerCode]]) -> FALSE | B3: =ISBLANK(LEDGER[[#This Row],[Title]]) -> FALSE | C3: =ISBLANK(LEDGER[[#This Row],[LedgerEnabled]]) -> FALSE | D3: =IF(LEN(LEDGER[[#This Row],[LedgerCode]])<100,FALSE,TRUE) -> FALSE | E3: =IF(LEN(LEDGER[[#This Row],[Title]])<100,FALSE,TRUE) -> FALSE | F3: =COUNTIF(LEDGER[[#This Row],[Code is Blank]:[Title length check]],"TRUE") -> 0 | G3: DEFAULT | H3: Default (no) Ledger | I3: TRUE
A4: =ISBLANK(LEDGER[[#This Row],[LedgerCode]]) -> FALSE | B4: =ISBLANK(LEDGER[[#This Row],[Title]]) -> FALSE | C4: =ISBLANK(LEDGER[[#This Row],[LedgerEnabled]]) -> FALSE | D4: =IF(LEN(LEDGER[[#This Row],[LedgerCode]])<100,FALSE,TRUE) -> FALSE | E4: =IF(LEN(LEDGER[[#This Row],[Title]])<100,FALSE,TRUE) -> FALSE | F4: =COUNTIF(LEDGER[[#This Row],[Code is Blank]:[Title length check]],"TRUE") -> 0 | G4: DEPARTMENTS | H4: Departments Ledger | I4: TRUE

Sheet CustGroup
G1: API - Do not edit
A2: Code is Blank | B2: Title is Blank | C2: Code length Check | D2: Title length check | E2: Enabled is blank | F2: Will import if zero | G2: CustomGroupingCode | H2: Title | I2: CustomGroupingEnabled
A3: =ISBLANK(CUSTGROUP[[#This Row],[CustomGroupingCode]]) -> TRUE | B3: =ISBLANK(CUSTGROUP[[#This Row],[Title]]) -> TRUE | C3: =IF(LEN(CUSTGROUP[[#This Row],[CustomGroupingCode]])<100,FALSE,TRUE) -> FALSE | D3: =IF(LEN(CUSTGROUP[[#This Row],[Title]])<100,FALSE,TRUE) -> FALSE | E3: =ISBLANK(CUSTGROUP[[#This Row],[CustomGroupingEnabled]]) -> FALSE | F3: =COUNTIF(CUSTGROUP[[#This Row],[Code is Blank]:[Enabled is blank]],"TRUE") -> 2 | I3: TRUE

Sheet SchHub
G1: API - Do not edit
A2: Code is Blank | B2: Title is Blank | C2: Enabled is blank | D2: Code length Check | E2: Title length check | F2: Will import if zero | G2: SchoolHubCode | H2: Title | I2: SchoolHubEnabled
A3: =ISBLANK(SCHHUB[[#This Row],[SchoolHubCode]]) -> FALSE | B3: =ISBLANK(SCHHUB[[#This Row],[Title]]) -> FALSE | C3: =ISBLANK(SCHHUB[[#This Row],[SchoolHubEnabled]]) -> FALSE | D3: =IF(LEN(SCHHUB[[#This Row],[SchoolHubCode]])<100,FALSE,TRUE) -> FALSE | E3: =IF(LEN(SCHHUB[[#This Row],[Title]])<100,FALSE,TRUE) -> FALSE | F3: =COUNTIF(SCHHUB[[#This Row],[Code is Blank]:[Title length check]],"TRUE") -> 0 | G3: ACADEMY | H3: Academy Schools | I3: TRUE

Sheet SchType
G1: API - Do not edit
A2: Code is Blank | B2: Title is Blank | C2: Enabled is blank | D2: Code length Check | E2: Title length check | F2: Will import if zero | G2: SchoolTypeCode | H2: Title | I2: SchoolTypeEnabled
A3: =ISBLANK(SCHTYPE[[#This Row],[SchoolTypeCode]]) -> FALSE | B3: =ISBLANK(SCHTYPE[[#This Row],[Title]]) -> FALSE | C3: =ISBLANK(SCHTYPE[[#This Row],[SchoolTypeEnabled]]) -> FALSE | D3: =IF(LEN(SCHTYPE[[#This Row],[SchoolTypeCode]])<100,FALSE,TRUE) -> FALSE | E3: =IF(LEN(SCHTYPE[[#This Row],[Title]])<100,FALSE,TRUE) -> FALSE | F3: =COUNTIF(SCHTYPE[[#This Row],[Code is Blank]:[Title length check]],"TRUE") -> 0 | G3: ALLTHROUGH | H3: Allthrough | I3: TRUE
A4: =ISBLANK(SCHTYPE[[#This Row],[SchoolTypeCode]]) -> FALSE | B4: =ISBLANK(SCHTYPE[[#This Row],[Title]]) -> FALSE | C4: =ISBLANK(SCHTYPE[[#This Row],[SchoolTypeEnabled]]) -> FALSE | D4: =IF(LEN(SCHTYPE[[#This Row],[SchoolTypeCode]])<100,FALSE,TRUE) -> FALSE | E4: =IF(LEN(SCHTYPE[[#This Row],[Title]])<100,FALSE,TRUE) -> FALSE | F4: =COUNTIF(SCHTYPE[[#This Row],[Code is Blank]:[Title length check]],"TRUE") -> 0 | G4: CENTRAL | H4: Central Services | I4: TRUE
A5: =ISBLANK(SCHTYPE[[#This Row],[SchoolTypeCode]]) -> FALSE | B5: =ISBLANK(SCHTYPE[[#This Row],[Title]]) -> FALSE | C5: =ISBLANK(SCHTYPE[[#This Row],[SchoolTypeEnabled]]) -> FALSE | D5: =IF(LEN(SCHTYPE[[#This Row],[SchoolTypeCode]])<100,FALSE,TRUE) -> FALSE | E5: =IF(LEN(SCHTYPE[[#This Row],[Title]])<100,FALSE,TRUE) -> FALSE | F5: =COUNTIF(SCHTYPE[[#This Row],[Code is Blank]:[Title length check]],"TRUE") -> 0 | G5: SECONDARY | H5: Secondary | I5: TRUE

Sheet LocalAuth
G1: This grey section can be edited | H1: API - Do not edit
A2: Code is Blank | B2: Title is Blank | C2: Enabled is blank | D2: Code length Check | E2: Title length check | F2: Will import if zero | G2: LA | H2: SchoolLocalAuthorityCode | I2: Title | J2: SchoolLocalAuthorityEnabled | K2: Index
A3: =ISBLANK(LA[[#This Row],[SchoolLocalAuthorityCode]]) -> FALSE | B3: =ISBLANK(LA[[#This Row],[Title]]) -> FALSE | C3: =ISBLANK(LA[[#This Row],[SchoolLocalAuthorityEnabled]]) -> FALSE | D3: =IF(LEN(LA[[#This Row],[SchoolLocalAuthorityCode]])<100,FALSE,TRUE) -> FALSE | E3: =IF(LEN(LA[[#This Row],[Title]])<100,FALSE,TRUE) -> FALSE | F3: =COUNTIF(LA[[#This Row],[Code is Blank]:[Title length check]],"TRUE") -> 0 | G3: =IF(LA[[#This Row],[SchoolLocalAuthorityCode]]="DEFAULT","LA0","LA"&LA[[#This Row],[Index]]) -> LA1 | H3: CLD | I3: Calderdale | J3: TRUE | K3: 1
A4: =ISBLANK(LA[[#This Row],[SchoolLocalAuthorityCode]]) -> FALSE | B4: =ISBLANK(LA[[#This Row],[Title]]) -> FALSE | C4: =ISBLANK(LA[[#This Row],[SchoolLocalAuthorityEnabled]]) -> FALSE | D4: =IF(LEN(LA[[#This Row],[SchoolLocalAuthorityCode]])<100,FALSE,TRUE) -> FALSE | E4: =IF(LEN(LA[[#This Row],[Title]])<100,FALSE,TRUE) -> FALSE | F4: =COUNTIF(LA[[#This Row],[Code is Blank]:[Title length check]],"TRUE") -> 0 | G4: =IF(LA[[#This Row],[SchoolLocalAuthorityCode]]="DEFAULT","LA0","LA"&LA[[#This Row],[Index]]) -> LA0 | H4: DEFAULT | I4: Default (no) Local Authority | J4: TRUE | K4: 2
A5: =ISBLANK(LA[[#This Row],[SchoolLocalAuthorityCode]]) -> FALSE | B5: =ISBLANK(LA[[#This Row],[Title]]) -> FALSE | C5: =ISBLANK(LA[[#This Row],[SchoolLocalAuthorityEnabled]]) -> FALSE | D5: =IF(LEN(LA[[#This Row],[SchoolLocalAuthorityCode]])<100,FALSE,TRUE) -> FALSE | E5: =IF(LEN(LA[[#This Row],[Title]])<100,FALSE,TRUE) -> FALSE | F5: =COUNTIF(LA[[#This Row],[Code is Blank]:[Title length check]],"TRUE") -> 0 | G5: =IF(LA[[#This Row],[SchoolLocalAuthorityCode]]="DEFAULT","LA0","LA"&LA[[#This Row],[Index]]) -> LA3 | H5: KKL | I5: Kirklees | J5: TRUE | K5: 3

Sheet Schools
G1: This grey section can be edited | J1: API - Do not edit
A2: HubIssues | B2: SchTypeIssue | C2: Blank Data | D2: Code length Check | E2: Title length check | F2: Will Import if 0 | G2: London Weighting Type | H2: LA | I2: School Type | J2: SchoolLocalAuthority | K2: SchoolCode | L2: SchoolHub | M2: SchoolType | N2: Title | O2: LondonWeighting | P2: UniqueReferenceNumber | Q2: TeachingHours | R2: SchoolEnabled
A3: =IF(COUNTIF(SCHHUB[SchoolHubCode],SCHOOLS[[#This Row],[SchoolHub]])>0,0,1) -> 1 | B3: =IF(COUNTIF(SCHTYPE[SchoolTypeCode],SCHOOLS[[#This Row],[SchoolType]])>0,0,1) -> 0 | C3: =COUNTBLANK(SCHOOLS[[#This Row],[SchoolLocalAuthority]:[SchoolEnabled]]) -> 0 | D3: =IF(LEN(SCHOOLS[[#This Row],[SchoolCode]])<100,0,1) -> 0 | E3: =IF(LEN(SCHOOLS[[#This Row],[Title]])<100,0,1) -> 0 | F3: =SUM(SCHOOLS[[#This Row],[HubIssues]:[Title length check]]) -> 1 | H3: =_xlfn.XLOOKUP(SCHOOLS[[#This Row],[SchoolLocalAuthority]],LA[SchoolLocalAuthorityCode],LA[LA]) -> LA1 | I3: Central | J3: CLD | K3: TLT | L3: DEFAULT | M3: CENTRAL | N3: Together Learning Trust | O3: FALSE | P3: 1 | Q3: 32.5 | R3: TRUE
A4: =IF(COUNTIF(SCHHUB[SchoolHubCode],SCHOOLS[[#This Row],[SchoolHub]])>0,0,1) -> 1 | B4: =IF(COUNTIF(SCHTYPE[SchoolTypeCode],SCHOOLS[[#This Row],[SchoolType]])>0,0,1) -> 1 | C4: =COUNTBLANK(SCHOOLS[[#This Row],[SchoolLocalAuthority]:[SchoolEnabled]]) -> 0 | D4: =IF(LEN(SCHOOLS[[#This Row],[SchoolCode]])<100,0,1) -> 0 | E4: =IF(LEN(SCHOOLS[[#This Row],[Title]])<100,0,1) -> 0 | F4: =SUM(SCHOOLS[[#This Row],[HubIssues]:[Title length check]]) -> 2 | H4: =_xlfn.XLOOKUP(SCHOOLS[[#This Row],[SchoolLocalAuthority]],LA[SchoolLocalAuthorityCode],LA[LA]) -> LA1 | I4: Primary | J4: CLD | K4: BBP | L4: DEFAULT | M4: PRIMARY | N4: Bolton Brow Primary Academy | O4: FALSE | P4: 137392 | Q4: 32.5 | R4: TRUE
A5: =IF(COUNTIF(SCHHUB[SchoolHubCode],SCHOOLS[[#This Row],[SchoolHub]])>0,0,1) -> 1 | B5: =IF(COUNTIF(SCHTYPE[SchoolTypeCode],SCHOOLS[[#This Row],[SchoolType]])>0,0,1) -> 1 | C5: =COUNTBLANK(SCHOOLS[[#This Row],[SchoolLocalAuthority]:[SchoolEnabled]]) -> 0 | D5: =IF(LEN(SCHOOLS[[#This Row],[SchoolCode]])<100,0,1) -> 0 | E5: =IF(LEN(SCHOOLS[[#This Row],[Title]])<100,0,1) -> 0 | F5: =SUM(SCHOOLS[[#This Row],[HubIssues]:[Title length check]]) -> 2 | H5: =_xlfn.XLOOKUP(SCHOOLS[[#This Row],[SchoolLocalAuthority]],LA[SchoolLocalAuthorityCode],LA[LA]) -> LA3 | I5: Primary | J5: KKL | K5: LCP | L5: DEFAULT | M5: PRIMARY | N5: Linthwaite Clough Primary School | O5: FALSE | P5: 150960 | Q5: 32.5 | R5: TRUE
A6: =IF(COUNTIF(SCHHUB[SchoolHubCode],SCHOOLS[[#This Row],[SchoolHub]])>0,0,1) -> 1 | B6: =IF(COUNTIF(SCHTYPE[SchoolTypeCode],SCHOOLS[[#This Row],[SchoolType]])>0,0,1) -> 1 | C6: =COUNTBLANK(SCHOOLS[[#This Row],[SchoolLocalAuthority]:[SchoolEnabled]]) -> 0 | D6: =IF(LEN(SCHOOLS[[#This Row],[SchoolCode]])<100,0,1) -> 0 | E6: =IF(LEN(SCHOOLS[[#This Row],[Title]])<100,0,1) -> 0 | F6: =SUM(SCHOOLS[[#This Row],[HubIssues]:[Title length check]]) -> 2 | H6: =_xlfn.XLOOKUP(SCHOOLS[[#This Row],[SchoolLocalAuthority]],LA[SchoolLocalAuthorityCode],LA[LA]) -> LA3 | I6: Primary | J6: KKL | K6: MMP | L6: DEFAULT | M6: PRIMARY | N6: Meltham Moor Primary School | O6: FALSE | P6: 146890 | Q6: 32.5 | R6: TRUE
A7: =IF(COUNTIF(SCHHUB[SchoolHubCode],SCHOOLS[[#This Row],[SchoolHub]])>0,0,1) -> 1 | B7: =IF(COUNTIF(SCHTYPE[SchoolTypeCode],SCHOOLS[[#This Row],[SchoolType]])>0,0,1) -> 1 | C7: =COUNTBLANK(SCHOOLS[[#This Row],[SchoolLocalAuthority]:[SchoolEnabled]]) -> 0 | D7: =IF(LEN(SCHOOLS[[#This Row],[SchoolCode]])<100,0,1) -> 0 | E7: =IF(LEN(SCHOOLS[[#This Row],[Title]])<100,0,1) -> 0 | F7: =SUM(SCHOOLS[[#This Row],[HubIssues]:[Title length check]]) -> 2 | H7: =_xlfn.XLOOKUP(SCHOOLS[[#This Row],[SchoolLocalAuthority]],LA[SchoolLocalAuthorityCode],LA[LA]) -> LA3 | I7: Primary | J7: KKL | K7: NIN | L7: DEFAULT | M7: PRIMARY | N7: Netherton Infant and Nursery School | O7: FALSE | P7: 146861 | Q7: 32.5 | R7: TRUE
A8: =IF(COUNTIF(SCHHUB[SchoolHubCode],SCHOOLS[[#This Row],[SchoolHub]])>0,0,1) -> 1 | B8: =IF(COUNTIF(SCHTYPE[SchoolTypeCode],SCHOOLS[[#This Row],[SchoolType]])>0,0,1) -> 1 | C8: =COUNTBLANK(SCHOOLS[[#This Row],[SchoolLocalAuthority]:[SchoolEnabled]]) -> 0 | D8: =IF(LEN(SCHOOLS[[#This Row],[SchoolCode]])<100,0,1) -> 0 | E8: =IF(LEN(SCHOOLS[[#This Row],[Title]])<100,0,1) -> 0 | F8: =SUM(SCHOOLS[[#This Row],[HubIssues]:[Title length check]]) -> 2 | H8: =_xlfn.XLOOKUP(SCHOOLS[[#This Row],[SchoolLocalAuthority]],LA[SchoolLocalAuthorityCode],LA[LA]) -> LA1 | I8: Primary | J8: CLD | K8: SRA | L8: DEFAULT | M8: PRIMARY | N8: Scout Road Academy | O8: FALSE | P8: 137341 | Q8: 32.5 | R8: TRUE
A9: =IF(COUNTIF(SCHHUB[SchoolHubCode],SCHOOLS[[#This Row],[SchoolHub]])>0,0,1) -> 1 | B9: =IF(COUNTIF(SCHTYPE[SchoolTypeCode],SCHOOLS[[#This Row],[SchoolType]])>0,0,1) -> 0 | C9: =COUNTBLANK(SCHOOLS[[#This Row],[SchoolLocalAuthority]:[SchoolEnabled]]) -> 0 | D9: =IF(LEN(SCHOOLS[[#This Row],[SchoolCode]])<100,0,1) -> 0 | E9: =IF(LEN(SCHOOLS[[#This Row],[Title]])<100,0,1) -> 0 | F9: =SUM(SCHOOLS[[#This Row],[HubIssues]:[Title length check]]) -> 1 | H9: =_xlfn.XLOOKUP(SCHOOLS[[#This Row],[SchoolLocalAuthority]],LA[SchoolLocalAuthorityCode],LA[LA]) -> LA1 | I9: Secondary | J9: CLD | K9: BBS | L9: DEFAULT | M9: SECONDARY | N9: The Brooksbank School | O9: FALSE | P9: 149531 | Q9: 32.5 | R9: TRUE
A10: =IF(COUNTIF(SCHHUB[SchoolHubCode],SCHOOLS[[#This Row],[SchoolHub]])>0,0,1) -> 1 | B10: =IF(COUNTIF(SCHTYPE[SchoolTypeCode],SCHOOLS[[#This Row],[SchoolType]])>0,0,1) -> 0 | C10: =COUNTBLANK(SCHOOLS[[#This Row],[SchoolLocalAuthority]:[SchoolEnabled]]) -> 0 | D10: =IF(LEN(SCHOOLS[[#This Row],[SchoolCode]])<100,0,1) -> 0 | E10: =IF(LEN(SCHOOLS[[#This Row],[Title]])<100,0,1) -> 0 | F10: =SUM(SCHOOLS[[#This Row],[HubIssues]:[Title length check]]) -> 1 | H10: =_xlfn.XLOOKUP(SCHOOLS[[#This Row],[SchoolLocalAuthority]],LA[SchoolLocalAuthorityCode],LA[LA]) -> LA3 | I10: Secondary | J10: KKL | K10: HHS | L10: DEFAULT | M10: SECONDARY | N10: Honley High School | O10: FALSE | P10: 146906 | Q10: 32.5 | R10: TRUE
A11: =IF(COUNTIF(SCHHUB[SchoolHubCode],SCHOOLS[[#This Row],[SchoolHub]])>0,0,1) -> 1 | B11: =IF(COUNTIF(SCHTYPE[SchoolTypeCode],SCHOOLS[[#This Row],[SchoolType]])>0,0,1) -> 0 | C11: =COUNTBLANK(SCHOOLS[[#This Row],[SchoolLocalAuthority]:[SchoolEnabled]]) -> 0 | D11: =IF(LEN(SCHOOLS[[#This Row],[SchoolCode]])<100,0,1) -> 0 | E11: =IF(LEN(SCHOOLS[[#This Row],[Title]])<100,0,1) -> 0 | F11: =SUM(SCHOOLS[[#This Row],[HubIssues]:[Title length check]]) -> 1 | H11: =_xlfn.XLOOKUP(SCHOOLS[[#This Row],[SchoolLocalAuthority]],LA[SchoolLocalAuthorityCode],LA[LA]) -> LA1 | I11: Secondary | J11: CLD | K11: RVS | L11: DEFAULT | M11: SECONDARY | N11: Ryburn Valley High School | O11: FALSE | P11: 141307 | Q11: 32.5 | R11: TRUE
A12: =IF(COUNTIF(SCHHUB[SchoolHubCode],SCHOOLS[[#This Row],[SchoolHub]])>0,0,1) -> 1 | B12: =IF(COUNTIF(SCHTYPE[SchoolTypeCode],SCHOOLS[[#This Row],[SchoolType]])>0,0,1) -> 1 | C12: =COUNTBLANK(SCHOOLS[[#This Row],[SchoolLocalAuthority]:[SchoolEnabled]]) -> 0 | D12: =IF(LEN(SCHOOLS[[#This Row],[SchoolCode]])<100,0,1) -> 0 | E12: =IF(LEN(SCHOOLS[[#This Row],[Title]])<100,0,1) -> 0 | F12: =SUM(SCHOOLS[[#This Row],[HubIssues]:[Title length check]]) -> 2 | H12: =_xlfn.XLOOKUP(SCHOOLS[[#This Row],[SchoolLocalAuthority]],LA[SchoolLocalAuthorityCode],LA[LA]) -> LA3 | I12: Special | J12: KKL | K12: CHS | L12: DEFAULT | M12: SPECIAL | N12: Castle Hill School | O12: FALSE | P12: 142420 | Q12: 32.5 | R12: TRUE

Sheet Depts
G1: API - Do not edit
A2: FundIssue | B2: ActivityIssue | C2: LedgerIssue | D2: Code length Check | E2: Title length check | F2: Will Import if 0 | G2: DepartmentCode | H2: Title | I2: AvailableToAllSchools | J2: SchoolCodes | K2: ActivityCode | L2: FundCode | M2: LedgerCode | N2: DefaultFinanceCode | O2: DepartmentEnabled

Sheet 11_Finance Codes S3
A1: LedgerIssue | B1: GroupingCodeIssue | C1: CustGrIssue | D1: SchCodeIssue | E1: DupCode | F1: DupDesc | G1: FCTypeIss | H1: Code length Check | I1: Code Blank Check | J1: Title Blank Check | K1: Title length check | L1: Balance to Scenario Blank | M1: Code is Uppercase | N1: Space in Code | O1: Will Import if 0 | P1: FinanceCode | Q1: Title | R1: FinanceCodeTypeCode | S1: GroupingCode | T1: CustomGrouping | U1: LedgerCode | V1: AvailableToAllSchools | W1: SchoolCodes | X1: FinanceCodeEnabled | Y1: BalanceToScenario | Z1: IsBalanceSheet
A2: =IF(COUNTIF(LEDGER[LedgerCode],FC_import[[#This Row],[LedgerCode]])>0,0,1) -> 0 | B2: =IF(COUNTIF(Table_System_Grouping_Codes[groupingCodeCode],FC_import[[#This Row],[GroupingCode]])>0,0,1) -> 0 | C2: =IF(COUNTIF(CUSTGROUP[CustomGroupingCode],FC_import[[#This Row],[CustomGrouping]])>0,0,1) -> 1 | D2: {=IF(FC_import[[#This Row],[AvailableToAllSchools]]=TRUE,0,COUNTA(_xlfn.TEXTSPLIT(FC_import[[#This Row],[SchoolCodes]],",",,TRUE))-SUM(COUNTIF(SCHOOLS[SchoolCode],_xlfn.TEXTSPLIT(FC_import[[#This Row],[SchoolCodes]],",",,TRUE))))} -> 0 | E2: =IF(FC_import[[#This Row],[FinanceCodeTypeCode]]="BUDGET",0,COUNTIF(P:P,P2)-1) -> 0 | F2: =IF(FC_import[[#This Row],[FinanceCodeTypeCode]]="BUDGET",0,COUNTIF(Q:Q,Q2)-1) -> 0 | G2: =COUNTIF(Lookup!$A$2:$A$7,R2)-1 -> 0 | H2: =IF(LEN(FC_import[[#This Row],[FinanceCode]])<100,0,1) -> 0 | I2: =IF(TRIM(FC_import[[#This Row],[FinanceCode]])="",1,0) -> 0 | J2: =IF(TRIM(FC_import[[#This Row],[Title]])="",1,0) -> 0 | K2: =IF(LEN(FC_import[[#This Row],[Title]])<100,0,1) -> 0 | L2: =IF(ISBLANK(FC_import[[#This Row],[BalanceToScenario]]),1,0) -> 0 | M2: =IF(EXACT(FC_import[[#This Row],[FinanceCode]],UPPER(FC_import[[#This Row],[FinanceCode]])),0,1) -> 0 | N2: =IF(SUBSTITUTE(TEXT(FC_import[[#This Row],[FinanceCode]],10)," ","")=TEXT(FC_import[[#This Row],[FinanceCode]],10),0,1) -> 0 | O2: =SUM(FC_import[[#This Row],[LedgerIssue]:[CustGrIssue]],FC_import[[#This Row],[DupCode]:[Space in Code]]) -> 1 | P2: CAP_BFWD_RES | Q2: Fixed Capital Fund B/F Balances | R2: CAPITALFUND | S2: Z06 | T2: ZZZ | U2: DEFAULT | V2: TRUE | X2: TRUE | Y2: FALSE | Z2: FALSE
A3: =IF(COUNTIF(LEDGER[LedgerCode],FC_import[[#This Row],[LedgerCode]])>0,0,1) -> 0 | B3: =IF(COUNTIF(Table_System_Grouping_Codes[groupingCodeCode],FC_import[[#This Row],[GroupingCode]])>0,0,1) -> 0 | C3: =IF(COUNTIF(CUSTGROUP[CustomGroupingCode],FC_import[[#This Row],[CustomGrouping]])>0,0,1) -> 1 | D3: {=IF(FC_import[[#This Row],[AvailableToAllSchools]]=TRUE,0,COUNTA(_xlfn.TEXTSPLIT(FC_import[[#This Row],[SchoolCodes]],",",,TRUE))-SUM(COUNTIF(SCHOOLS[SchoolCode],_xlfn.TEXTSPLIT(FC_import[[#This Row],[SchoolCodes]],",",,TRUE))))} -> 0 | E3: =IF(FC_import[[#This Row],[FinanceCodeTypeCode]]="BUDGET",0,COUNTIF(P:P,P3)-1) -> 0 | F3: =IF(FC_import[[#This Row],[FinanceCodeTypeCode]]="BUDGET",0,COUNTIF(Q:Q,Q3)-1) -> 0 | G3: =COUNTIF(Lookup!$A$2:$A$7,R3)-1 -> 0 | H3: =IF(LEN(FC_import[[#This Row],[FinanceCode]])<100,0,1) -> 0 | I3: =IF(TRIM(FC_import[[#This Row],[FinanceCode]])="",1,0) -> 0 | J3: =IF(TRIM(FC_import[[#This Row],[Title]])="",1,0) -> 0 | K3: =IF(LEN(FC_import[[#This Row],[Title]])<100,0,1) -> 0 | L3: =IF(ISBLANK(FC_import[[#This Row],[BalanceToScenario]]),1,0) -> 0 | M3: =IF(EXACT(FC_import[[#This Row],[FinanceCode]],UPPER(FC_import[[#This Row],[FinanceCode]])),0,1) -> 0 | N3: =IF(SUBSTITUTE(TEXT(FC_import[[#This Row],[FinanceCode]],10)," ","")=TEXT(FC_import[[#This Row],[FinanceCode]],10),0,1) -> 0 | O3: =SUM(FC_import[[#This Row],[LedgerIssue]:[CustGrIssue]],FC_import[[#This Row],[DupCode]:[Space in Code]]) -> 1 | P3: DFC | Q3: DFC Funding | R3: FUNDING | S3: ZZZ | T3: ZZZ | U3: DEFAULT | V3: TRUE | X3: TRUE | Y3: FALSE | Z3: FALSE
A4: =IF(COUNTIF(LEDGER[LedgerCode],FC_import[[#This Row],[LedgerCode]])>0,0,1) -> 0 | B4: =IF(COUNTIF(Table_System_Grouping_Codes[groupingCodeCode],FC_import[[#This Row],[GroupingCode]])>0,0,1) -> 0 | C4: =IF(COUNTIF(CUSTGROUP[CustomGroupingCode],FC_import[[#This Row],[CustomGrouping]])>0,0,1) -> 1 | D4: {=IF(FC_import[[#This Row],[AvailableToAllSchools]]=TRUE,0,COUNTA(_xlfn.TEXTSPLIT(FC_import[[#This Row],[SchoolCodes]],",",,TRUE))-SUM(COUNTIF(SCHOOLS[SchoolCode],_xlfn.TEXTSPLIT(FC_import[[#This Row],[SchoolCodes]],",",,TRUE))))} -> 0 | E4: =IF(FC_import[[#This Row],[FinanceCodeTypeCode]]="BUDGET",0,COUNTIF(P:P,P4)-1) -> 0 | F4: =IF(FC_import[[#This Row],[FinanceCodeTypeCode]]="BUDGET",0,COUNTIF(Q:Q,Q4)-1) -> 0 | G4: =COUNTIF(Lookup!$A$2:$A$7,R4)-1 -> 0 | H4: =IF(LEN(FC_import[[#This Row],[FinanceCode]])<100,0,1) -> 0 | I4: =IF(TRIM(FC_import[[#This Row],[FinanceCode]])="",1,0) -> 0 | J4: =IF(TRIM(FC_import[[#This Row],[Title]])="",1,0) -> 0 | K4: =IF(LEN(FC_import[[#This Row],[Title]])<100,0,1) -> 0 | L4: =IF(ISBLANK(FC_import[[#This Row],[BalanceToScenario]]),1,0) -> 0 | M4: =IF(EXACT(FC_import[[#This Row],[FinanceCode]],UPPER(FC_import[[#This Row],[FinanceCode]])),0,1) -> 0 | N4: =IF(SUBSTITUTE(TEXT(FC_import[[#This Row],[FinanceCode]],10)," ","")=TEXT(FC_import[[#This Row],[FinanceCode]],10),0,1) -> 0 | O4: =SUM(FC_import[[#This Row],[LedgerIssue]:[CustGrIssue]],FC_import[[#This Row],[DupCode]:[Space in Code]]) -> 1 | P4: DFE_TOTAL | Q4: Total DFE Pre 16 Funding Statement | R4: FUNDING | S4: ZZZ | T4: ZZZ | U4: DEFAULT | V4: TRUE | X4: TRUE | Y4: FALSE | Z4: FALSE
A5: =IF(COUNTIF(LEDGER[LedgerCode],FC_import[[#This Row],[LedgerCode]])>0,0,1) -> 0 | B5: =IF(COUNTIF(Table_System_Grouping_Codes[groupingCodeCode],FC_import[[#This Row],[GroupingCode]])>0,0,1) -> 0 | C5: =IF(COUNTIF(CUSTGROUP[CustomGroupingCode],FC_import[[#This Row],[CustomGrouping]])>0,0,1) -> 1 | D5: {=IF(FC_import[[#This Row],[AvailableToAllSchools]]=TRUE,0,COUNTA(_xlfn.TEXTSPLIT(FC_import[[#This Row],[SchoolCodes]],",",,TRUE))-SUM(COUNTIF(SCHOOLS[SchoolCode],_xlfn.TEXTSPLIT(FC_import[[#This Row],[SchoolCodes]],",",,TRUE))))} -> 0 | E5: =IF(FC_import[[#This Row],[FinanceCodeTypeCode]]="BUDGET",0,COUNTIF(P:P,P5)-1) -> 0 | F5: =IF(FC_import[[#This Row],[FinanceCodeTypeCode]]="BUDGET",0,COUNTIF(Q:Q,Q5)-1) -> 0 | G5: =COUNTIF(Lookup!$A$2:$A$7,R5)-1 -> 0 | H5: =IF(LEN(FC_import[[#This Row],[FinanceCode]])<100,0,1) -> 0 | I5: =IF(TRIM(FC_import[[#This Row],[FinanceCode]])="",1,0) -> 0 | J5: =IF(TRIM(FC_import[[#This Row],[Title]])="",1,0) -> 0 | K5: =IF(LEN(FC_import[[#This Row],[Title]])<100,0,1) -> 0 | L5: =IF(ISBLANK(FC_import[[#This Row],[BalanceToScenario]]),1,0) -> 0 | M5: =IF(EXACT(FC_import[[#This Row],[FinanceCode]],UPPER(FC_import[[#This Row],[FinanceCode]])),0,1) -> 0 | N5: =IF(SUBSTITUTE(TEXT(FC_import[[#This Row],[FinanceCode]],10)," ","")=TEXT(FC_import[[#This Row],[FinanceCode]],10),0,1) -> 0 | O5: =SUM(FC_import[[#This Row],[LedgerIssue]:[CustGrIssue]],FC_import[[#This Row],[DupCode]:[Space in Code]]) -> 1 | P5: FUNDING_GAG | Q5: Funding GAG | R5: FUNDING | S5: ZZZ | T5: ZZZ | U5: DEFAULT | V5: TRUE | X5: TRUE | Y5: FALSE | Z5: FALSE
A6: =IF(COUNTIF(LEDGER[LedgerCode],FC_import[[#This Row],[LedgerCode]])>0,0,1) -> 0 | B6: =IF(COUNTIF(Table_System_Grouping_Codes[groupingCodeCode],FC_import[[#This Row],[GroupingCode]])>0,0,1) -> 0 | C6: =IF(COUNTIF(CUSTGROUP[CustomGroupingCode],FC_import[[#This Row],[CustomGrouping]])>0,0,1) -> 1 | D6: {=IF(FC_import[[#This Row],[AvailableToAllSchools]]=TRUE,0,COUNTA(_xlfn.TEXTSPLIT(FC_import[[#This Row],[SchoolCodes]],",",,TRUE))-SUM(COUNTIF(SCHOOLS[SchoolCode],_xlfn.TEXTSPLIT(FC_import[[#This Row],[SchoolCodes]],",",,TRUE))))} -> 0 | E6: =IF(FC_import[[#This Row],[FinanceCodeTypeCode]]="BUDGET",0,COUNTIF(P:P,P6)-1) -> 0 | F6: =IF(FC_import[[#This Row],[FinanceCodeTypeCode]]="BUDGET",0,COUNTIF(Q:Q,Q6)-1) -> 0 | G6: =COUNTIF(Lookup!$A$2:$A$7,R6)-1 -> 0 | H6: =IF(LEN(FC_import[[#This Row],[FinanceCode]])<100,0,1) -> 0 | I6: =IF(TRIM(FC_import[[#This Row],[FinanceCode]])="",1,0) -> 0 | J6: =IF(TRIM(FC_import[[#This Row],[Title]])="",1,0) -> 0 | K6: =IF(LEN(FC_import[[#This Row],[Title]])<100,0,1) -> 0 | L6: =IF(ISBLANK(FC_import[[#This Row],[BalanceToScenario]]),1,0) -> 0 | M6: =IF(EXACT(FC_import[[#This Row],[FinanceCode]],UPPER(FC_import[[#This Row],[FinanceCode]])),0,1) -> 0 | N6: =IF(SUBSTITUTE(TEXT(FC_import[[#This Row],[FinanceCode]],10)," ","")=TEXT(FC_import[[#This Row],[FinanceCode]],10),0,1) -> 0 | O6: =SUM(FC_import[[#This Row],[LedgerIssue]:[CustGrIssue]],FC_import[[#This Row],[DupCode]:[Space in Code]]) -> 1 | P6: FUNDING_HNPRE16 | Q6: Funding Statement Unoccupied Pre 16 Special Provision | R6: FUNDING | S6: ZZZ | T6: ZZZ | U6: DEFAULT | V6: TRUE | X6: TRUE | Y6: FALSE | Z6: FALSE
A7: =IF(COUNTIF(LEDGER[LedgerCode],FC_import[[#This Row],[LedgerCode]])>0,0,1) -> 0 | B7: =IF(COUNTIF(Table_System_Grouping_Codes[groupingCodeCode],FC_import[[#This Row],[GroupingCode]])>0,0,1) -> 0 | C7: =IF(COUNTIF(CUSTGROUP[CustomGroupingCode],FC_import[[#This Row],[CustomGrouping]])>0,0,1) -> 1 | D7: {=IF(FC_import[[#This Row],[AvailableToAllSchools]]=TRUE,0,COUNTA(_xlfn.TEXTSPLIT(FC_import[[#This Row],[SchoolCodes]],",",,TRUE))-SUM(COUNTIF(SCHOOLS[SchoolCode],_xlfn.TEXTSPLIT(FC_import[[#This Row],[SchoolCodes]],",",,TRUE))))} -> 0 | E7: =IF(FC_import[[#This Row],[FinanceCodeTypeCode]]="BUDGET",0,COUNTIF(P:P,P7)-1) -> 0 | F7: =IF(FC_import[[#This Row],[FinanceCodeTypeCode]]="BUDGET",0,COUNTIF(Q:Q,Q7)-1) -> 0 | G7: =COUNTIF(Lookup!$A$2:$A$7,R7)-1 -> 0 | H7: =IF(LEN(FC_import[[#This Row],[FinanceCode]])<100,0,1) -> 0 | I7: =IF(TRIM(FC_import[[#This Row],[FinanceCode]])="",1,0) -> 0 | J7: =IF(TRIM(FC_import[[#This Row],[Title]])="",1,0) -> 0 | K7: =IF(LEN(FC_import[[#This Row],[Title]])<100,0,1) -> 0 | L7: =IF(ISBLANK(FC_import[[#This Row],[BalanceToScenario]]),1,0) -> 0 | M7: =IF(EXACT(FC_import[[#This Row],[FinanceCode]],UPPER(FC_import[[#This Row],[FinanceCode]])),0,1) -> 0 | N7: =IF(SUBSTITUTE(TEXT(FC_import[[#This Row],[FinanceCode]],10)," ","")=TEXT(FC_import[[#This Row],[FinanceCode]],10),0,1) -> 0 | O7: =SUM(FC_import[[#This Row],[LedgerIssue]:[CustGrIssue]],FC_import[[#This Row],[DupCode]:[Space in Code]]) -> 1 | P7: FUNDING_HNPRE16O | Q7: Funding Statement Occupied Pre 16 Special Provision | R7: FUNDING | S7: ZZZ | T7: ZZZ | U7: DEFAULT | V7: TRUE | X7: TRUE | Y7: FALSE | Z7: FALSE
A8: =IF(COUNTIF(LEDGER[LedgerCode],FC_import[[#This Row],[LedgerCode]])>0,0,1) -> 0 | B8: =IF(COUNTIF(Table_System_Grouping_Codes[groupingCodeCode],FC_import[[#This Row],[GroupingCode]])>0,0,1) -> 0 | C8: =IF(COUNTIF(CUSTGROUP[CustomGroupingCode],FC_import[[#This Row],[CustomGrouping]])>0,0,1) -> 1 | D8: {=IF(FC_import[[#This Row],[AvailableToAllSchools]]=TRUE,0,COUNTA(_xlfn.TEXTSPLIT(FC_import[[#This Row],[SchoolCodes]],",",,TRUE))-SUM(COUNTIF(SCHOOLS[SchoolCode],_xlfn.TEXTSPLIT(FC_import[[#This Row],[SchoolCodes]],",",,TRUE))))} -> 0 | E8: =IF(FC_import[[#This Row],[FinanceCodeTypeCode]]="BUDGET",0,COUNTIF(P:P,P8)-1) -> 0 | F8: =IF(FC_import[[#This Row],[FinanceCodeTypeCode]]="BUDGET",0,COUNTIF(Q:Q,Q8)-1) -> 0 | G8: =COUNTIF(Lookup!$A$2:$A$7,R8)-1 -> 0 | H8: =IF(LEN(FC_import[[#This Row],[FinanceCode]])<100,0,1) -> 0 | I8: =IF(TRIM(FC_import[[#This Row],[FinanceCode]])="",1,0) -> 0 | J8: =IF(TRIM(FC_import[[#This Row],[Title]])="",1,0) -> 0 | K8: =IF(LEN(FC_import[[#This Row],[Title]])<100,0,1) -> 0 | L8: =IF(ISBLANK(FC_import[[#This Row],[BalanceToScenario]]),1,0) -> 0 | M8: =IF(EXACT(FC_import[[#This Row],[FinanceCode]],UPPER(FC_import[[#This Row],[FinanceCode]])),0,1) -> 0 | N8: =IF(SUBSTITUTE(TEXT(FC_import[[#This Row],[FinanceCode]],10)," ","")=TEXT(FC_import[[#This Row],[FinanceCode]],10),0,1) -> 0 | O8: =SUM(FC_import[[#This Row],[LedgerIssue]:[CustGrIssue]],FC_import[[#This Row],[DupCode]:[Space in Code]]) -> 1 | P8: FUNDING_PUPPREM_PLAC | Q8: Pupil Premium Post Looked After Children Income | R8: FUNDING | S8: ZZZ | T8: ZZZ | U8: DEFAULT | V8: TRUE | X8: TRUE | Y8: FALSE | Z8: FALSE
A9: =IF(COUNTIF(LEDGER[LedgerCode],FC_import[[#This Row],[LedgerCode]])>0,0,1) -> 0 | B9: =IF(COUNTIF(Table_System_Grouping_Codes[groupingCodeCode],FC_import[[#This Row],[GroupingCode]])>0,0,1) -> 0 | C9: =IF(COUNTIF(CUSTGROUP[CustomGroupingCode],FC_import[[#This Row],[CustomGrouping]])>0,0,1) -> 1 | D9: {=IF(FC_import[[#This Row],[AvailableToAllSchools]]=TRUE,0,COUNTA(_xlfn.TEXTSPLIT(FC_import[[#This Row],[SchoolCodes]],",",,TRUE))-SUM(COUNTIF(SCHOOLS[SchoolCode],_xlfn.TEXTSPLIT(FC_import[[#This Row],[SchoolCodes]],",",,TRUE))))} -> 0 | E9: =IF(FC_import[[#This Row],[FinanceCodeTypeCode]]="BUDGET",0,COUNTIF(P:P,P9)-1) -> 0 | F9: =IF(FC_import[[#This Row],[FinanceCodeTypeCode]]="BUDGET",0,COUNTIF(Q:Q,Q9)-1) -> 0 | G9: =COUNTIF(Lookup!$A$2:$A$7,R9)-1 -> 0 | H9: =IF(LEN(FC_import[[#This Row],[FinanceCode]])<100,0,1) -> 0 | I9: =IF(TRIM(FC_import[[#This Row],[FinanceCode]])="",1,0) -> 0 | J9: =IF(TRIM(FC_import[[#This Row],[Title]])="",1,0) -> 0 | K9: =IF(LEN(FC_import[[#This Row],[Title]])<100,0,1) -> 0 | L9: =IF(ISBLANK(FC_import[[#This Row],[BalanceToScenario]]),1,0) -> 0 | M9: =IF(EXACT(FC_import[[#This Row],[FinanceCode]],UPPER(FC_import[[#This Row],[FinanceCode]])),0,1) -> 0 | N9: =IF(SUBSTITUTE(TEXT(FC_import[[#This Row],[FinanceCode]],10)," ","")=TEXT(FC_import[[#This Row],[FinanceCode]],10),0,1) -> 0 | O9: =SUM(FC_import[[#This Row],[LedgerIssue]:[CustGrIssue]],FC_import[[#This Row],[DupCode]:[Space in Code]]) -> 1 | P9: FUNDING_PUPPREM_PRI | Q9: Pupil Premium Income Primary | R9: FUNDING | S9: ZZZ | T9: ZZZ | U9: DEFAULT | V9: TRUE | X9: TRUE | Y9: FALSE | Z9: FALSE
A10: =IF(COUNTIF(LEDGER[LedgerCode],FC_import[[#This Row],[LedgerCode]])>0,0,1) -> 0 | B10: =IF(COUNTIF(Table_System_Grouping_Codes[groupingCodeCode],FC_import[[#This Row],[GroupingCode]])>0,0,1) -> 0 | C10: =IF(COUNTIF(CUSTGROUP[CustomGroupingCode],FC_import[[#This Row],[CustomGrouping]])>0,0,1) -> 1 | D10: {=IF(FC_import[[#This Row],[AvailableToAllSchools]]=TRUE,0,COUNTA(_xlfn.TEXTSPLIT(FC_import[[#This Row],[SchoolCodes]],",",,TRUE))-SUM(COUNTIF(SCHOOLS[SchoolCode],_xlfn.TEXTSPLIT(FC_import[[#This Row],[SchoolCodes]],",",,TRUE))))} -> 0 | E10: =IF(FC_import[[#This Row],[FinanceCodeTypeCode]]="BUDGET",0,COUNTIF(P:P,P10)-1) -> 0 | F10: =IF(FC_import[[#This Row],[FinanceCodeTypeCode]]="BUDGET",0,COUNTIF(Q:Q,Q10)-1) -> 0 | G10: =COUNTIF(Lookup!$A$2:$A$7,R10)-1 -> 0 | H10: =IF(LEN(FC_import[[#This Row],[FinanceCode]])<100,0,1) -> 0 | I10: =IF(TRIM(FC_import[[#This Row],[FinanceCode]])="",1,0) -> 0 | J10: =IF(TRIM(FC_import[[#This Row],[Title]])="",1,0) -> 0 | K10: =IF(LEN(FC_import[[#This Row],[Title]])<100,0,1) -> 0 | L10: =IF(ISBLANK(FC_import[[#This Row],[BalanceToScenario]]),1,0) -> 0 | M10: =IF(EXACT(FC_import[[#This Row],[FinanceCode]],UPPER(FC_import[[#This Row],[FinanceCode]])),0,1) -> 0 | N10: =IF(SUBSTITUTE(TEXT(FC_import[[#This Row],[FinanceCode]],10)," ","")=TEXT(FC_import[[#This Row],[FinanceCode]],10),0,1) -> 0 | O10: =SUM(FC_import[[#This Row],[LedgerIssue]:[CustGrIssue]],FC_import[[#This Row],[DupCode]:[Space in Code]]) -> 1 | P10: FUNDING_PUPPREM_SER | Q10: Pupil Premium Service Children Income | R10: FUNDING | S10: ZZZ | T10: ZZZ | U10: DEFAULT | V10: TRUE | X10: TRUE | Y10: FALSE | Z10: FALSE
A11: =IF(COUNTIF(LEDGER[LedgerCode],FC_import[[#This Row],[LedgerCode]])>0,0,1) -> 0 | B11: =IF(COUNTIF(Table_System_Grouping_Codes[groupingCodeCode],FC_import[[#This Row],[GroupingCode]])>0,0,1) -> 0 | C11: =IF(COUNTIF(CUSTGROUP[CustomGroupingCode],FC_import[[#This Row],[CustomGrouping]])>0,0,1) -> 1 | D11: {=IF(FC_import[[#This Row],[AvailableToAllSchools]]=TRUE,0,COUNTA(_xlfn.TEXTSPLIT(FC_import[[#This Row],[SchoolCodes]],",",,TRUE))-SUM(COUNTIF(SCHOOLS[SchoolCode],_xlfn.TEXTSPLIT(FC_import[[#This Row],[SchoolCodes]],",",,TRUE))))} -> 0 | E11: =IF(FC_import[[#This Row],[FinanceCodeTypeCode]]="BUDGET",0,COUNTIF(P:P,P11)-1) -> 0 | F11: =IF(FC_import[[#This Row],[FinanceCodeTypeCode]]="BUDGET",0,COUNTIF(Q:Q,Q11)-1) -> 0 | G11: =COUNTIF(Lookup!$A$2:$A$7,R11)-1 -> 0 | H11: =IF(LEN(FC_import[[#This Row],[FinanceCode]])<100,0,1) -> 0 | I11: =IF(TRIM(FC_import[[#This Row],[FinanceCode]])="",1,0) -> 0 | J11: =IF(TRIM(FC_import[[#This Row],[Title]])="",1,0) -> 0 | K11: =IF(LEN(FC_import[[#This Row],[Title]])<100,0,1) -> 0 | L11: =IF(ISBLANK(FC_import[[#This Row],[BalanceToScenario]]),1,0) -> 0 | M11: =IF(EXACT(FC_import[[#This Row],[FinanceCode]],UPPER(FC_import[[#This Row],[FinanceCode]])),0,1) -> 0 | N11: =IF(SUBSTITUTE(TEXT(FC_import[[#This Row],[FinanceCode]],10)," ","")=TEXT(FC_import[[#This Row],[FinanceCode]],10),0,1) -> 0 | O11: =SUM(FC_import[[#This Row],[LedgerIssue]:[CustGrIssue]],FC_import[[#This Row],[DupCode]:[Space in Code]]) -> 1 | P11: PE_GRANT | Q11: PE Grant Allocation | R11: FUNDING | S11: ZZZ | T11: ZZZ | U11: DEFAULT | V11: TRUE | X11: TRUE | Y11: FALSE | Z11: FALSE
A12: =IF(COUNTIF(LEDGER[LedgerCode],FC_import[[#This Row],[LedgerCode]])>0,0,1) -> 0 | B12: =IF(COUNTIF(Table_System_Grouping_Codes[groupingCodeCode],FC_import[[#This Row],[GroupingCode]])>0,0,1) -> 0 | C12: =IF(COUNTIF(CUSTGROUP[CustomGroupingCode],FC_import[[#This Row],[CustomGrouping]])>0,0,1) -> 1 | D12: {=IF(FC_import[[#This Row],[AvailableToAllSchools]]=TRUE,0,COUNTA(_xlfn.TEXTSPLIT(FC_import[[#This Row],[SchoolCodes]],",",,TRUE))-SUM(COUNTIF(SCHOOLS[SchoolCode],_xlfn.TEXTSPLIT(FC_import[[#This Row],[SchoolCodes]],",",,TRUE))))} -> 0 | E12: =IF(FC_import[[#This Row],[FinanceCodeTypeCode]]="BUDGET",0,COUNTIF(P:P,P12)-1) -> 0 | F12: =IF(FC_import[[#This Row],[FinanceCodeTypeCode]]="BUDGET",0,COUNTIF(Q:Q,Q12)-1) -> 0 | G12: =COUNTIF(Lookup!$A$2:$A$7,R12)-1 -> 0 | H12: =IF(LEN(FC_import[[#This Row],[FinanceCode]])<100,0,1) -> 0 | I12: =IF(TRIM(FC_import[[#This Row],[FinanceCode]])="",1,0) -> 0 | J12: =IF(TRIM(FC_import[[#This Row],[Title]])="",1,0) -> 0 | K12: =IF(LEN(FC_import[[#This Row],[Title]])<100,0,1) -> 0 | L12: =IF(ISBLANK(FC_import[[#This Row],[BalanceToScenario]]),1,0) -> 0 | M12: =IF(EXACT(FC_import[[#This Row],[FinanceCode]],UPPER(FC_import[[#This Row],[FinanceCode]])),0,1) -> 0 | N12: =IF(SUBSTITUTE(TEXT(FC_import[[#This Row],[FinanceCode]],10)," ","")=TEXT(FC_import[[#This Row],[FinanceCode]],10),0,1) -> 0 | O12: =SUM(FC_import[[#This Row],[LedgerIssue]:[CustGrIssue]],FC_import[[#This Row],[DupCode]:[Space in Code]]) -> 1 | P12: UIFSM_ANNUAL | Q12: UIFSM - Annual calc | R12: FUNDING | S12: ZZZ | T12: ZZZ | U12: DEFAULT | V12: TRUE | X12: TRUE | Y12: FALSE | Z12: FALSE
A13: =IF(COUNTIF(LEDGER[LedgerCode],FC_import[[#This Row],[LedgerCode]])>0,0,1) -> 0 | B13: =IF(COUNTIF(Table_System_Grouping_Codes[groupingCodeCode],FC_import[[#This Row],[GroupingCode]])>0,0,1) -> 0 | C13: =IF(COUNTIF(CUSTGROUP[CustomGroupingCode],FC_import[[#This Row],[CustomGrouping]])>0,0,1) -> 1 | D13: {=IF(FC_import[[#This Row],[AvailableToAllSchools]]=TRUE,0,COUNTA(_xlfn.TEXTSPLIT(FC_import[[#This Row],[SchoolCodes]],",",,TRUE))-SUM(COUNTIF(SCHOOLS[SchoolCode],_xlfn.TEXTSPLIT(FC_import[[#This Row],[SchoolCodes]],",",,TRUE))))} -> 0 | E13: =IF(FC_import[[#This Row],[FinanceCodeTypeCode]]="BUDGET",0,COUNTIF(P:P,P13)-1) -> 0 | F13: =IF(FC_import[[#This Row],[FinanceCodeTypeCode]]="BUDGET",0,COUNTIF(Q:Q,Q13)-1) -> 0 | G13: =COUNTIF(Lookup!$A$2:$A$7,R13)-1 -> 0 | H13: =IF(LEN(FC_import[[#This Row],[FinanceCode]])<100,0,1) -> 0 | I13: =IF(TRIM(FC_import[[#This Row],[FinanceCode]])="",1,0) -> 0 | J13: =IF(TRIM(FC_import[[#This Row],[Title]])="",1,0) -> 0 | K13: =IF(LEN(FC_import[[#This Row],[Title]])<100,0,1) -> 0 | L13: =IF(ISBLANK(FC_import[[#This Row],[BalanceToScenario]]),1,0) -> 0 | M13: =IF(EXACT(FC_import[[#This Row],[FinanceCode]],UPPER(FC_import[[#This Row],[FinanceCode]])),0,1) -> 0 | N13: =IF(SUBSTITUTE(TEXT(FC_import[[#This Row],[FinanceCode]],10)," ","")=TEXT(FC_import[[#This Row],[FinanceCode]],10),0,1) -> 0 | O13: =SUM(FC_import[[#This Row],[LedgerIssue]:[CustGrIssue]],FC_import[[#This Row],[DupCode]:[Space in Code]]) -> 1 | P13: UIFSM_FIN | Q13: UIFSM - Final Payment | R13: FUNDING | S13: ZZZ | T13: ZZZ | U13: DEFAULT | V13: TRUE | X13: TRUE | Y13: FALSE | Z13: FALSE
