Workbook
Name BuildYear: Parameters!$B$5

Sheet Parameters
A1: VERSION | B1: 1.1
A3: Parameter | B3: Value | D3: Link updated? | E3: Yes
A4: Token | B4: eyJhbGciOiJIUzI1NiIsInR5cCI6IkpXVCJ9.eyJodHRwOi8vc2NoZW1hcy54bWxzb2FwLm9yZy93cy8yMDA1LzA1L2lkZW50aXR5L2NsYWltcy9uYW1laWRlbnRpZmllciI6IjQ1ZDA5ZmY3LWE2NjEtNDUyMy1iMmEyLTIxYWU3OGZhMjZhMSIsImh0dHA6Ly9zY2hlbWFzLnhtbHNvYXAub3JnL3dzLzIwMDUvMDUvaWRlbnRpdHkvY2xhaW1zL25hbWUiOiJDT1IwMDRAaW1wc29mdHdhcmUuY28udWsiLCJhdF9oYXNoIjoiYzg3NzNlODQtOGVjMC00ZDI4LWEzYzUtNzY1M2Y5OGY1OGNjIn0.wg1yILUA9FhHArhosCaiVtXyClwannHe7t7loxLrOCM
A5: Year From | B5: 2025/26
A6: Api Url Root | B6: https://api.impplanner.co.uk
A7: Date Last Amended | B7: 46007 | D7: update to today date (shortcut is CTRL + ;)
A9: Element | B9: Type
A10: CALCULATIONS | B10: SIMPLE

Sheet Notes
A1: Process Notes
A3: Updating API
A5: Step
A6: 1 | B6: Add API code to parameter tab
A28: 2 | B28: Navigate to the queries and connections in Data tab
A51: 3 | B51: This will bring up a side menu
A104: 4 | B104: Right click on the API folder and click "Refresh"
A147: 5 | B147: If the below pop-up appears please tick the "Ignore Privacy Levels" box and then click the "Save" button.
A164: 6 | B164: If the below pop-up appears please click the "Don't Update" button.
A174: Schools
A176: Step
A177: 1 | B177: London Weighting Type needs to be updated with the correct type from the drop down. This is based on the Local authority, whose weighting can be found in column "Teachers IL/OL/FRI" of the "Local Authorities - standard codes" document.
A193: #VALUE!

Sheet Build Checklist
A1: Checklist
A2: Task | B2: Notes | C2: Error Check
A3: Check for PayScale Issues | C3: =SUM(PAYSCALES[Will Import if 0]) -> 0
A4: Check for PayScale Point Issues | C4: =SUM(PSPOINTS[Will Import if 0]) -> 0
A5: Check for PayScale Increase % Issues | C5: =SUM(PS_INCPERC[Will Import if 0]) -> 0
A6: Check for PayScale Grades Issues | C6: =SUM(GRADES[Will Import if 0]) -> 0
A7: Check Allowance Type Issues | C7: =SUM(ALLWCTYPE[Will Import if 0]) -> 0
A8: Check Allowance Point Issues | C8: =SUM(ALLWCPTS[Will import if 0]) -> 0
A9: Check Allowance Increase % Issues | C9: =SUM(AL_INCPERC[Will Import if 0]) -> 0
A10: Check for Pensions Issues | C10: =SUM(PENS[Will import if 0]) -> 0
A11: Check for EQWP Issues | C11: =SUM(EQW[Will import if 0]) -> 0
A12: Check for Staff Members Issues | C12: =SUM(MEMBERS[Will Import if 0]) -> 0
A13: Check for Staff Role Groups Issues | C13: =SUM(SRG[Will Import if 0]) -> 0
A14: Check for Staff Roles Issues | C14: =SUM(ROLES[Will Import if 0]) -> 0
A15: Check for Contract Issues (Teacher) | C15: =SUM(CONT_TEA[Will Import if 0]) -> 336
A16: Check for Contract Issues (Support) | C16: =SUM(CONT_SUP[Will Import if 0]) -> 161
A17: Check Adjustment Type Issues | C17: =SUM(ADJTYPE[Will import if 0]) -> 0
A18: Check Contract Adjustment Issues | C18: =SUM(CONTADJ[Will import if 0]) -> 4
A19: Check Contract Allowance Issues | C19: =SUM(CONTAL[Will import if 0]) -> 0
A20: Check Leave Types Issues | C20: =SUM(LEAVES[Will Import if 0]) -> 0
A21: Check Staff Member Leaves Issues | C21: =SUM(SM_LEAVES[Will Import if 0]) -> 0
A22: Check Finance Codes S2 Issues (Ledger needed?) | C22: =SUM(FC_import[Will Import if 0]) -> 0
A23: Total Tab Check | C23: =SUM(C3:C22) -> 501
A24: Have the Scope Document info / Email Responses been reviewed? | C24: Yes
A25: Do funds need to be assigned at Scenario Row Level? (See Scope Document info) | C25: No
A26: If not standard, did we receive and check Statutory leave types? | C26: Yes
A27: Do contract effective dates match the dates provided in the Scope Document? | C27: Yes
A28: Have we built all the PayScales provided? | C28: Yes
A29: Did we build contracts for all locations? | C29: Yes
A30: Have all pension rates been supplied? | C30: Yes
A31: Do PayScales increment and increase in line with Scope Document info? | B31: Support increment on Anniversary Date | C31: Yes
A32: Are full time hours - for roles/locations - in line with Scope Document info? | C32: Yes
A33: Are notes added to Import Checklist (and against task row, this tab) to explain all 'non-errors' with an Error Check score (Col C)? | C33: NA
A34: Are there any SRG Critical Errors which will prevent successful Import? - if YES - alert LC to issue | C34: No
A35: Excluded contracts/ allowances - Do any excluded lines have budgetary impact (ie. data lines show salary / allowance cost)? | C35: No
A36: Non-Contract staffing data - Has any data been sent to Strand 3 Builder? (Check with Kim if unsure) | C36: No
A37: Review purposes - is (as at) Annual Full-Time Salary provided in the original staffing data? | B37: Except for MLB | C37: Yes
A38: Review purposes - is (as at) Actual Calculated Salary provided in the original staffing data? | B38: Except for MLB | C38: Yes
A39: Review purposes - if either (or both) Salaries in data NO, is the customer / LC already aware? | C39: Yes
A40: Review purposes - If Salaries in data YES, is this part of your Staff Contract Build Reconciliation? If not, please alert LC to any issue | C40: Yes
...

Sheet Import Checklist
A1: Checklist
A2: Task | B2: Number of Rows to Import | C2: Number of Rows Imported | D2: Import Checked | E2: LC Import Notes | F2: Builder Import Notes | G2: Importer Notes/Issues
A3: If this is not zero - return to builder | B3: =SUM('Build Checklist'!C23) -> 501
A4: Finance codes S2 | B4: =COUNTA(FC_import[FinanceCode]) -> 95 | C4: =631-536 -> 95 | D4: =IF(B4=C4,TRUE,FALSE) -> TRUE
A5: Allowance Type | B5: =COUNTA(ALLWCTYPE[AllowanceTypeCode]) -> 2 | C5: 2 | D5: =IF(B5=C5,TRUE,FALSE) -> TRUE
A6: Allowance Point | B6: =COUNTA(ALLWCPTS[AllowanceTypeCode]) -> 13 | C6: 13 | D6: =IF(B6=C6,TRUE,FALSE) -> TRUE
A7: Allowance Increase % | B7: =COUNTA(AL_INCPERC[AllowanceTypeCode]) -> 2 | C7: 2 | D7: =IF(B7=C7,TRUE,FALSE) -> TRUE
A8: Payscales | B8: =COUNTA(PAYSCALES[PayScaleEnabled]) -> 6 | C8: 6 | D8: =IF(B8=C8,TRUE,FALSE) -> TRUE
A9: Payscale Points | B9: =COUNTIF(PSPOINTS[PayScalePointEnabled],TRUE) -> 111 | C9: 111 | D9: =IF(B9=C9,TRUE,FALSE) -> TRUE
A10: Payscale Increase Percentages | B10: =COUNTA(PS_INCPERC[IncreasePercentage]) -> 5 | C10: 5 | D10: =IF(B10=C10,TRUE,FALSE) -> TRUE
A11: Payscale Grades | B11: =COUNTA(GRADES[PayScaleGradeEnabled]) -> 36 | C11: 36 | D11: =IF(B11=C11,TRUE,FALSE) -> TRUE
A12: Equated Week Patterns | B12: =COUNTA(EQW[EquatedWeekPatternEnabled]) -> 16 | C12: 16 | D12: =IF(B12=C12,TRUE,FALSE) -> TRUE
A13: Pensions | B13: =COUNTA(PENS[PensionEnabled]) -> 3 | C13: 3 | D13: =IF(B13=C13,TRUE,FALSE) -> TRUE
A14: Staff Members | B14: =COUNTA(MEMBERS[StaffMemberEnabled]) -> 829 | C14: 829 | D14: =IF(B14=C14,TRUE,FALSE) -> TRUE
A15: Staff Role Groups | B15: =COUNTA(SRG[StaffRoleGroupEnabled]) -> 15 | C15: 15 | D15: =IF(B15=C15,TRUE,FALSE) -> TRUE
A16: Staff Roles | B16: =COUNTA(ROLES[StaffRoleEnabled]) -> 101 | C16: 101 | D16: =IF(B16=C16,TRUE,FALSE) -> TRUE
A17: Contract (Teacher) | B17: =COUNTA(CONT_TEA[StaffMemberCode]) -> 337 | C17: 337 | D17: =IF(B17=C17,TRUE,FALSE) -> TRUE | E17: If Values are built as FTE - Check that you have selected FTE!
A18: Contract (Support) | B18: =COUNTA(CONT_SUP[StaffMemberCode]) -> 401 | C18: 401 | D18: =IF(B18=C18,TRUE,FALSE) -> TRUE
A19: Leave Types | B19: =COUNTA(LEAVES[LeaveTypeEnabled]) -> 33 | C19: 33 | D19: =IF(B19=C19,TRUE,FALSE) -> TRUE
A20: Adjustments | B20: =COUNTA(ADJTYPE[AdjustmentTypeCode]) -> 8 | C20: 8 | D20: =IF(B20=C20,TRUE,FALSE) -> TRUE
A21: Staff Member Leaves | B21: =COUNTA(SM_LEAVES[StaffMemberCode]) -> 10 | C21: 10 | D21: =IF(B21=C21,TRUE,FALSE) -> TRUE | E21: Imports - Maternity Start must not pre-date contract start. Import as-is for base weekly pay to calc, then manually backdate the Mat From date in Planner if needed.
A22: Contract Adjustments | B22: =COUNTA(CONTADJ[SchoolCode]) -> 82 | C22: 82 | D22: =IF(B22=C22,TRUE,FALSE) -> TRUE
A23: Contract Allowances | B23: =COUNTA(CONTAL[StaffMemberCode]) -> 100 | C23: 100 | D23: =IF(B23=C23,TRUE,FALSE) -> TRUE

Sheet System Grouping Codes
A1: groupingCodeCode | B1: title | C1: groupingCodeTypeCode
A2: 510100 | B2: IN: DfE Revenue Grants: GAG (not stud supp and trust grants) | C2: A
A3: 510110 | B3: IN: DfE Revenue Grants: GAG (student support) | C3: A
A4: 510120 | B4: IN: DfE Revenue Grants: GAG (start up grants) | C4: A
A5: 510130 | B5: IN: DfE Revenue Grants: Trust level grants | C5: A
A6: 510140 | B6: IN: DfE Revenue Grants: Pupil number adjustment | C6: A
A7: 510150 | B7: IN: DfE Revenue Grants: Rates reclaim | C7: A
A8: 510200 | B8: IN: DfE Revenue Grants: Pupil Premium | C8: A
A9: 510250 | B9: IN: DfE Revenue Grants: Universal Inf Free School Meals | C9: A
A10: 510300 | B10: IN: DfE Revenue Grants: Insurance top up | C10: A
A11: 510350 | B11: IN: DfE Revenue Grants: Sponsor capacity grant | C11: A
A12: 510400 | B12: IN: DfE Revenue Grants: PE & Sports grant | C12: A
... A509: ZZZ | B509: Not Applicable | C509: ZZZ

Sheet Funds
G1: API - Do not edit
A2: Code is Blank | B2: Title is Blank | C2: Enabled is blank | D2: Code length Check | E2: Title length check | F2: Will import if zero | G2: FundCode | H2: Title | I2: FundEnabled
A3: =ISBLANK(FUNDS[[#This Row],[FundCode]]) -> FALSE | B3: =ISBLANK(FUNDS[[#This Row],[Title]]) -> FALSE | C3: =ISBLANK(FUNDS[[#This Row],[FundEnabled]]) -> FALSE | D3: =IF(LEN(FUNDS[[#This Row],[FundCode]])<100,FALSE,TRUE) -> FALSE | E3: =IF(LEN(FUNDS[[#This Row],[Title]])<100,FALSE,TRUE) -> FALSE | F3: =COUNTIF(FUNDS[[#This Row],[Code is Blank]:[Title length check]],"TRUE") -> 0 | G3: ACT | H3: Alsager Community Trust | I3: TRUE
A4: =ISBLANK(FUNDS[[#This Row],[FundCode]]) -> FALSE | B4: =ISBLANK(FUNDS[[#This Row],[Title]]) -> FALSE | C4: =ISBLANK(FUNDS[[#This Row],[FundEnabled]]) -> FALSE | D4: =IF(LEN(FUNDS[[#This Row],[FundCode]])<100,FALSE,TRUE) -> FALSE | E4: =IF(LEN(FUNDS[[#This Row],[Title]])<100,FALSE,TRUE) -> FALSE | F4: =COUNTIF(FUNDS[[#This Row],[Code is Blank]:[Title length check]],"TRUE") -> 0 | G4: COV19 | H4: Covid Catch Up Fund | I4: TRUE
A5: =ISBLANK(FUNDS[[#This Row],[FundCode]]) -> FALSE | B5: =ISBLANK(FUNDS[[#This Row],[Title]]) -> FALSE | C5: =ISBLANK(FUNDS[[#This Row],[FundEnabled]]) -> FALSE | D5: =IF(LEN(FUNDS[[#This Row],[FundCode]])<100,FALSE,TRUE) -> FALSE | E5: =IF(LEN(FUNDS[[#This Row],[Title]])<100,FALSE,TRUE) -> FALSE | F5: =COUNTIF(FUNDS[[#This Row],[Code is Blank]:[Title length check]],"TRUE") -> 0 | G5: DEFAULT | H5: Default (no) Fund | I5: TRUE
A6: =ISBLANK(FUNDS[[#This Row],[FundCode]]) -> FALSE | B6: =ISBLANK(FUNDS[[#This Row],[Title]]) -> FALSE | C6: =ISBLANK(FUNDS[[#This Row],[FundEnabled]]) -> FALSE | D6: =IF(LEN(FUNDS[[#This Row],[FundCode]])<100,FALSE,TRUE) -> FALSE | E6: =IF(LEN(FUNDS[[#This Row],[Title]])<100,FALSE,TRUE) -> FALSE | F6: =COUNTIF(FUNDS[[#This Row],[Code is Blank]:[Title length check]],"TRUE") -> 0 | G6: DESF | H6: Designated Funds | I6: TRUE
A7: =ISBLANK(FUNDS[[#This Row],[FundCode]]) -> FALSE | B7: =ISBLANK(FUNDS[[#This Row],[Title]]) -> FALSE | C7: =ISBLANK(FUNDS[[#This Row],[FundEnabled]]) -> FALSE | D7: =IF(LEN(FUNDS[[#This Row],[FundCode]])<100,FALSE,TRUE) -> FALSE | E7: =IF(LEN(FUNDS[[#This Row],[Title]])<100,FALSE,TRUE) -> FALSE | F7: =COUNTIF(FUNDS[[#This Row],[Code is Blank]:[Title length check]],"TRUE") -> 0 | G7: GAG | H7: General Annual Grant | I7: TRUE
A8: =ISBLANK(FUNDS[[#This Row],[FundCode]]) -> FALSE | B8: =ISBLANK(FUNDS[[#This Row],[Title]]) -> FALSE | C8: =ISBLANK(FUNDS[[#This Row],[FundEnabled]]) -> FALSE | D8: =IF(LEN(FUNDS[[#This Row],[FundCode]])<100,FALSE,TRUE) -> FALSE | E8: =IF(LEN(FUNDS[[#This Row],[Title]])<100,FALSE,TRUE) -> FALSE | F8: =COUNTIF(FUNDS[[#This Row],[Code is Blank]:[Title length check]],"TRUE") -> 0 | G8: HUB | H8: Maths HUB | I8: TRUE
A9: =ISBLANK(FUNDS[[#This Row],[FundCode]]) -> FALSE | B9: =ISBLANK(FUNDS[[#This Row],[Title]]) -> FALSE | C9: =ISBLANK(FUNDS[[#This Row],[FundEnabled]]) -> FALSE | D9: =IF(LEN(FUNDS[[#This Row],[FundCode]])<100,FALSE,TRUE) -> FALSE | E9: =IF(LEN(FUNDS[[#This Row],[Title]])<100,FALSE,TRUE) -> FALSE | F9: =COUNTIF(FUNDS[[#This Row],[Code is Blank]:[Title length check]],"TRUE") -> 0 | G9: OTHINC | H9: Other Income | I9: TRUE
A10: =ISBLANK(FUNDS[[#This Row],[FundCode]]) -> FALSE | B10: =ISBLANK(FUNDS[[#This Row],[Title]]) -> FALSE | C10: =ISBLANK(FUNDS[[#This Row],[FundEnabled]]) -> FALSE | D10: =IF(LEN(FUNDS[[#This Row],[FundCode]])<100,FALSE,TRUE) -> FALSE | E10: =IF(LEN(FUNDS[[#This Row],[Title]])<100,FALSE,TRUE) -> FALSE | F10: =COUNTIF(FUNDS[[#This Row],[Code is Blank]:[Title length check]],"TRUE") -> 0 | G10: PPREM | H10: Pupil Premium | I10: TRUE
A11: =ISBLANK(FUNDS[[#This Row],[FundCode]]) -> FALSE | B11: =ISBLANK(FUNDS[[#This Row],[Title]]) -> FALSE | C11: =ISBLANK(FUNDS[[#This Row],[FundEnabled]]) -> FALSE | D11: =IF(LEN(FUNDS[[#This Row],[FundCode]])<100,FALSE,TRUE) -> FALSE | E11: =IF(LEN(FUNDS[[#This Row],[Title]])<100,FALSE,TRUE) -> FALSE | F11: =COUNTIF(FUNDS[[#This Row],[Code is Blank]:[Title length check]],"TRUE") -> 0 | G11: REST | H11: Restricted Fund | I11: TRUE
A12: =ISBLANK(FUNDS[[#This Row],[FundCode]]) -> FALSE | B12: =ISBLANK(FUNDS[[#This Row],[Title]]) -> FALSE | C12: =ISBLANK(FUNDS[[#This Row],[FundEnabled]]) -> FALSE | D12: =IF(LEN(FUNDS[[#This Row],[FundCode]])<100,FALSE,TRUE) -> FALSE | E12: =IF(LEN(FUNDS[[#This Row],[Title]])<100,FALSE,TRUE) -> FALSE | F12: =COUNTIF(FUNDS[[#This Row],[Code is Blank]:[Title length check]],"TRUE") -> 0 | G12: RESTFA | H12: Restricted Fixed Asset | I12: TRUE
A13: =ISBLANK(FUNDS[[#This Row],[FundCode]]) -> FALSE | B13: =ISBLANK(FUNDS[[#This Row],[Title]]) -> FALSE | C13: =ISBLANK(FUNDS[[#This Row],[FundEnabled]]) -> FALSE | D13: =IF(LEN(FUNDS[[#This Row],[FundCode]])<100,FALSE,TRUE) -> FALSE | E13: =IF(LEN(FUNDS[[#This Row],[Title]])<100,FALSE,TRUE) -> FALSE | F13: =COUNTIF(FUNDS[[#This Row],[Code is Blank]:[Title length check]],"TRUE") -> 0 | G13: UNRF | H13: Unrestricted Fund | I13: TRUE

Sheet Activity
G1: API - Do not edit
A2: Code is Blank | B2: Title is Blank | C2: Code length Check | D2: Title length check | E2: Enabled is blank | F2: Will import if zero | G2: ActivityCode | H2: Title | I2: ActivityEnabled
A3: =ISBLANK(ACTIVITIES[[#This Row],[ActivityCode]]) -> FALSE | B3: =ISBLANK(ACTIVITIES[[#This Row],[Title]]) -> FALSE | C3: =IF(LEN(ACTIVITIES[[#This Row],[ActivityCode]])<100,FALSE,TRUE) -> FALSE | D3: =IF(LEN(ACTIVITIES[[#This Row],[Title]])<100,FALSE,TRUE) -> FALSE | E3: =ISBLANK(ACTIVITIES[[#This Row],[ActivityEnabled]]) -> FALSE | F3: =COUNTIF(ACTIVITIES[[#This Row],[Code is Blank]:[Enabled is blank]],"TRUE") -> 0 | G3: COMM | H3: Community | I3: TRUE
A4: =ISBLANK(ACTIVITIES[[#This Row],[ActivityCode]]) -> FALSE | B4: =ISBLANK(ACTIVITIES[[#This Row],[Title]]) -> FALSE | C4: =IF(LEN(ACTIVITIES[[#This Row],[ActivityCode]])<100,FALSE,TRUE) -> FALSE | D4: =IF(LEN(ACTIVITIES[[#This Row],[Title]])<100,FALSE,TRUE) -> FALSE | E4: =ISBLANK(ACTIVITIES[[#This Row],[ActivityEnabled]]) -> FALSE | F4: =COUNTIF(ACTIVITIES[[#This Row],[Code is Blank]:[Enabled is blank]],"TRUE") -> 0 | G4: DEFAULT | H4: Default (no) Activity | I4: TRUE
A5: =ISBLANK(ACTIVITIES[[#This Row],[ActivityCode]]) -> FALSE | B5: =ISBLANK(ACTIVITIES[[#This Row],[Title]]) -> FALSE | C5: =IF(LEN(ACTIVITIES[[#This Row],[ActivityCode]])<100,FALSE,TRUE) -> FALSE | D5: =IF(LEN(ACTIVITIES[[#This Row],[Title]])<100,FALSE,TRUE) -> FALSE | E5: =ISBLANK(ACTIVITIES[[#This Row],[ActivityEnabled]]) -> FALSE | F5: =COUNTIF(ACTIVITIES[[#This Row],[Code is Blank]:[Enabled is blank]],"TRUE") -> 0 | G5: EXTENDED | H5: Extended | I5: TRUE
A6: =ISBLANK(ACTIVITIES[[#This Row],[ActivityCode]]) -> FALSE | B6: =ISBLANK(ACTIVITIES[[#This Row],[Title]]) -> FALSE | C6: =IF(LEN(ACTIVITIES[[#This Row],[ActivityCode]])<100,FALSE,TRUE) -> FALSE | D6: =IF(LEN(ACTIVITIES[[#This Row],[Title]])<100,FALSE,TRUE) -> FALSE | E6: =ISBLANK(ACTIVITIES[[#This Row],[ActivityEnabled]]) -> FALSE | F6: =COUNTIF(ACTIVITIES[[#This Row],[Code is Blank]:[Enabled is blank]],"TRUE") -> 0 | G6: LETTINGS | H6: Lettings | I6: TRUE
A7: =ISBLANK(ACTIVITIES[[#This Row],[ActivityCode]]) -> FALSE | B7: =ISBLANK(ACTIVITIES[[#This Row],[Title]]) -> FALSE | C7: =IF(LEN(ACTIVITIES[[#This Row],[ActivityCode]])<100,FALSE,TRUE) -> FALSE | D7: =IF(LEN(ACTIVITIES[[#This Row],[Title]])<100,FALSE,TRUE) -> FALSE | E7: =ISBLANK(ACTIVITIES[[#This Row],[ActivityEnabled]]) -> FALSE | F7: =COUNTIF(ACTIVITIES[[#This Row],[Code is Blank]:[Enabled is blank]],"TRUE") -> 0 | G7: MATHS | H7: Maths Hub | I7: TRUE
A8: =ISBLANK(ACTIVITIES[[#This Row],[ActivityCode]]) -> FALSE | B8: =ISBLANK(ACTIVITIES[[#This Row],[Title]]) -> FALSE | C8: =IF(LEN(ACTIVITIES[[#This Row],[ActivityCode]])<100,FALSE,TRUE) -> FALSE | D8: =IF(LEN(ACTIVITIES[[#This Row],[Title]])<100,FALSE,TRUE) -> FALSE | E8: =ISBLANK(ACTIVITIES[[#This Row],[ActivityEnabled]]) -> FALSE | F8: =COUNTIF(ACTIVITIES[[#This Row],[Code is Blank]:[Enabled is blank]],"TRUE") -> 0 | G8: NURSERY | H8: Nursery | I8: TRUE
A9: =ISBLANK(ACTIVITIES[[#This Row],[ActivityCode]]) -> FALSE | B9: =ISBLANK(ACTIVITIES[[#This Row],[Title]]) -> FALSE | C9: =IF(LEN(ACTIVITIES[[#This Row],[ActivityCode]])<100,FALSE,TRUE) -> FALSE | D9: =IF(LEN(ACTIVITIES[[#This Row],[Title]])<100,FALSE,TRUE) -> FALSE | E9: =ISBLANK(ACTIVITIES[[#This Row],[ActivityEnabled]]) -> FALSE | F9: =COUNTIF(ACTIVITIES[[#This Row],[Code is Blank]:[Enabled is blank]],"TRUE") -> 0 | G9: SCHFUND | H9: School Fund | I9: TRUE
A10: =ISBLANK(ACTIVITIES[[#This Row],[ActivityCode]]) -> FALSE | B10: =ISBLANK(ACTIVITIES[[#This Row],[Title]]) -> FALSE | C10: =IF(LEN(ACTIVITIES[[#This Row],[ActivityCode]])<100,FALSE,TRUE) -> FALSE | D10: =IF(LEN(ACTIVITIES[[#This Row],[Title]])<100,FALSE,TRUE) -> FALSE | E10: =ISBLANK(ACTIVITIES[[#This Row],[ActivityEnabled]]) -> FALSE | F10: =COUNTIF(ACTIVITIES[[#This Row],[Code is Blank]:[Enabled is blank]],"TRUE") -> 0 | G10: SCHOOL | H10: School | I10: TRUE

Sheet Ledger
G1: API - Do not edit
A2: Code is Blank | B2: Title is Blank | C2: Enabled is blank | D2: Code length Check | E2: Title length check | F2: Will import if zero | G2: LedgerCode | H2: Title | I2: LedgerEnabled
A3: =ISBLANK(LEDGER[[#This Row],[LedgerCode]]) -> FALSE | B3: =ISBLANK(LEDGER[[#This Row],[Title]]) -> FALSE | C3: =ISBLANK(LEDGER[[#This Row],[LedgerEnabled]]) -> FALSE | D3: =IF(LEN(LEDGER[[#This Row],[LedgerCode]])<100,FALSE,TRUE) -> FALSE | E3: =IF(LEN(LEDGER[[#This Row],[Title]])<100,FALSE,TRUE) -> FALSE | F3: =COUNTIF(LEDGER[[#This Row],[Code is Blank]:[Title length check]],"TRUE") -> 0 | G3: CAPITAL | H3: CAPITAL | I3: TRUE
A4: =ISBLANK(LEDGER[[#This Row],[LedgerCode]]) -> FALSE | B4: =ISBLANK(LEDGER[[#This Row],[Title]]) -> FALSE | C4: =ISBLANK(LEDGER[[#This Row],[LedgerEnabled]]) -> FALSE | D4: =IF(LEN(LEDGER[[#This Row],[LedgerCode]])<100,FALSE,TRUE) -> FALSE | E4: =IF(LEN(LEDGER[[#This Row],[Title]])<100,FALSE,TRUE) -> FALSE | F4: =COUNTIF(LEDGER[[#This Row],[Code is Blank]:[Title length check]],"TRUE") -> 0 | G4: COSTCENTRES | H4: COSTCENTRES | I4: TRUE
A5: =ISBLANK(LEDGER[[#This Row],[LedgerCode]]) -> FALSE | B5: =ISBLANK(LEDGER[[#This Row],[Title]]) -> FALSE | C5: =ISBLANK(LEDGER[[#This Row],[LedgerEnabled]]) -> FALSE | D5: =IF(LEN(LEDGER[[#This Row],[LedgerCode]])<100,FALSE,TRUE) -> FALSE | E5: =IF(LEN(LEDGER[[#This Row],[Title]])<100,FALSE,TRUE) -> FALSE | F5: =COUNTIF(LEDGER[[#This Row],[Code is Blank]:[Title length check]],"TRUE") -> 0 | G5: COSTCTR | H5: COSTCTR | I5: TRUE
A6: =ISBLANK(LEDGER[[#This Row],[LedgerCode]]) -> FALSE | B6: =ISBLANK(LEDGER[[#This Row],[Title]]) -> FALSE | C6: =ISBLANK(LEDGER[[#This Row],[LedgerEnabled]]) -> FALSE | D6: =IF(LEN(LEDGER[[#This Row],[LedgerCode]])<100,FALSE,TRUE) -> FALSE | E6: =IF(LEN(LEDGER[[#This Row],[Title]])<100,FALSE,TRUE) -> FALSE | F6: =COUNTIF(LEDGER[[#This Row],[Code is Blank]:[Title length check]],"TRUE") -> 0 | G6: DEFAULT | H6: Default (no) Ledger | I6: TRUE
A7: =ISBLANK(LEDGER[[#This Row],[LedgerCode]]) -> FALSE | B7: =ISBLANK(LEDGER[[#This Row],[Title]]) -> FALSE | C7: =ISBLANK(LEDGER[[#This Row],[LedgerEnabled]]) -> FALSE | D7: =IF(LEN(LEDGER[[#This Row],[LedgerCode]])<100,FALSE,TRUE) -> FALSE | E7: =IF(LEN(LEDGER[[#This Row],[Title]])<100,FALSE,TRUE) -> FALSE | F7: =COUNTIF(LEDGER[[#This Row],[Code is Blank]:[Title length check]],"TRUE") -> 0 | G7: SALARY | H7: SALARY | I7: TRUE
A8: =ISBLANK(LEDGER[[#This Row],[LedgerCode]]) -> FALSE | B8: =ISBLANK(LEDGER[[#This Row],[Title]]) -> FALSE | C8: =ISBLANK(LEDGER[[#This Row],[LedgerEnabled]]) -> FALSE | D8: =IF(LEN(LEDGER[[#This Row],[LedgerCode]])<100,FALSE,TRUE) -> FALSE | E8: =IF(LEN(LEDGER[[#This Row],[Title]])<100,FALSE,TRUE) -> FALSE | F8: =COUNTIF(LEDGER[[#This Row],[Code is Blank]:[Title length check]],"TRUE") -> 0 | G8: TRIPS | H8: TRIPS | I8: TRUE

Sheet CustGroup
G1: API - Do not edit
A2: Code is Blank | B2: Title is Blank | C2: Code length Check | D2: Title length check | E2: Enabled is blank | F2: Will import if zero | G2: CustomGroupingCode | H2: Title | I2: CustomGroupingEnabled
A3: =ISBLANK(CUSTGROUP[[#This Row],[CustomGroupingCode]]) -> FALSE | B3: =ISBLANK(CUSTGROUP[[#This Row],[Title]]) -> FALSE | C3: =IF(LEN(CUSTGROUP[[#This Row],[CustomGroupingCode]])<100,FALSE,TRUE) -> FALSE | D3: =IF(LEN(CUSTGROUP[[#This Row],[Title]])<100,FALSE,TRUE) -> FALSE | E3: =ISBLANK(CUSTGROUP[[#This Row],[CustomGroupingEnabled]]) -> FALSE | F3: =COUNTIF(CUSTGROUP[[#This Row],[Code is Blank]:[Enabled is blank]],"TRUE") -> 0 | G3: A0 | H3: GAG funding | I3: TRUE
A4: =ISBLANK(CUSTGROUP[[#This Row],[CustomGroupingCode]]) -> FALSE | B4: =ISBLANK(CUSTGROUP[[#This Row],[Title]]) -> FALSE | C4: =IF(LEN(CUSTGROUP[[#This Row],[CustomGroupingCode]])<100,FALSE,TRUE) -> FALSE | D4: =IF(LEN(CUSTGROUP[[#This Row],[Title]])<100,FALSE,TRUE) -> FALSE | E4: =ISBLANK(CUSTGROUP[[#This Row],[CustomGroupingEnabled]]) -> FALSE | F4: =COUNTIF(CUSTGROUP[[#This Row],[Code is Blank]:[Enabled is blank]],"TRUE") -> 0 | G4: A1 | H4: Other DfE Grants - Standards Funds | I4: TRUE
A5: =ISBLANK(CUSTGROUP[[#This Row],[CustomGroupingCode]]) -> FALSE | B5: =ISBLANK(CUSTGROUP[[#This Row],[Title]]) -> FALSE | C5: =IF(LEN(CUSTGROUP[[#This Row],[CustomGroupingCode]])<100,FALSE,TRUE) -> FALSE | D5: =IF(LEN(CUSTGROUP[[#This Row],[Title]])<100,FALSE,TRUE) -> FALSE | E5: =ISBLANK(CUSTGROUP[[#This Row],[CustomGroupingEnabled]]) -> FALSE | F5: =COUNTIF(CUSTGROUP[[#This Row],[Code is Blank]:[Enabled is blank]],"TRUE") -> 0 | G5: A2 | H5: Other Govt Grants | I5: TRUE
A6: =ISBLANK(CUSTGROUP[[#This Row],[CustomGroupingCode]]) -> FALSE | B6: =ISBLANK(CUSTGROUP[[#This Row],[Title]]) -> FALSE | C6: =IF(LEN(CUSTGROUP[[#This Row],[CustomGroupingCode]])<100,FALSE,TRUE) -> FALSE | D6: =IF(LEN(CUSTGROUP[[#This Row],[Title]])<100,FALSE,TRUE) -> FALSE | E6: =ISBLANK(CUSTGROUP[[#This Row],[CustomGroupingEnabled]]) -> FALSE | F6: =COUNTIF(CUSTGROUP[[#This Row],[Code is Blank]:[Enabled is blank]],"TRUE") -> 0 | G6: A3 | H6: Private Sector Funding | I6: TRUE
A7: =ISBLANK(CUSTGROUP[[#This Row],[CustomGroupingCode]]) -> FALSE | B7: =ISBLANK(CUSTGROUP[[#This Row],[Title]]) -> FALSE | C7: =IF(LEN(CUSTGROUP[[#This Row],[CustomGroupingCode]])<100,FALSE,TRUE) -> FALSE | D7: =IF(LEN(CUSTGROUP[[#This Row],[Title]])<100,FALSE,TRUE) -> FALSE | E7: =ISBLANK(CUSTGROUP[[#This Row],[CustomGroupingEnabled]]) -> FALSE | F7: =COUNTIF(CUSTGROUP[[#This Row],[Code is Blank]:[Enabled is blank]],"TRUE") -> 0 | G7: A4 | H7: Other Income | I7: TRUE
A8: =ISBLANK(CUSTGROUP[[#This Row],[CustomGroupingCode]]) -> FALSE | B8: =ISBLANK(CUSTGROUP[[#This Row],[Title]]) -> FALSE | C8: =IF(LEN(CUSTGROUP[[#This Row],[CustomGroupingCode]])<100,FALSE,TRUE) -> FALSE | D8: =IF(LEN(CUSTGROUP[[#This Row],[Title]])<100,FALSE,TRUE) -> FALSE | E8: =ISBLANK(CUSTGROUP[[#This Row],[CustomGroupingEnabled]]) -> FALSE | F8: =COUNTIF(CUSTGROUP[[#This Row],[Code is Blank]:[Enabled is blank]],"TRUE") -> 0 | G8: B0 | H8: Teaching Staff | I8: TRUE
A9: =ISBLANK(CUSTGROUP[[#This Row],[CustomGroupingCode]]) -> FALSE | B9: =ISBLANK(CUSTGROUP[[#This Row],[Title]]) -> FALSE | C9: =IF(LEN(CUSTGROUP[[#This Row],[CustomGroupingCode]])<100,FALSE,TRUE) -> FALSE | D9: =IF(LEN(CUSTGROUP[[#This Row],[Title]])<100,FALSE,TRUE) -> FALSE | E9: =ISBLANK(CUSTGROUP[[#This Row],[CustomGroupingEnabled]]) -> FALSE | F9: =COUNTIF(CUSTGROUP[[#This Row],[Code is Blank]:[Enabled is blank]],"TRUE") -> 0 | G9: B1 | H9: Educational Support Staff | I9: TRUE
A10: =ISBLANK(CUSTGROUP[[#This Row],[CustomGroupingCode]]) -> FALSE | B10: =ISBLANK(CUSTGROUP[[#This Row],[Title]]) -> FALSE | C10: =IF(LEN(CUSTGROUP[[#This Row],[CustomGroupingCode]])<100,FALSE,TRUE) -> FALSE | D10: =IF(LEN(CUSTGROUP[[#This Row],[Title]])<100,FALSE,TRUE) -> FALSE | E10: =ISBLANK(CUSTGROUP[[#This Row],[CustomGroupingEnabled]]) -> FALSE | F10: =COUNTIF(CUSTGROUP[[#This Row],[Code is Blank]:[Enabled is blank]],"TRUE") -> 0 | G10: B2 | H10: Premises Staffing | I10: TRUE
A11: =ISBLANK(CUSTGROUP[[#This Row],[CustomGroupingCode]]) -> FALSE | B11: =ISBLANK(CUSTGROUP[[#This Row],[Title]]) -> FALSE | C11: =IF(LEN(CUSTGROUP[[#This Row],[CustomGroupingCode]])<100,FALSE,TRUE) -> FALSE | D11: =IF(LEN(CUSTGROUP[[#This Row],[Title]])<100,FALSE,TRUE) -> FALSE | E11: =ISBLANK(CUSTGROUP[[#This Row],[CustomGroupingEnabled]]) -> FALSE | F11: =COUNTIF(CUSTGROUP[[#This Row],[Code is Blank]:[Enabled is blank]],"TRUE") -> 0 | G11: B3 | H11: Admin Staffing | I11: TRUE
A12: =ISBLANK(CUSTGROUP[[#This Row],[CustomGroupingCode]]) -> FALSE | B12: =ISBLANK(CUSTGROUP[[#This Row],[Title]]) -> FALSE | C12: =IF(LEN(CUSTGROUP[[#This Row],[CustomGroupingCode]])<100,FALSE,TRUE) -> FALSE | D12: =IF(LEN(CUSTGROUP[[#This Row],[Title]])<100,FALSE,TRUE) -> FALSE | E12: =ISBLANK(CUSTGROUP[[#This Row],[CustomGroupingEnabled]]) -> FALSE | F12: =COUNTIF(CUSTGROUP[[#This Row],[Code is Blank]:[Enabled is blank]],"TRUE") -> 0 | G12: B4 | H12: Other Staff | I12: TRUE
A13: =ISBLANK(CUSTGROUP[[#This Row],[CustomGroupingCode]]) -> FALSE | B13: =ISBLANK(CUSTGROUP[[#This Row],[Title]]) -> FALSE | C13: =IF(LEN(CUSTGROUP[[#This Row],[CustomGroupingCode]])<100,FALSE,TRUE) -> FALSE | D13: =IF(LEN(CUSTGROUP[[#This Row],[Title]])<100,FALSE,TRUE) -> FALSE | E13: =ISBLANK(CUSTGROUP[[#This Row],[CustomGroupingEnabled]]) -> FALSE | F13: =COUNTIF(CUSTGROUP[[#This Row],[Code is Blank]:[Enabled is blank]],"TRUE") -> 0 | G13: B5 | H13: Agency Staff | I13: TRUE
A14: =ISBLANK(CUSTGROUP[[#This Row],[CustomGroupingCode]]) -> FALSE | B14: =ISBLANK(CUSTGROUP[[#This Row],[Title]]) -> FALSE | C14: =IF(LEN(CUSTGROUP[[#This Row],[CustomGroupingCode]])<100,FALSE,TRUE) -> FALSE | D14: =IF(LEN(CUSTGROUP[[#This Row],[Title]])<100,FALSE,TRUE) -> FALSE | E14: =ISBLANK(CUSTGROUP[[#This Row],[CustomGroupingEnabled]]) -> FALSE | F14: =COUNTIF(CUSTGROUP[[#This Row],[Code is Blank]:[Enabled is blank]],"TRUE") -> 0 | G14: B6 | H14: SLT Staff Costs | I14: TRUE
... A55: =ISBLANK(CUSTGROUP[[#This Row],[CustomGroupingCode]]) -> FALSE | B55: =ISBLANK(CUSTGROUP[[#This Row],[Title]]) -> FALSE | C55: =IF(LEN(CUSTGROUP[[#This Row],[CustomGroupingCode]])<100,FALSE,TRUE) -> FALSE | D55: =IF(LEN(CUSTGROUP[[#This Row],[Title]])<100,FALSE,TRUE) -> FALSE | E55: =ISBLANK(CUSTGROUP[[#This Row],[CustomGroupingEnabled]]) -> FALSE | F55: =COUNTIF(CUSTGROUP[[#This Row],[Code is Blank]:[Enabled is blank]],"TRUE") -> 0 | G55: ZZZ | H55: Not Applicable | I55: TRUE

Sheet SchHub
G1: API - Do not edit
A2: Code is Blank | B2: Title is Blank | C2: Enabled is blank | D2: Code length Check | E2: Title length check | F2: Will import if zero | G2: SchoolHubCode | H2: Title | I2: SchoolHubEnabled
A3: =ISBLANK(SCHHUB[[#This Row],[SchoolHubCode]]) -> FALSE | B3: =ISBLANK(SCHHUB[[#This Row],[Title]]) -> FALSE | C3: =ISBLANK(SCHHUB[[#This Row],[SchoolHubEnabled]]) -> FALSE | D3: =IF(LEN(SCHHUB[[#This Row],[SchoolHubCode]])<100,FALSE,TRUE) -> FALSE | E3: =IF(LEN(SCHHUB[[#This Row],[Title]])<100,FALSE,TRUE) -> FALSE | F3: =COUNTIF(SCHHUB[[#This Row],[Code is Blank]:[Title length check]],"TRUE") -> 0 | G3: CENTRAL | H3: Central Hub | I3: TRUE
A4: =ISBLANK(SCHHUB[[#This Row],[SchoolHubCode]]) -> FALSE | B4: =ISBLANK(SCHHUB[[#This Row],[Title]]) -> FALSE | C4: =ISBLANK(SCHHUB[[#This Row],[SchoolHubEnabled]]) -> FALSE | D4: =IF(LEN(SCHHUB[[#This Row],[SchoolHubCode]])<100,FALSE,TRUE) -> FALSE | E4: =IF(LEN(SCHHUB[[#This Row],[Title]])<100,FALSE,TRUE) -> FALSE | F4: =COUNTIF(SCHHUB[[#This Row],[Code is Blank]:[Title length check]],"TRUE") -> 0 | G4: DEFAULT | H4: Default (no) Hub | I4: TRUE
A5: =ISBLANK(SCHHUB[[#This Row],[SchoolHubCode]]) -> FALSE | B5: =ISBLANK(SCHHUB[[#This Row],[Title]]) -> FALSE | C5: =ISBLANK(SCHHUB[[#This Row],[SchoolHubEnabled]]) -> FALSE | D5: =IF(LEN(SCHHUB[[#This Row],[SchoolHubCode]])<100,FALSE,TRUE) -> FALSE | E5: =IF(LEN(SCHHUB[[#This Row],[Title]])<100,FALSE,TRUE) -> FALSE | F5: =COUNTIF(SCHHUB[[#This Row],[Code is Blank]:[Title length check]],"TRUE") -> 0 | G5: EAST | H5: East Hub | I5: TRUE
A6: =ISBLANK(SCHHUB[[#This Row],[SchoolHubCode]]) -> FALSE | B6: =ISBLANK(SCHHUB[[#This Row],[Title]]) -> FALSE | C6: =ISBLANK(SCHHUB[[#This Row],[SchoolHubEnabled]]) -> FALSE | D6: =IF(LEN(SCHHUB[[#This Row],[SchoolHubCode]])<100,FALSE,TRUE) -> FALSE | E6: =IF(LEN(SCHHUB[[#This Row],[Title]])<100,FALSE,TRUE) -> FALSE | F6: =COUNTIF(SCHHUB[[#This Row],[Code is Blank]:[Title length check]],"TRUE") -> 0 | G6: NORTH | H6: North Hub | I6: TRUE
A7: =ISBLANK(SCHHUB[[#This Row],[SchoolHubCode]]) -> FALSE | B7: =ISBLANK(SCHHUB[[#This Row],[Title]]) -> FALSE | C7: =ISBLANK(SCHHUB[[#This Row],[SchoolHubEnabled]]) -> FALSE | D7: =IF(LEN(SCHHUB[[#This Row],[SchoolHubCode]])<100,FALSE,TRUE) -> FALSE | E7: =IF(LEN(SCHHUB[[#This Row],[Title]])<100,FALSE,TRUE) -> FALSE | F7: =COUNTIF(SCHHUB[[#This Row],[Code is Blank]:[Title length check]],"TRUE") -> 0 | G7: SOUTH | H7: South Hub | I7: TRUE
A8: =ISBLANK(SCHHUB[[#This Row],[SchoolHubCode]]) -> FALSE | B8: =ISBLANK(SCHHUB[[#This Row],[Title]]) -> FALSE | C8: =ISBLANK(SCHHUB[[#This Row],[SchoolHubEnabled]]) -> FALSE | D8: =IF(LEN(SCHHUB[[#This Row],[SchoolHubCode]])<100,FALSE,TRUE) -> FALSE | E8: =IF(LEN(SCHHUB[[#This Row],[Title]])<100,FALSE,TRUE) -> FALSE | F8: =COUNTIF(SCHHUB[[#This Row],[Code is Blank]:[Title length check]],"TRUE") -> 0 | G8: WEST | H8: West Hub | I8: TRUE

Sheet SchType
G1: API - Do not edit
A2: Code is Blank | B2: Title is Blank | C2: Enabled is blank | D2: Code length Check | E2: Title length check | F2: Will import if zero | G2: SchoolTypeCode | H2: Title | I2: SchoolTypeEnabled
A3: =ISBLANK(SCHTYPE[[#This Row],[SchoolTypeCode]]) -> FALSE | B3: =ISBLANK(SCHTYPE[[#This Row],[Title]]) -> FALSE | C3: =ISBLANK(SCHTYPE[[#This Row],[SchoolTypeEnabled]]) -> FALSE | D3: =IF(LEN(SCHTYPE[[#This Row],[SchoolTypeCode]])<100,FALSE,TRUE) -> FALSE | E3: =IF(LEN(SCHTYPE[[#This Row],[Title]])<100,FALSE,TRUE) -> FALSE | F3: =COUNTIF(SCHTYPE[[#This Row],[Code is Blank]:[Title length check]],"TRUE") -> 0 | G3: ALLTHROUGH | H3: All Through School | I3: TRUE
A4: =ISBLANK(SCHTYPE[[#This Row],[SchoolTypeCode]]) -> FALSE | B4: =ISBLANK(SCHTYPE[[#This Row],[Title]]) -> FALSE | C4: =ISBLANK(SCHTYPE[[#This Row],[SchoolTypeEnabled]]) -> FALSE | D4: =IF(LEN(SCHTYPE[[#This Row],[SchoolTypeCode]])<100,FALSE,TRUE) -> FALSE | E4: =IF(LEN(SCHTYPE[[#This Row],[Title]])<100,FALSE,TRUE) -> FALSE | F4: =COUNTIF(SCHTYPE[[#This Row],[Code is Blank]:[Title length check]],"TRUE") -> 0 | G4: CENTRAL | H4: Central | I4: TRUE
A5: =ISBLANK(SCHTYPE[[#This Row],[SchoolTypeCode]]) -> FALSE | B5: =ISBLANK(SCHTYPE[[#This Row],[Title]]) -> FALSE | C5: =ISBLANK(SCHTYPE[[#This Row],[SchoolTypeEnabled]]) -> FALSE | D5: =IF(LEN(SCHTYPE[[#This Row],[SchoolTypeCode]])<100,FALSE,TRUE) -> FALSE | E5: =IF(LEN(SCHTYPE[[#This Row],[Title]])<100,FALSE,TRUE) -> FALSE | F5: =COUNTIF(SCHTYPE[[#This Row],[Code is Blank]:[Title length check]],"TRUE") -> 0 | G5: DEFAULT | H5: Default (no) Type | I5: TRUE
A6: =ISBLANK(SCHTYPE[[#This Row],[SchoolTypeCode]]) -> FALSE | B6: =ISBLANK(SCHTYPE[[#This Row],[Title]]) -> FALSE | C6: =ISBLANK(SCHTYPE[[#This Row],[SchoolTypeEnabled]]) -> FALSE | D6: =IF(LEN(SCHTYPE[[#This Row],[SchoolTypeCode]])<100,FALSE,TRUE) -> FALSE | E6: =IF(LEN(SCHTYPE[[#This Row],[Title]])<100,FALSE,TRUE) -> FALSE | F6: =COUNTIF(SCHTYPE[[#This Row],[Code is Blank]:[Title length check]],"TRUE") -> 0 | G6: OTHER | H6: Other | I6: TRUE
A7: =ISBLANK(SCHTYPE[[#This Row],[SchoolTypeCode]]) -> FALSE | B7: =ISBLANK(SCHTYPE[[#This Row],[Title]]) -> FALSE | C7: =ISBLANK(SCHTYPE[[#This Row],[SchoolTypeEnabled]]) -> FALSE | D7: =IF(LEN(SCHTYPE[[#This Row],[SchoolTypeCode]])<100,FALSE,TRUE) -> FALSE | E7: =IF(LEN(SCHTYPE[[#This Row],[Title]])<100,FALSE,TRUE) -> FALSE | F7: =COUNTIF(SCHTYPE[[#This Row],[Code is Blank]:[Title length check]],"TRUE") -> 0 | G7: PRIMARY | H7: Primary School | I7: TRUE
A8: =ISBLANK(SCHTYPE[[#This Row],[SchoolTypeCode]]) -> FALSE | B8: =ISBLANK(SCHTYPE[[#This Row],[Title]]) -> FALSE | C8: =ISBLANK(SCHTYPE[[#This Row],[SchoolTypeEnabled]]) -> FALSE | D8: =IF(LEN(SCHTYPE[[#This Row],[SchoolTypeCode]])<100,FALSE,TRUE) -> FALSE | E8: =IF(LEN(SCHTYPE[[#This Row],[Title]])<100,FALSE,TRUE) -> FALSE | F8: =COUNTIF(SCHTYPE[[#This Row],[Code is Blank]:[Title length check]],"TRUE") -> 0 | G8: SECONDARY | H8: Secondary School | I8: TRUE

Sheet LocalAuth
G1: This grey section can be edited | H1: API - Do not edit
A2: Code is Blank | B2: Title is Blank | C2: Enabled is blank | D2: Code length Check | E2: Title length check | F2: Will import if zero | G2: LA | H2: SchoolLocalAuthorityCode | I2: Title | J2: SchoolLocalAuthorityEnabled
A3: =ISBLANK(LocalAuth[[#This Row],[SchoolLocalAuthorityCode]]) -> FALSE | B3: =ISBLANK(LocalAuth[[#This Row],[Title]]) -> FALSE | C3: =ISBLANK(LocalAuth[[#This Row],[SchoolLocalAuthorityEnabled]]) -> FALSE | D3: =IF(LEN(LocalAuth[[#This Row],[SchoolLocalAuthorityCode]])<100,FALSE,TRUE) -> FALSE | E3: =IF(LEN(LocalAuth[[#This Row],[Title]])<100,FALSE,TRUE) -> FALSE | F3: =COUNTIF(LocalAuth[[#This Row],[Code is Blank]:[Title length check]],"TRUE") -> 0 | G3: LA0 | H3: CHE | I3: Cheshire East | J3: TRUE
A4: =ISBLANK(LocalAuth[[#This Row],[SchoolLocalAuthorityCode]]) -> FALSE | B4: =ISBLANK(LocalAuth[[#This Row],[Title]]) -> FALSE | C4: =ISBLANK(LocalAuth[[#This Row],[SchoolLocalAuthorityEnabled]]) -> FALSE | D4: =IF(LEN(LocalAuth[[#This Row],[SchoolLocalAuthorityCode]])<100,FALSE,TRUE) -> FALSE | E4: =IF(LEN(LocalAuth[[#This Row],[Title]])<100,FALSE,TRUE) -> FALSE | F4: =COUNTIF(LocalAuth[[#This Row],[Code is Blank]:[Title length check]],"TRUE") -> 0 | G4: LA2 | H4: DEFAULT | I4: Default (no) Local Authority | J4: TRUE

Sheet Schools
G1: This grey section can be edited | J1: API - Do not edit
A2: HubIssues | B2: SchTypeIssue | C2: Blank Data | D2: Code length Check | E2: Title length check | F2: Will Import if 0 | G2: London Weighting Type | H2: LA | I2: School Type | J2: SchoolLocalAuthority | K2: SchoolCode | L2: SchoolHub | M2: SchoolType | N2: Title | O2: LondonWeighting | P2: UniqueReferenceNumber | Q2: TeachingHours | R2: SchoolEnabled
A3: =IF(COUNTIF(SCHHUB[SchoolHubCode],SCHOOLS[[#This Row],[SchoolHub]])>0,0,1) -> 0 | B3: =IF(COUNTIF(SCHTYPE[SchoolTypeCode],SCHOOLS[[#This Row],[SchoolType]])>0,0,1) -> 0 | C3: =COUNTBLANK(SCHOOLS[[#This Row],[SchoolLocalAuthority]:[SchoolEnabled]]) -> 0 | D3: =IF(LEN(SCHOOLS[[#This Row],[SchoolCode]])<100,0,1) -> 0 | E3: =IF(LEN(SCHOOLS[[#This Row],[Title]])<100,0,1) -> 0 | F3: =SUM(SCHOOLS[[#This Row],[HubIssues]:[Title length check]]) -> 0 | G3: England & Wales | H3: =_xlfn.XLOOKUP(SCHOOLS[[#This Row],[SchoolLocalAuthority]],LocalAuth[SchoolLocalAuthorityCode],LocalAuth[LA]) -> LA0 | I3: Central | J3: CHE | K3: ALS | L3: DEFAULT | M3: SECONDARY | N3: Alsager School | O3: FALSE | P3: 140108 | Q3: 32.436 | R3: TRUE
A4: =IF(COUNTIF(SCHHUB[SchoolHubCode],SCHOOLS[[#This Row],[SchoolHub]])>0,0,1) -> 0 | B4: =IF(COUNTIF(SCHTYPE[SchoolTypeCode],SCHOOLS[[#This Row],[SchoolType]])>0,0,1) -> 0 | C4: =COUNTBLANK(SCHOOLS[[#This Row],[SchoolLocalAuthority]:[SchoolEnabled]]) -> 0 | D4: =IF(LEN(SCHOOLS[[#This Row],[SchoolCode]])<100,0,1) -> 0 | E4: =IF(LEN(SCHOOLS[[#This Row],[Title]])<100,0,1) -> 0 | F4: =SUM(SCHOOLS[[#This Row],[HubIssues]:[Title length check]]) -> 0 | G4: England & Wales | H4: =_xlfn.XLOOKUP(SCHOOLS[[#This Row],[SchoolLocalAuthority]],LocalAuth[SchoolLocalAuthorityCode],LocalAuth[LA]) -> LA0 | I4: Secondary | J4: CHE | K4: AUD | L4: DEFAULT | M4: PRIMARY | N4: Audlem St James' CofE Primary | O4: FALSE | P4: 148489 | Q4: 32.436 | R4: TRUE
A5: =IF(COUNTIF(SCHHUB[SchoolHubCode],SCHOOLS[[#This Row],[SchoolHub]])>0,0,1) -> 0 | B5: =IF(COUNTIF(SCHTYPE[SchoolTypeCode],SCHOOLS[[#This Row],[SchoolType]])>0,0,1) -> 0 | C5: =COUNTBLANK(SCHOOLS[[#This Row],[SchoolLocalAuthority]:[SchoolEnabled]]) -> 0 | D5: =IF(LEN(SCHOOLS[[#This Row],[SchoolCode]])<100,0,1) -> 0 | E5: =IF(LEN(SCHOOLS[[#This Row],[Title]])<100,0,1) -> 0 | F5: =SUM(SCHOOLS[[#This Row],[HubIssues]:[Title length check]]) -> 0 | G5: England & Wales | H5: =_xlfn.XLOOKUP(SCHOOLS[[#This Row],[SchoolLocalAuthority]],LocalAuth[SchoolLocalAuthorityCode],LocalAuth[LA]) -> LA0 | I5: Primary | J5: CHE | K5: BLS | L5: DEFAULT | M5: SECONDARY | N5: Brine Leas School | O5: FALSE | P5: 136279 | Q5: 32.436 | R5: TRUE
A6: =IF(COUNTIF(SCHHUB[SchoolHubCode],SCHOOLS[[#This Row],[SchoolHub]])>0,0,1) -> 0 | B6: =IF(COUNTIF(SCHTYPE[SchoolTypeCode],SCHOOLS[[#This Row],[SchoolType]])>0,0,1) -> 0 | C6: =COUNTBLANK(SCHOOLS[[#This Row],[SchoolLocalAuthority]:[SchoolEnabled]]) -> 0 | D6: =IF(LEN(SCHOOLS[[#This Row],[SchoolCode]])<100,0,1) -> 0 | E6: =IF(LEN(SCHOOLS[[#This Row],[Title]])<100,0,1) -> 0 | F6: =SUM(SCHOOLS[[#This Row],[HubIssues]:[Title length check]]) -> 0 | G6: England & Wales | H6: =_xlfn.XLOOKUP(SCHOOLS[[#This Row],[SchoolLocalAuthority]],LocalAuth[SchoolLocalAuthorityCode],LocalAuth[LA]) -> LA0 | I6: AllThrough | J6: CHE | K6: HIG | L6: DEFAULT | M6: PRIMARY | N6: Alsager Highfields Primary School | O6: FALSE | P6: 148136 | Q6: 32.436 | R6: TRUE
A7: =IF(COUNTIF(SCHHUB[SchoolHubCode],SCHOOLS[[#This Row],[SchoolHub]])>0,0,1) -> 0 | B7: =IF(COUNTIF(SCHTYPE[SchoolTypeCode],SCHOOLS[[#This Row],[SchoolType]])>0,0,1) -> 0 | C7: =COUNTBLANK(SCHOOLS[[#This Row],[SchoolLocalAuthority]:[SchoolEnabled]]) -> 0 | D7: =IF(LEN(SCHOOLS[[#This Row],[SchoolCode]])<100,0,1) -> 0 | E7: =IF(LEN(SCHOOLS[[#This Row],[Title]])<100,0,1) -> 0 | F7: =SUM(SCHOOLS[[#This Row],[HubIssues]:[Title length check]]) -> 0 | G7: England & Wales | H7: =_xlfn.XLOOKUP(SCHOOLS[[#This Row],[SchoolLocalAuthority]],LocalAuth[SchoolLocalAuthorityCode],LocalAuth[LA]) -> LA2 | J7: DEFAULT | K7: HUB | L7: DEFAULT | M7: DEFAULT | N7: Maths Hub | O7: FALSE | P7: 0 | Q7: 0 | R7: TRUE
A8: =IF(COUNTIF(SCHHUB[SchoolHubCode],SCHOOLS[[#This Row],[SchoolHub]])>0,0,1) -> 0 | B8: =IF(COUNTIF(SCHTYPE[SchoolTypeCode],SCHOOLS[[#This Row],[SchoolType]])>0,0,1) -> 0 | C8: =COUNTBLANK(SCHOOLS[[#This Row],[SchoolLocalAuthority]:[SchoolEnabled]]) -> 0 | D8: =IF(LEN(SCHOOLS[[#This Row],[SchoolCode]])<100,0,1) -> 0 | E8: =IF(LEN(SCHOOLS[[#This Row],[Title]])<100,0,1) -> 0 | F8: =SUM(SCHOOLS[[#This Row],[HubIssues]:[Title length check]]) -> 0 | G8: England & Wales | H8: =_xlfn.XLOOKUP(SCHOOLS[[#This Row],[SchoolLocalAuthority]],LocalAuth[SchoolLocalAuthorityCode],LocalAuth[LA]) -> LA0 | J8: CHE | K8: MAT | L8: DEFAULT | M8: CENTRAL | N8: The Cornovii Trust | O8: FALSE | P8: 1 | Q8: 32.436 | R8: TRUE
A9: =IF(COUNTIF(SCHHUB[SchoolHubCode],SCHOOLS[[#This Row],[SchoolHub]])>0,0,1) -> 0 | B9: =IF(COUNTIF(SCHTYPE[SchoolTypeCode],SCHOOLS[[#This Row],[SchoolType]])>0,0,1) -> 0 | C9: =COUNTBLANK(SCHOOLS[[#This Row],[SchoolLocalAuthority]:[SchoolEnabled]]) -> 0 | D9: =IF(LEN(SCHOOLS[[#This Row],[SchoolCode]])<100,0,1) -> 0 | E9: =IF(LEN(SCHOOLS[[#This Row],[Title]])<100,0,1) -> 0 | F9: =SUM(SCHOOLS[[#This Row],[HubIssues]:[Title length check]]) -> 0 | G9: England & Wales | H9: =_xlfn.XLOOKUP(SCHOOLS[[#This Row],[SchoolLocalAuthority]],LocalAuth[SchoolLocalAuthorityCode],LocalAuth[LA]) -> LA0 | J9: CHE | K9: MLB | L9: DEFAULT | M9: SECONDARY | N9: Malbank School and Sixth Form College | O9: FALSE | P9: 111419 | Q9: 32.436 | R9: TRUE
A10: =IF(COUNTIF(SCHHUB[SchoolHubCode],SCHOOLS[[#This Row],[SchoolHub]])>0,0,1) -> 0 | B10: =IF(COUNTIF(SCHTYPE[SchoolTypeCode],SCHOOLS[[#This Row],[SchoolType]])>0,0,1) -> 0 | C10: =COUNTBLANK(SCHOOLS[[#This Row],[SchoolLocalAuthority]:[SchoolEnabled]]) -> 0 | D10: =IF(LEN(SCHOOLS[[#This Row],[SchoolCode]])<100,0,1) -> 0 | E10: =IF(LEN(SCHOOLS[[#This Row],[Title]])<100,0,1) -> 0 | F10: =SUM(SCHOOLS[[#This Row],[HubIssues]:[Title length check]]) -> 0 | G10: England & Wales | H10: =_xlfn.XLOOKUP(SCHOOLS[[#This Row],[SchoolLocalAuthority]],LocalAuth[SchoolLocalAuthorityCode],LocalAuth[LA]) -> LA0 | J10: CHE | K10: PTP | L10: DEFAULT | M10: PRIMARY | N10: Pear Tree Primary School | O10: FALSE | P10: 140740 | Q10: 32.436 | R10: TRUE
A11: =IF(COUNTIF(SCHHUB[SchoolHubCode],SCHOOLS[[#This Row],[SchoolHub]])>0,0,1) -> 0 | B11: =IF(COUNTIF(SCHTYPE[SchoolTypeCode],SCHOOLS[[#This Row],[SchoolType]])>0,0,1) -> 0 | C11: =COUNTBLANK(SCHOOLS[[#This Row],[SchoolLocalAuthority]:[SchoolEnabled]]) -> 0 | D11: =IF(LEN(SCHOOLS[[#This Row],[SchoolCode]])<100,0,1) -> 0 | E11: =IF(LEN(SCHOOLS[[#This Row],[Title]])<100,0,1) -> 0 | F11: =SUM(SCHOOLS[[#This Row],[HubIssues]:[Title length check]]) -> 0 | G11: England & Wales | H11: =_xlfn.XLOOKUP(SCHOOLS[[#This Row],[SchoolLocalAuthority]],LocalAuth[SchoolLocalAuthorityCode],LocalAuth[LA]) -> LA0 | J11: CHE | K11: SBL | L11: DEFAULT | M11: PRIMARY | N11: Stapeley Broad Lane CofE Primary School | O11: FALSE | P11: 139539 | Q11: 32.436 | R11: TRUE
A12: =IF(COUNTIF(SCHHUB[SchoolHubCode],SCHOOLS[[#This Row],[SchoolHub]])>0,0,1) -> 0 | B12: =IF(COUNTIF(SCHTYPE[SchoolTypeCode],SCHOOLS[[#This Row],[SchoolType]])>0,0,1) -> 0 | C12: =COUNTBLANK(SCHOOLS[[#This Row],[SchoolLocalAuthority]:[SchoolEnabled]]) -> 0 | D12: =IF(LEN(SCHOOLS[[#This Row],[SchoolCode]])<100,0,1) -> 0 | E12: =IF(LEN(SCHOOLS[[#This Row],[Title]])<100,0,1) -> 0 | F12: =SUM(SCHOOLS[[#This Row],[HubIssues]:[Title length check]]) -> 0 | G12: England & Wales | H12: =_xlfn.XLOOKUP(SCHOOLS[[#This Row],[SchoolLocalAuthority]],LocalAuth[SchoolLocalAuthorityCode],LocalAuth[LA]) -> LA0 | J12: CHE | K12: WVP | L12: DEFAULT | M12: PRIMARY | N12: Weston Village Primary School | O12: FALSE | P12: 145587 | Q12: 32.436 | R12: TRUE

Sheet Depts
G1: API - Do not edit
A2: FundIssue | B2: ActivityIssue | C2: LedgerIssue | D2: Code length Check | E2: Title length check | F2: Will Import if 0 | G2: DepartmentCode | H2: Title | I2: AvailableToAllSchools | J2: SchoolCodes | K2: ActivityCode | L2: FundCode | M2: LedgerCode | N2: DefaultFinanceCode | O2: DepartmentEnabled
A3: =IF(COUNTIF(FUNDS[FundCode],DEPTS[[#This Row],[FundCode]])>0,0,1) -> 0 | B3: =IF(COUNTIF(ACTIVITIES[ActivityCode],DEPTS[[#This Row],[ActivityCode]])>0,0,1) -> 0 | C3: =IF(COUNTIF(LEDGER[LedgerCode],DEPTS[[#This Row],[LedgerCode]])>0,0,1) -> 0 | D3: =IF(LEN(DEPTS[[#This Row],[DepartmentCode]])<100,0,1) -> 0 | E3: =IF(LEN(DEPTS[[#This Row],[Title]])<100,0,1) -> 0 | F3: =SUM(DEPTS[[#This Row],[FundIssue]:[Title length check]]) -> 0 | G3: ACHIEVE | H3: Keep on Track / Achievement | I3: FALSE | J3: MAT | K3: SCHOOL | L3: GAG | M3: COSTCENTRES | O3: TRUE
A4: =IF(COUNTIF(FUNDS[FundCode],DEPTS[[#This Row],[FundCode]])>0,0,1) -> 0 | B4: =IF(COUNTIF(ACTIVITIES[ActivityCode],DEPTS[[#This Row],[ActivityCode]])>0,0,1) -> 0 | C4: =IF(COUNTIF(LEDGER[LedgerCode],DEPTS[[#This Row],[LedgerCode]])>0,0,1) -> 0 | D4: =IF(LEN(DEPTS[[#This Row],[DepartmentCode]])<100,0,1) -> 0 | E4: =IF(LEN(DEPTS[[#This Row],[Title]])<100,0,1) -> 0 | F4: =SUM(DEPTS[[#This Row],[FundIssue]:[Title length check]]) -> 0 | G4: ACHIEVE | H4: Keep on Track / Achievement | I4: FALSE | J4: ALS | K4: SCHOOL | L4: GAG | M4: COSTCTR | O4: TRUE
A5: =IF(COUNTIF(FUNDS[FundCode],DEPTS[[#This Row],[FundCode]])>0,0,1) -> 0 | B5: =IF(COUNTIF(ACTIVITIES[ActivityCode],DEPTS[[#This Row],[ActivityCode]])>0,0,1) -> 0 | C5: =IF(COUNTIF(LEDGER[LedgerCode],DEPTS[[#This Row],[LedgerCode]])>0,0,1) -> 0 | D5: =IF(LEN(DEPTS[[#This Row],[DepartmentCode]])<100,0,1) -> 0 | E5: =IF(LEN(DEPTS[[#This Row],[Title]])<100,0,1) -> 0 | F5: =SUM(DEPTS[[#This Row],[FundIssue]:[Title length check]]) -> 0 | G5: ACT | H5: Alsager Community Trust | I5: FALSE | J5: MAT | K5: COMM | L5: ACT | M5: COSTCENTRES | O5: TRUE
A6: =IF(COUNTIF(FUNDS[FundCode],DEPTS[[#This Row],[FundCode]])>0,0,1) -> 0 | B6: =IF(COUNTIF(ACTIVITIES[ActivityCode],DEPTS[[#This Row],[ActivityCode]])>0,0,1) -> 0 | C6: =IF(COUNTIF(LEDGER[LedgerCode],DEPTS[[#This Row],[LedgerCode]])>0,0,1) -> 0 | D6: =IF(LEN(DEPTS[[#This Row],[DepartmentCode]])<100,0,1) -> 0 | E6: =IF(LEN(DEPTS[[#This Row],[Title]])<100,0,1) -> 0 | F6: =SUM(DEPTS[[#This Row],[FundIssue]:[Title length check]]) -> 0 | G6: ACT | H6: Alsager Community Trust | I6: FALSE | J6: ALS | K6: COMM | L6: ACT | M6: COSTCTR | O6: TRUE
A7: =IF(COUNTIF(FUNDS[FundCode],DEPTS[[#This Row],[FundCode]])>0,0,1) -> 0 | B7: =IF(COUNTIF(ACTIVITIES[ActivityCode],DEPTS[[#This Row],[ActivityCode]])>0,0,1) -> 0 | C7: =IF(COUNTIF(LEDGER[LedgerCode],DEPTS[[#This Row],[LedgerCode]])>0,0,1) -> 0 | D7: =IF(LEN(DEPTS[[#This Row],[DepartmentCode]])<100,0,1) -> 0 | E7: =IF(LEN(DEPTS[[#This Row],[Title]])<100,0,1) -> 0 | F7: =SUM(DEPTS[[#This Row],[FundIssue]:[Title length check]]) -> 0 | G7: ADMIN | H7: Administration | I7: FALSE | J7: MAT | K7: DEFAULT | L7: DEFAULT | M7: COSTCENTRES | O7: TRUE
A8: =IF(COUNTIF(FUNDS[FundCode],DEPTS[[#This Row],[FundCode]])>0,0,1) -> 0 | B8: =IF(COUNTIF(ACTIVITIES[ActivityCode],DEPTS[[#This Row],[ActivityCode]])>0,0,1) -> 0 | C8: =IF(COUNTIF(LEDGER[LedgerCode],DEPTS[[#This Row],[LedgerCode]])>0,0,1) -> 0 | D8: =IF(LEN(DEPTS[[#This Row],[DepartmentCode]])<100,0,1) -> 0 | E8: =IF(LEN(DEPTS[[#This Row],[Title]])<100,0,1) -> 0 | F8: =SUM(DEPTS[[#This Row],[FundIssue]:[Title length check]]) -> 0 | G8: ADMIN | H8: Administration | I8: FALSE | J8: AUD,BLS,MLB,PTP | K8: DEFAULT | L8: DEFAULT | M8: COSTCTR | O8: TRUE
A9: =IF(COUNTIF(FUNDS[FundCode],DEPTS[[#This Row],[FundCode]])>0,0,1) -> 0 | B9: =IF(COUNTIF(ACTIVITIES[ActivityCode],DEPTS[[#This Row],[ActivityCode]])>0,0,1) -> 0 | C9: =IF(COUNTIF(LEDGER[LedgerCode],DEPTS[[#This Row],[LedgerCode]])>0,0,1) -> 0 | D9: =IF(LEN(DEPTS[[#This Row],[DepartmentCode]])<100,0,1) -> 0 | E9: =IF(LEN(DEPTS[[#This Row],[Title]])<100,0,1) -> 0 | F9: =SUM(DEPTS[[#This Row],[FundIssue]:[Title length check]]) -> 0 | G9: ADMIN | H9: Administration | I9: FALSE | J9: ALS,WVP,HIG,SBL | K9: SCHOOL | L9: DEFAULT | M9: COSTCTR | O9: TRUE
A10: =IF(COUNTIF(FUNDS[FundCode],DEPTS[[#This Row],[FundCode]])>0,0,1) -> 0 | B10: =IF(COUNTIF(ACTIVITIES[ActivityCode],DEPTS[[#This Row],[ActivityCode]])>0,0,1) -> 0 | C10: =IF(COUNTIF(LEDGER[LedgerCode],DEPTS[[#This Row],[LedgerCode]])>0,0,1) -> 0 | D10: =IF(LEN(DEPTS[[#This Row],[DepartmentCode]])<100,0,1) -> 0 | E10: =IF(LEN(DEPTS[[#This Row],[Title]])<100,0,1) -> 0 | F10: =SUM(DEPTS[[#This Row],[FundIssue]:[Title length check]]) -> 0 | G10: ADMINSER | H10: MAT contribution | I10: FALSE | J10: MAT | K10: DEFAULT | L10: DEFAULT | M10: COSTCENTRES | O10: TRUE
A11: =IF(COUNTIF(FUNDS[FundCode],DEPTS[[#This Row],[FundCode]])>0,0,1) -> 0 | B11: =IF(COUNTIF(ACTIVITIES[ActivityCode],DEPTS[[#This Row],[ActivityCode]])>0,0,1) -> 0 | C11: =IF(COUNTIF(LEDGER[LedgerCode],DEPTS[[#This Row],[LedgerCode]])>0,0,1) -> 0 | D11: =IF(LEN(DEPTS[[#This Row],[DepartmentCode]])<100,0,1) -> 0 | E11: =IF(LEN(DEPTS[[#This Row],[Title]])<100,0,1) -> 0 | F11: =SUM(DEPTS[[#This Row],[FundIssue]:[Title length check]]) -> 0 | G11: ADMINSER | H11: MAT contribution | I11: FALSE | J11: WVP,HIG,AUD,BLS,MLB,PTP,SBL | K11: DEFAULT | L11: DEFAULT | M11: COSTCTR | O11: TRUE
A12: =IF(COUNTIF(FUNDS[FundCode],DEPTS[[#This Row],[FundCode]])>0,0,1) -> 0 | B12: =IF(COUNTIF(ACTIVITIES[ActivityCode],DEPTS[[#This Row],[ActivityCode]])>0,0,1) -> 0 | C12: =IF(COUNTIF(LEDGER[LedgerCode],DEPTS[[#This Row],[LedgerCode]])>0,0,1) -> 0 | D12: =IF(LEN(DEPTS[[#This Row],[DepartmentCode]])<100,0,1) -> 0 | E12: =IF(LEN(DEPTS[[#This Row],[Title]])<100,0,1) -> 0 | F12: =SUM(DEPTS[[#This Row],[FundIssue]:[Title length check]]) -> 0 | G12: ADMINSER | H12: MAT contribution | I12: FALSE | J12: ALS | K12: SCHOOL | L12: DEFAULT | M12: COSTCTR | O12: TRUE
A13: =IF(COUNTIF(FUNDS[FundCode],DEPTS[[#This Row],[FundCode]])>0,0,1) -> 0 | B13: =IF(COUNTIF(ACTIVITIES[ActivityCode],DEPTS[[#This Row],[ActivityCode]])>0,0,1) -> 0 | C13: =IF(COUNTIF(LEDGER[LedgerCode],DEPTS[[#This Row],[LedgerCode]])>0,0,1) -> 0 | D13: =IF(LEN(DEPTS[[#This Row],[DepartmentCode]])<100,0,1) -> 0 | E13: =IF(LEN(DEPTS[[#This Row],[Title]])<100,0,1) -> 0 | F13: =SUM(DEPTS[[#This Row],[FundIssue]:[Title length check]]) -> 0 | G13: ADSER | H13: Admin Services | I13: FALSE | J13: AUD | K13: DEFAULT | L13: DEFAULT | M13: COSTCTR | O13: TRUE
A14: =IF(COUNTIF(FUNDS[FundCode],DEPTS[[#This Row],[FundCode]])>0,0,1) -> 0 | B14: =IF(COUNTIF(ACTIVITIES[ActivityCode],DEPTS[[#This Row],[ActivityCode]])>0,0,1) -> 0 | C14: =IF(COUNTIF(LEDGER[LedgerCode],DEPTS[[#This Row],[LedgerCode]])>0,0,1) -> 0 | D14: =IF(LEN(DEPTS[[#This Row],[DepartmentCode]])<100,0,1) -> 0 | E14: =IF(LEN(DEPTS[[#This Row],[Title]])<100,0,1) -> 0 | F14: =SUM(DEPTS[[#This Row],[FundIssue]:[Title length check]]) -> 0 | G14: ADSER | H14: Admin Services | I14: FALSE | J14: WVP,HIG,SBL | K14: SCHOOL | L14: DEFAULT | M14: COSTCTR | O14: TRUE
... A195: =IF(COUNTIF(FUNDS[FundCode],DEPTS[[#This Row],[FundCode]])>0,0,1) -> 0 | B195: =IF(COUNTIF(ACTIVITIES[ActivityCode],DEPTS[[#This Row],[ActivityCode]])>0,0,1) -> 0 | C195: =IF(COUNTIF(LEDGER[LedgerCode],DEPTS[[#This Row],[LedgerCode]])>0,0,1) -> 0 | D195: =IF(LEN(DEPTS[[#This Row],[DepartmentCode]])<100,0,1) -> 0 | E195: =IF(LEN(DEPTS[[#This Row],[Title]])<100,0,1) -> 0 | F195: =SUM(DEPTS[[#This Row],[FundIssue]:[Title length check]]) -> 0 | G195: CWARWICK | H195: Warwick | I195: FALSE | J195: BLS | K195: DEFAULT | L195: DEFAULT | M195: COSTCTR | O195: TRUE
A196: =IF(COUNTIF(FUNDS[FundCode],DEPTS[[#This Row],[FundCode]])>0,0,1) -> 0 | B196: =IF(COUNTIF(ACTIVITIES[ActivityCode],DEPTS[[#This Row],[ActivityCode]])>0,0,1) -> 0 | C196: =IF(COUNTIF(LEDGER[LedgerCode],DEPTS[[#This Row],[LedgerCode]])>0,0,1) -> 0 | D196: =IF(LEN(DEPTS[[#This Row],[DepartmentCode]])<100,0,1) -> 0 | E196: =IF(LEN(DEPTS[[#This Row],[Title]])<100,0,1) -> 0 | F196: =SUM(DEPTS[[#This Row],[FundIssue]:[Title length check]]) -> 0 | G196: DEFAULT | H196: Default (no) Department | I196: TRUE | K196: DEFAULT | L196: DEFAULT | M196: DEFAULT | O196: TRUE
A197: =IF(COUNTIF(FUNDS[FundCode],DEPTS[[#This Row],[FundCode]])>0,0,1) -> 0 | B197: =IF(COUNTIF(ACTIVITIES[ActivityCode],DEPTS[[#This Row],[ActivityCode]])>0,0,1) -> 0 | C197: =IF(COUNTIF(LEDGER[LedgerCode],DEPTS[[#This Row],[LedgerCode]])>0,0,1) -> 0 | D197: =IF(LEN(DEPTS[[#This Row],[DepartmentCode]])<100,0,1) -> 0 | E197: =IF(LEN(DEPTS[[#This Row],[Title]])<100,0,1) -> 0 | F197: =SUM(DEPTS[[#This Row],[FundIssue]:[Title length check]]) -> 0 | G197: DEP | H197: Depreciation | I197: FALSE | J197: ALS,WVP,MLB,MAT | K197: DEFAULT | L197: DEFAULT | M197: CAPITAL | O197: TRUE
A198: =IF(COUNTIF(FUNDS[FundCode],DEPTS[[#This Row],[FundCode]])>0,0,1) -> 0 | B198: =IF(COUNTIF(ACTIVITIES[ActivityCode],DEPTS[[#This Row],[ActivityCode]])>0,0,1) -> 0 | C198: =IF(COUNTIF(LEDGER[LedgerCode],DEPTS[[#This Row],[LedgerCode]])>0,0,1) -> 0 | D198: =IF(LEN(DEPTS[[#This Row],[DepartmentCode]])<100,0,1) -> 0 | E198: =IF(LEN(DEPTS[[#This Row],[Title]])<100,0,1) -> 0 | F198: =SUM(DEPTS[[#This Row],[FundIssue]:[Title length check]]) -> 0 | G198: DEP | H198: Depreciation | I198: FALSE | J198: HIG | K198: DEFAULT | L198: RESTFA | M198: CAPITAL | O198: TRUE
A199: =IF(COUNTIF(FUNDS[FundCode],DEPTS[[#This Row],[FundCode]])>0,0,1) -> 0 | B199: =IF(COUNTIF(ACTIVITIES[ActivityCode],DEPTS[[#This Row],[ActivityCode]])>0,0,1) -> 0 | C199: =IF(COUNTIF(LEDGER[LedgerCode],DEPTS[[#This Row],[LedgerCode]])>0,0,1) -> 0 | D199: =IF(LEN(DEPTS[[#This Row],[DepartmentCode]])<100,0,1) -> 0 | E199: =IF(LEN(DEPTS[[#This Row],[Title]])<100,0,1) -> 0 | F199: =SUM(DEPTS[[#This Row],[FundIssue]:[Title length check]]) -> 0 | G199: EXAGSS | H199: Agency Supply Staff | I199: FALSE | J199: MAT | K199: DEFAULT | L199: DEFAULT | M199: COSTCENTRES | O199: TRUE
A200: =IF(COUNTIF(FUNDS[FundCode],DEPTS[[#This Row],[FundCode]])>0,0,1) -> 0 | B200: =IF(COUNTIF(ACTIVITIES[ActivityCode],DEPTS[[#This Row],[ActivityCode]])>0,0,1) -> 0 | C200: =IF(COUNTIF(LEDGER[LedgerCode],DEPTS[[#This Row],[LedgerCode]])>0,0,1) -> 0 | D200: =IF(LEN(DEPTS[[#This Row],[DepartmentCode]])<100,0,1) -> 0 | E200: =IF(LEN(DEPTS[[#This Row],[Title]])<100,0,1) -> 0 | F200: =SUM(DEPTS[[#This Row],[FundIssue]:[Title length check]]) -> 0 | G200: EXAGSS | H200: Agency Supply Staff | I200: FALSE | J200: AUD,BLS,MLB,PTP | K200: DEFAULT | L200: DEFAULT | M200: COSTCTR | O200: TRUE
A201: =IF(COUNTIF(FUNDS[FundCode],DEPTS[[#This Row],[FundCode]])>0,0,1) -> 0 | B201: =IF(COUNTIF(ACTIVITIES[ActivityCode],DEPTS[[#This Row],[ActivityCode]])>0,0,1) -> 0 | C201: =IF(COUNTIF(LEDGER[LedgerCode],DEPTS[[#This Row],[LedgerCode]])>0,0,1) -> 0 | D201: =IF(LEN(DEPTS[[#This Row],[DepartmentCode]])<100,0,1) -> 0 | E201: =IF(LEN(DEPTS[[#This Row],[Title]])<100,0,1) -> 0 | F201: =SUM(DEPTS[[#This Row],[FundIssue]:[Title length check]]) -> 0 | G201: EXAGSS | H201: Agency Supply Staff | I201: FALSE | J201: ALS,WVP,HIG,SBL | K201: SCHOOL | L201: DEFAULT | M201: COSTCTR | O201: TRUE
A202: =IF(COUNTIF(FUNDS[FundCode],DEPTS[[#This Row],[FundCode]])>0,0,1) -> 0 | B202: =IF(COUNTIF(ACTIVITIES[ActivityCode],DEPTS[[#This Row],[ActivityCode]])>0,0,1) -> 0 | C202: =IF(COUNTIF(LEDGER[LedgerCode],DEPTS[[#This Row],[LedgerCode]])>0,0,1) -> 0 | D202: =IF(LEN(DEPTS[[#This Row],[DepartmentCode]])<100,0,1) -> 0 | E202: =IF(LEN(DEPTS[[#This Row],[Title]])<100,0,1) -> 0 | F202: =SUM(DEPTS[[#This Row],[FundIssue]:[Title length check]]) -> 0 | G202: EXAM | H202: Examinations | I202: FALSE | J202: MAT | K202: DEFAULT | L202: DEFAULT | M202: COSTCENTRES | O202: TRUE
A203: =IF(COUNTIF(FUNDS[FundCode],DEPTS[[#This Row],[FundCode]])>0,0,1) -> 0 | B203: =IF(COUNTIF(ACTIVITIES[ActivityCode],DEPTS[[#This Row],[ActivityCode]])>0,0,1) -> 0 | C203: =IF(COUNTIF(LEDGER[LedgerCode],DEPTS[[#This Row],[LedgerCode]])>0,0,1) -> 0 | D203: =IF(LEN(DEPTS[[#This Row],[DepartmentCode]])<100,0,1) -> 0 | E203: =IF(LEN(DEPTS[[#This Row],[Title]])<100,0,1) -> 0 | F203: =SUM(DEPTS[[#This Row],[FundIssue]:[Title length check]]) -> 0 | G203: EXAM | H203: Examinations | I203: FALSE | J203: BLS,MLB | K203: DEFAULT | L203: DEFAULT | M203: COSTCTR | O203: TRUE
A204: =IF(COUNTIF(FUNDS[FundCode],DEPTS[[#This Row],[FundCode]])>0,0,1) -> 0 | B204: =IF(COUNTIF(ACTIVITIES[ActivityCode],DEPTS[[#This Row],[ActivityCode]])>0,0,1) -> 0 | C204: =IF(COUNTIF(LEDGER[LedgerCode],DEPTS[[#This Row],[LedgerCode]])>0,0,1) -> 0 | D204: =IF(LEN(DEPTS[[#This Row],[DepartmentCode]])<100,0,1) -> 0 | E204: =IF(LEN(DEPTS[[#This Row],[Title]])<100,0,1) -> 0 | F204: =SUM(DEPTS[[#This Row],[FundIssue]:[Title length check]]) -> 0 | G204: EXAM | H204: Examinations | I204: FALSE | J204: ALS | K204: SCHOOL | L204: DEFAULT | M204: COSTCTR | O204: TRUE
A205: =IF(COUNTIF(FUNDS[FundCode],DEPTS[[#This Row],[FundCode]])>0,0,1) -> 0 | B205: =IF(COUNTIF(ACTIVITIES[ActivityCode],DEPTS[[#This Row],[ActivityCode]])>0,0,1) -> 0 | C205: =IF(COUNTIF(LEDGER[LedgerCode],DEPTS[[#This Row],[LedgerCode]])>0,0,1) -> 0 | D205: =IF(LEN(DEPTS[[#This Row],[DepartmentCode]])<100,0,1) -> 0 | E205: =IF(LEN(DEPTS[[#This Row],[Title]])<100,0,1) -> 0 | F205: =SUM(DEPTS[[#This Row],[FundIssue]:[Title length check]]) -> 0 | G205: EXASTRO | H205: Astro Turf | I205: FALSE | J205: ALS | K205: SCHOOL | L205: RESTFA | M205: CAPITAL | O205: TRUE
A206: =IF(COUNTIF(FUNDS[FundCode],DEPTS[[#This Row],[FundCode]])>0,0,1) -> 0 | B206: =IF(COUNTIF(ACTIVITIES[ActivityCode],DEPTS[[#This Row],[ActivityCode]])>0,0,1) -> 0 | C206: =IF(COUNTIF(LEDGER[LedgerCode],DEPTS[[#This Row],[LedgerCode]])>0,0,1) -> 0 | D206: =IF(LEN(DEPTS[[#This Row],[DepartmentCode]])<100,0,1) -> 0 | E206: =IF(LEN(DEPTS[[#This Row],[Title]])<100,0,1) -> 0 | F206: =SUM(DEPTS[[#This Row],[FundIssue]:[Title length check]]) -> 0 | G206: EXCAPCIF19 | H206: CIF 2019/20 | I206: FALSE | J206: WVP | K206: SCHOOL | L206: RESTFA | M206: CAPITAL | O206: TRUE
A207: =IF(COUNTIF(FUNDS[FundCode],DEPTS[[#This Row],[FundCode]])>0,0,1) -> 0 | B207: =IF(COUNTIF(ACTIVITIES[ActivityCode],DEPTS[[#This Row],[ActivityCode]])>0,0,1) -> 0 | C207: =IF(COUNTIF(LEDGER[LedgerCode],DEPTS[[#This Row],[LedgerCode]])>0,0,1) -> 0 | D207: =IF(LEN(DEPTS[[#This Row],[DepartmentCode]])<100,0,1) -> 0 | E207: =IF(LEN(DEPTS[[#This Row],[Title]])<100,0,1) -> 0 | F207: =SUM(DEPTS[[#This Row],[FundIssue]:[Title length check]]) -> 0 | G207: EXCAPCIF20 | H207: CIF 2020/21 | I207: FALSE | J207: ALS,WVP | K207: SCHOOL | L207: RESTFA | M207: CAPITAL | O207: TRUE
A208: =IF(COUNTIF(FUNDS[FundCode],DEPTS[[#This Row],[FundCode]])>0,0,1) -> 0 | B208: =IF(COUNTIF(ACTIVITIES[ActivityCode],DEPTS[[#This Row],[ActivityCode]])>0,0,1) -> 0 | C208: =IF(COUNTIF(LEDGER[LedgerCode],DEPTS[[#This Row],[LedgerCode]])>0,0,1) -> 0 | D208: =IF(LEN(DEPTS[[#This Row],[DepartmentCode]])<100,0,1) -> 0 | E208: =IF(LEN(DEPTS[[#This Row],[Title]])<100,0,1) -> 0 | F208: =SUM(DEPTS[[#This Row],[FundIssue]:[Title length check]]) -> 0 | G208: EXCAPCIF20 | H208: CIF 2020/21 | I208: FALSE | J208: MAT | K208: SCHOOL | L208: RESTFA | M208: COSTCENTRES | O208: TRUE
... A454: =IF(COUNTIF(FUNDS[FundCode],DEPTS[[#This Row],[FundCode]])>0,0,1) -> 0 | B454: =IF(COUNTIF(ACTIVITIES[ActivityCode],DEPTS[[#This Row],[ActivityCode]])>0,0,1) -> 0 | C454: =IF(COUNTIF(LEDGER[LedgerCode],DEPTS[[#This Row],[LedgerCode]])>0,0,1) -> 0 | D454: =IF(LEN(DEPTS[[#This Row],[DepartmentCode]])<100,0,1) -> 0 | E454: =IF(LEN(DEPTS[[#This Row],[Title]])<100,0,1) -> 0 | F454: =SUM(DEPTS[[#This Row],[FundIssue]:[Title length check]]) -> 0 | G454: WORK | H454: Core Enrichment | I454: FALSE | J454: ALS | K454: SCHOOL | L454: DEFAULT | M454: COSTCTR | O454: TRUE

Sheet SourceFinanceCodes
A1: School Type | B1: LA | C1: London Weighting | D1: Key stage | E1: FinanceCode | F1: Title | G1: FinanceCodeTypeCode | H1: GroupingCode2 | I1: CustomGrouping | J1: LedgerCode | K1: AvailableToAllSchools | L1: SchoolCodes | M1: FinanceCodeEnabled | N1: BalanceToScenario
A2: All | E2: A_FTE_ADM | F2: Finance Admin Annual FTE | G2: STATISTICS | H2: Z05 | I2: ZZZ | K2: TRUE | M2: TRUE | N2: FALSE
A3: All | E3: A_FTE_CAT | F3: Catering Annual FTE | G3: STATISTICS | H3: Z05 | I3: ZZZ | K3: TRUE | M3: TRUE | N3: FALSE
A4: All | E4: A_FTE_CLE | F4: Cleaning Annual FTE | G4: STATISTICS | H4: Z05 | I4: ZZZ | K4: TRUE | M4: TRUE | N4: FALSE
A5: All | E5: A_FTE_COM | F5: Community Facilities Annual FTE | G5: STATISTICS | H5: Z05 | I5: ZZZ | K5: TRUE | M5: TRUE | N5: FALSE
A6: All | E6: A_FTE_COV | F6: Cover Annual FTE | G6: STATISTICS | H6: Z05 | I6: ZZZ | K6: TRUE | M6: TRUE | N6: FALSE
A7: All | E7: A_FTE_EDS | F7: Education Support Annual FTE | G7: STATISTICS | H7: Z05 | I7: ZZZ | K7: TRUE | M7: TRUE | N7: FALSE
A8: All | E8: A_FTE_ESTF | F8: External Staff Annual FTE | G8: STATISTICS | H8: ZZZ | I8: ZZZ | K8: TRUE | M8: TRUE | N8: FALSE
A9: All | E9: A_FTE_EXT | F9: Extended Schools Annual FTE | G9: STATISTICS | H9: Z05 | I9: ZZZ | K9: TRUE | M9: TRUE | N9: FALSE
A10: All | E10: A_FTE_FLA | F10: FLA Annual FTE | G10: STATISTICS | H10: Z05 | I10: ZZZ | K10: TRUE | M10: TRUE | N10: FALSE
A11: All | E11: A_FTE_FSW | F11: Family Support Annual FTE | G11: STATISTICS | H11: Z05 | I11: ZZZ | K11: TRUE | M11: TRUE | N11: FALSE
A12: All | E12: A_FTE_INV | F12: Invigilator Annual FTE | G12: STATISTICS | H12: Z05 | I12: ZZZ | K12: TRUE | M12: TRUE | N12: FALSE
A13: All | E13: A_FTE_LEAVE_ADJ_ADM | F13: Finance Admin Annual FTE Leave Adjustment | G13: STATISTICS | H13: Z17 | I13: ZZZ | K13: TRUE | M13: TRUE | N13: FALSE
... A92: All | E92: WK_FTE_TEC | F92: Technicians Weekly FTE | G92: STATISTICS | H92: Z03 | I92: ZZZ | K92: TRUE | M92: TRUE | N92: FALSE

Sheet Finance Codes S2
