Workbook
Name BuildYear: Parameters!$B$5

Sheet Parameters
A1: VERSION | B1: 1.101
A3: Parameter | B3: Value | D3: Link updated? | E3: No
A4: Token
A5: Year From | B5: 2023/24
A6: Api Url Root | B6: https://api.impplanner.co.uk
A7: Date Last Amended | B7: 45868 | D7: update to today date (shortcut is CTRL + ;)
A9: Element | B9: Type
A10: CALCULATIONS | B10: SIMPLE

Sheet Notes
A1: Process Notes
A3: Updating API
A5: Step
A6: 1 | B6: Add API code to parameter tab
A28: 2 | B28: Navigate to the queries and connections in Data tab
A51: 3 | B51: This will bring up a side menu
A104: 4 | B104: Right click on the API folder and click "Refresh"
A147: 5 | B147: If the below pop-up appears please tick the "Ignore Privacy Levels" box and then click the "Save" button.
A164: 6 | B164: If the below pop-up appears please click the "Don't Update" button.
A174: Schools
A176: Step
A177: 1 | B177: London Weighting Type needs to be updated with the correct type from the drop down. This is based on the Local authority, whose weighting can be found in column "Teachers IL/OL/FRI" of the "Local Authorities - standard codes" document.
A193: #VALUE!

Sheet Build Checklist
A1: Checklist
A2: Task | B2: Notes | C2: Error Check
A3: Check for PayScale Issues | C3: =SUM(PAYSCALES[Will Import if 0]) -> 0
A4: Check for PayScale Point Issues | C4: =SUM(PSPOINTS[Will Import if 0]) -> 0
A5: Check for PayScale Increase % Issues | C5: =SUM(PS_INCPERC[Will Import if 0]) -> 0
A6: Check for PayScale Grades Issues | C6: =SUM(GRADES[Will Import if 0]) -> 0
A7: Check Allowance Type Issues | C7: =SUM(ALLWCTYPE[Will Import if 0]) -> 0
A8: Check Allowance Point Issues | C8: =SUM(ALLWCPTS[Will import if 0]) -> 0
A9: Check Allowance Increase % Issues | C9: =SUM(AL_INCPERC[Will Import if 0]) -> 0
A10: Check for Pensions Issues | C10: =SUM(PENS[Will import if 0]) -> 0
A11: Check for EQWP Issues | C11: =SUM(EQW[Will import if 0]) -> 0
A12: Check for Staff Members Issues | C12: =SUM(MEMBERS[Will Import if 0]) -> 13
A13: Check for Staff Role Groups Issues | C13: =SUM(SRG[Will Import if 0]) -> 221
A14: Check for Staff Roles Issues | C14: =SUM(ROLES[Will Import if 0]) -> 102
A15: Check for Contract Issues (Teacher) | C15: =SUM(CONT_TEA[Will Import if 0]) -> #N/A
A16: Check for Contract Issues (Support) | C16: =SUM(CONT_SUP[Will Import if 0]) -> #N/A
A17: Check Adjustment Type Issues | C17: =SUM(ADJTYPE[Will import if 0]) -> 0
A18: Check Contract Adjustment Issues | C18: =SUM(CONTADJ[Will import if 0]) -> 5
A19: Check Contract Allowance Issues | C19: =SUM(CONTAL[Will import if 0]) -> #N/A
A20: Check Leave Types Issues | C20: =SUM(LEAVES[Will Import if 0]) -> 0
A21: Check Staff Member Leaves Issues | C21: =SUM(SM_LEAVES[Will Import if 0]) -> 10
A22: Check Finance Codes S2 Issues (Ledger needed?) | C22: =SUM(FC_import[Will Import if 0]) -> 91
A23: Total Tab Check | C23: =SUM(C3:C22) -> #N/A
A24: Have the Scope Document info / Email Responses been reviewed?
A25: Do funds need to be assigned at Scenario Row Level? (See Scope Document info)
A26: If not standard, did we receive and check Statutory leave types?
A27: Do contract effective dates match the dates provided in the Scope Document?
A28: Have we built all the PayScales provided?
A29: Did we build contracts for all locations?
A30: Have all pension rates been supplied?
A31: Do PayScales increment and increase in line with Scope Document info?
A32: Are full time hours - for roles/locations - in line with Scope Document info?
A33: Are notes added to Import Checklist (and against task row, this tab) to explain all 'non-errors' with an Error Check score (Col C)?
A34: Are there any SRG Critical Errors which will prevent successful Import? - if YES - alert LC to issue
A35: Excluded contracts/ allowances - Do any excluded lines have budgetary impact (ie. data lines show salary / allowance cost)?
... A40: Review purposes - If Salaries in data YES, is this part of your Staff Contract Build Reconciliation? If not, please alert LC to any issue
A42: Reviewed by Builder | B42: Y/N
A43: Reviewed by Lead Consultant | B43: Y/N

Sheet Import Checklist
B1: Checklist
B2: If this is not zero - return to builder | C2: =SUM('Build Checklist'!C21) -> 10
A3: Column1 | B3: Task | C3: Number of Rows to Import | D3: Number of Rows Imported | E3: Import Checked | F3: LC Import Notes | G3: Builder Import Notes | H3: Importer Notes/Issues
A4: 11 | B4: Finance codes S2 | C4: =COUNTA(FC_import[FinanceCode]) -> 91 | E4: =IF(C4=D4,TRUE,FALSE) -> FALSE
A5: 16 | B5: Allowance Type | C5: =COUNTA(ALLWCTYPE[AllowanceTypeCode]) -> 2 | E5: =IF(C5=D5,TRUE,FALSE) -> FALSE
A6: 17 | B6: Allowance Point | C6: =COUNTA(ALLWCPTS[AllowanceTypeCode]) -> 10 | E6: =IF(C6=D6,TRUE,FALSE) -> FALSE
A7: 18 | B7: Allowance Increase % | C7: =COUNTA(AL_INCPERC[AllowanceTypeCode]) -> 2 | E7: =IF(C7=D7,TRUE,FALSE) -> FALSE
A8: 19 | B8: Payscales | C8: =COUNTA(PAYSCALES[PayScaleEnabled]) -> 22 | E8: =IF(C8=D8,TRUE,FALSE) -> FALSE
A9: 20 | B9: Payscale Points | C9: =COUNTIF(PSPOINTS[PayScalePointEnabled],TRUE) -> 492 | E9: =IF(C9=D9,TRUE,FALSE) -> FALSE
A10: 21 | B10: Payscale Increase Percentages | C10: =COUNTA(PS_INCPERC[IncreasePercentage]) -> 19 | E10: =IF(C10=D10,TRUE,FALSE) -> FALSE
A11: 22 | B11: Payscale Grades | C11: =COUNTA(GRADES[PayScaleGradeEnabled]) -> 33 | E11: =IF(C11=D11,TRUE,FALSE) -> FALSE
A12: 23 | B12: Equated Week Patterns | C12: =COUNTA(EQW[EquatedWeekPatternEnabled]) -> 1 | E12: =IF(C12=D12,TRUE,FALSE) -> FALSE
A13: 24 | B13: Pensions | C13: =COUNTA(PENS[PensionEnabled]) -> 3 | E13: =IF(C13=D13,TRUE,FALSE) -> FALSE
A14: 25 | B14: Staff Members | C14: =COUNTA(MEMBERS[StaffMemberEnabled]) -> 1 | E14: =IF(C14=D14,TRUE,FALSE) -> FALSE
A15: 26 | B15: Staff Role Groups | C15: =COUNTA(SRG[StaffRoleGroupEnabled]) -> 17 | E15: =IF(C15=D15,TRUE,FALSE) -> FALSE
A16: 27 | B16: Staff Roles | C16: =COUNTA(ROLES[StaffRoleEnabled]) -> 34 | E16: =IF(C16=D16,TRUE,FALSE) -> FALSE
A17: 28 | B17: Contract (Teacher) | C17: =COUNTA(CONT_TEA[StaffMemberCode]) -> 1 | E17: =IF(C17=D17,TRUE,FALSE) -> FALSE | F17: If Values are built as FTE - Check that you have selected FTE!
A18: 29 | B18: Contract (Support) | C18: =COUNTA(CONT_SUP[StaffMemberCode]) -> 1 | E18: =IF(C18=D18,TRUE,FALSE) -> FALSE
A19: 30 | B19: Leave Types | C19: =COUNTA(LEAVES[LeaveTypeEnabled]) -> 33 | E19: =IF(C19=D19,TRUE,FALSE) -> FALSE
A20: 31 | B20: Adjustments | C20: =COUNTA(ADJTYPE[AdjustmentTypeCode]) -> 2 | E20: =IF(C20=D20,TRUE,FALSE) -> FALSE
A21: 32 | B21: Staff Member Leaves | C21: =COUNTA(SM_LEAVES[StaffMemberCode]) -> 0 | E21: =IF(C21=D21,TRUE,FALSE) -> TRUE | F21: Imports - Maternity Start must not pre-date contract start. Import as-is for base weekly pay to calc, then manually backdate the Mat From date in Planner if needed.
A22: 33 | B22: Contract Adjustments | C22: =COUNTA(CONTADJ[SchoolCode]) -> 1 | E22: =IF(C22=D22,TRUE,FALSE) -> FALSE
A23: 34 | B23: Contract Allowances | C23: =COUNTA(CONTAL[StaffMemberCode]) -> 1 | E23: =IF(C23=D23,TRUE,FALSE) -> FALSE

Sheet System Grouping Codes
A1: groupingCodeCode | B1: title | C1: groupingCodeTypeCode
A2: 510100 | B2: IN: DfE Revenue Grants: GAG (not stud supp and trust grants) | C2: A
A3: 510110 | B3: IN: DfE Revenue Grants: GAG (student support) | C3: A
A4: 510120 | B4: IN: DfE Revenue Grants: GAG (start up grants) | C4: A
A5: 510130 | B5: IN: DfE Revenue Grants: Trust level grants | C5: A
A6: 510140 | B6: IN: DfE Revenue Grants: Pupil number adjustment | C6: A
A7: 510150 | B7: IN: DfE Revenue Grants: Rates reclaim | C7: A
A8: 510200 | B8: IN: DfE Revenue Grants: Pupil Premium | C8: A
A9: 510250 | B9: IN: DfE Revenue Grants: Universal Inf Free School Meals | C9: A
A10: 510300 | B10: IN: DfE Revenue Grants: Insurance top up | C10: A
A11: 510350 | B11: IN: DfE Revenue Grants: Sponsor capacity grant | C11: A
A12: 510400 | B12: IN: DfE Revenue Grants: PE & Sports grant | C12: A
... A481: ZZZ | B481: Not Applicable | C481: ZZZ

Sheet Funds
G1: API - Do not edit
A2: Code is Blank | B2: Title is Blank | C2: Enabled is blank | D2: Code length Check | E2: Title length check | F2: Will import if zero | G2: FundCode | H2: Title | I2: FundEnabled
A3: =ISBLANK(FUNDS[[#This Row],[FundCode]]) -> FALSE | B3: =ISBLANK(FUNDS[[#This Row],[Title]]) -> FALSE | C3: =ISBLANK(FUNDS[[#This Row],[FundEnabled]]) -> FALSE | D3: =IF(LEN(FUNDS[[#This Row],[FundCode]])<100,FALSE,TRUE) -> FALSE | E3: =IF(LEN(FUNDS[[#This Row],[Title]])<100,FALSE,TRUE) -> FALSE | F3: =COUNTIF(FUNDS[[#This Row],[Code is Blank]:[Title length check]],"TRUE") -> 0 | G3: DEFAULT | H3: DEFAULT | I3: TRUE
A4: =ISBLANK(FUNDS[[#This Row],[FundCode]]) -> FALSE | B4: =ISBLANK(FUNDS[[#This Row],[Title]]) -> FALSE | C4: =ISBLANK(FUNDS[[#This Row],[FundEnabled]]) -> FALSE | D4: =IF(LEN(FUNDS[[#This Row],[FundCode]])<100,FALSE,TRUE) -> FALSE | E4: =IF(LEN(FUNDS[[#This Row],[Title]])<100,FALSE,TRUE) -> FALSE | F4: =COUNTIF(FUNDS[[#This Row],[Code is Blank]:[Title length check]],"TRUE") -> 0 | G4: 01 | H4: title | I4: TRUE

Sheet Activity
G1: API - Do not edit
A2: Code is Blank | B2: Title is Blank | C2: Code length Check | D2: Title length check | E2: Enabled is blank | F2: Will import if zero | G2: ActivityCode | H2: Title | I2: ActivityEnabled
A3: =ISBLANK(ACTIVITIES[[#This Row],[ActivityCode]]) -> FALSE | B3: =ISBLANK(ACTIVITIES[[#This Row],[Title]]) -> FALSE | C3: =IF(LEN(ACTIVITIES[[#This Row],[ActivityCode]])<100,FALSE,TRUE) -> FALSE | D3: =IF(LEN(ACTIVITIES[[#This Row],[Title]])<100,FALSE,TRUE) -> FALSE | E3: =ISBLANK(ACTIVITIES[[#This Row],[ActivityEnabled]]) -> FALSE | F3: =COUNTIF(ACTIVITIES[[#This Row],[Code is Blank]:[Enabled is blank]],"TRUE") -> 0 | G3: DEFAULT | H3: Default (no) Activity | I3: TRUE

Sheet Ledger
G1: API - Do not edit
A2: Code is Blank | B2: Title is Blank | C2: Enabled is blank | D2: Code length Check | E2: Title length check | F2: Will import if zero | G2: LedgerCode | H2: Title | I2: LedgerEnabled
A3: =ISBLANK(LEDGER[[#This Row],[LedgerCode]]) -> FALSE | B3: =ISBLANK(LEDGER[[#This Row],[Title]]) -> FALSE | C3: =ISBLANK(LEDGER[[#This Row],[LedgerEnabled]]) -> FALSE | D3: =IF(LEN(LEDGER[[#This Row],[LedgerCode]])<100,FALSE,TRUE) -> FALSE | E3: =IF(LEN(LEDGER[[#This Row],[Title]])<100,FALSE,TRUE) -> FALSE | F3: =COUNTIF(LEDGER[[#This Row],[Code is Blank]:[Title length check]],"TRUE") -> 0 | G3: DEFAULT | H3: Default (no) Ledger | I3: TRUE
A4: =ISBLANK(LEDGER[[#This Row],[LedgerCode]]) -> FALSE | B4: =ISBLANK(LEDGER[[#This Row],[Title]]) -> FALSE | C4: =ISBLANK(LEDGER[[#This Row],[LedgerEnabled]]) -> FALSE | D4: =IF(LEN(LEDGER[[#This Row],[LedgerCode]])<100,FALSE,TRUE) -> FALSE | E4: =IF(LEN(LEDGER[[#This Row],[Title]])<100,FALSE,TRUE) -> FALSE | F4: =COUNTIF(LEDGER[[#This Row],[Code is Blank]:[Title length check]],"TRUE") -> 0 | G4: DEPARTMENTS | H4: Departments Ledger | I4: TRUE

Sheet CustGroup
G1: API - Do not edit
A2: Code is Blank | B2: Title is Blank | C2: Code length Check | D2: Title length check | E2: Enabled is blank | F2: Will import if zero | G2: CustomGroupingCode | H2: Title | I2: CustomGroupingEnabled
A3: =ISBLANK(CUSTGROUP[[#This Row],[CustomGroupingCode]]) -> FALSE | B3: =ISBLANK(CUSTGROUP[[#This Row],[Title]]) -> FALSE | C3: =IF(LEN(CUSTGROUP[[#This Row],[CustomGroupingCode]])<100,FALSE,TRUE) -> FALSE | D3: =IF(LEN(CUSTGROUP[[#This Row],[Title]])<100,FALSE,TRUE) -> FALSE | E3: =ISBLANK(CUSTGROUP[[#This Row],[CustomGroupingEnabled]]) -> FALSE | F3: =COUNTIF(CUSTGROUP[[#This Row],[Code is Blank]:[Enabled is blank]],"TRUE") -> 0 | G3: ZZZ | H3: Default Custom Group | I3: TRUE

Sheet SchHub
G1: API - Do not edit
A2: Code is Blank | B2: Title is Blank | C2: Enabled is blank | D2: Code length Check | E2: Title length check | F2: Will import if zero | G2: SchoolHubCode | H2: Title | I2: SchoolHubEnabled
A3: =ISBLANK(SCHHUB[[#This Row],[SchoolHubCode]]) -> FALSE | B3: =ISBLANK(SCHHUB[[#This Row],[Title]]) -> FALSE | C3: =ISBLANK(SCHHUB[[#This Row],[SchoolHubEnabled]]) -> FALSE | D3: =IF(LEN(SCHHUB[[#This Row],[SchoolHubCode]])<100,FALSE,TRUE) -> FALSE | E3: =IF(LEN(SCHHUB[[#This Row],[Title]])<100,FALSE,TRUE) -> FALSE | F3: =COUNTIF(SCHHUB[[#This Row],[Code is Blank]:[Title length check]],"TRUE") -> 0 | G3: MAT | H3: Mat Hub | I3: TRUE
A4: =ISBLANK(SCHHUB[[#This Row],[SchoolHubCode]]) -> FALSE | B4: =ISBLANK(SCHHUB[[#This Row],[Title]]) -> FALSE | C4: =ISBLANK(SCHHUB[[#This Row],[SchoolHubEnabled]]) -> FALSE | D4: =IF(LEN(SCHHUB[[#This Row],[SchoolHubCode]])<100,FALSE,TRUE) -> FALSE | E4: =IF(LEN(SCHHUB[[#This Row],[Title]])<100,FALSE,TRUE) -> FALSE | F4: =COUNTIF(SCHHUB[[#This Row],[Code is Blank]:[Title length check]],"TRUE") -> 0 | G4: DEFAULT | H4: Default | I4: TRUE

Sheet SchType
G1: API - Do not edit
A2: Code is Blank | B2: Title is Blank | C2: Enabled is blank | D2: Code length Check | E2: Title length check | F2: Will import if zero | G2: SchoolTypeCode | H2: Title | I2: SchoolTypeEnabled
A3: =ISBLANK(SCHTYPE[[#This Row],[SchoolTypeCode]]) -> FALSE | B3: =ISBLANK(SCHTYPE[[#This Row],[Title]]) -> FALSE | C3: =ISBLANK(SCHTYPE[[#This Row],[SchoolTypeEnabled]]) -> FALSE | D3: =IF(LEN(SCHTYPE[[#This Row],[SchoolTypeCode]])<100,FALSE,TRUE) -> FALSE | E3: =IF(LEN(SCHTYPE[[#This Row],[Title]])<100,FALSE,TRUE) -> FALSE | F3: =COUNTIF(SCHTYPE[[#This Row],[Code is Blank]:[Title length check]],"TRUE") -> 0 | G3: CENTRAL | H3: Central Services | I3: TRUE
A4: =ISBLANK(SCHTYPE[[#This Row],[SchoolTypeCode]]) -> FALSE | B4: =ISBLANK(SCHTYPE[[#This Row],[Title]]) -> FALSE | C4: =ISBLANK(SCHTYPE[[#This Row],[SchoolTypeEnabled]]) -> FALSE | D4: =IF(LEN(SCHTYPE[[#This Row],[SchoolTypeCode]])<100,FALSE,TRUE) -> FALSE | E4: =IF(LEN(SCHTYPE[[#This Row],[Title]])<100,FALSE,TRUE) -> FALSE | F4: =COUNTIF(SCHTYPE[[#This Row],[Code is Blank]:[Title length check]],"TRUE") -> 0 | G4: PRIMARY | H4: Primary | I4: TRUE
A5: =ISBLANK(SCHTYPE[[#This Row],[SchoolTypeCode]]) -> FALSE | B5: =ISBLANK(SCHTYPE[[#This Row],[Title]]) -> FALSE | C5: =ISBLANK(SCHTYPE[[#This Row],[SchoolTypeEnabled]]) -> FALSE | D5: =IF(LEN(SCHTYPE[[#This Row],[SchoolTypeCode]])<100,FALSE,TRUE) -> FALSE | E5: =IF(LEN(SCHTYPE[[#This Row],[Title]])<100,FALSE,TRUE) -> FALSE | F5: =COUNTIF(SCHTYPE[[#This Row],[Code is Blank]:[Title length check]],"TRUE") -> 0 | G5: SECONDARY | H5: Secondary | I5: TRUE
A6: =ISBLANK(SCHTYPE[[#This Row],[SchoolTypeCode]]) -> FALSE | B6: =ISBLANK(SCHTYPE[[#This Row],[Title]]) -> FALSE | C6: =ISBLANK(SCHTYPE[[#This Row],[SchoolTypeEnabled]]) -> FALSE | D6: =IF(LEN(SCHTYPE[[#This Row],[SchoolTypeCode]])<100,FALSE,TRUE) -> FALSE | E6: =IF(LEN(SCHTYPE[[#This Row],[Title]])<100,FALSE,TRUE) -> FALSE | F6: =COUNTIF(SCHTYPE[[#This Row],[Code is Blank]:[Title length check]],"TRUE") -> 0 | G6: ALLTHROUGH | H6: All Through | I6: TRUE
A7: =ISBLANK(SCHTYPE[[#This Row],[SchoolTypeCode]]) -> FALSE | B7: =ISBLANK(SCHTYPE[[#This Row],[Title]]) -> FALSE | C7: =ISBLANK(SCHTYPE[[#This Row],[SchoolTypeEnabled]]) -> FALSE | D7: =IF(LEN(SCHTYPE[[#This Row],[SchoolTypeCode]])<100,FALSE,TRUE) -> FALSE | E7: =IF(LEN(SCHTYPE[[#This Row],[Title]])<100,FALSE,TRUE) -> FALSE | F7: =COUNTIF(SCHTYPE[[#This Row],[Code is Blank]:[Title length check]],"TRUE") -> 0 | G7: TEACHING | H7: Teaching | I7: TRUE
A8: =ISBLANK(SCHTYPE[[#This Row],[SchoolTypeCode]]) -> FALSE | B8: =ISBLANK(SCHTYPE[[#This Row],[Title]]) -> FALSE | C8: =ISBLANK(SCHTYPE[[#This Row],[SchoolTypeEnabled]]) -> FALSE | D8: =IF(LEN(SCHTYPE[[#This Row],[SchoolTypeCode]])<100,FALSE,TRUE) -> FALSE | E8: =IF(LEN(SCHTYPE[[#This Row],[Title]])<100,FALSE,TRUE) -> FALSE | F8: =COUNTIF(SCHTYPE[[#This Row],[Code is Blank]:[Title length check]],"TRUE") -> 0 | G8: SPECIAL | H8: Special | I8: TRUE
A9: =ISBLANK(SCHTYPE[[#This Row],[SchoolTypeCode]]) -> FALSE | B9: =ISBLANK(SCHTYPE[[#This Row],[Title]]) -> FALSE | C9: =ISBLANK(SCHTYPE[[#This Row],[SchoolTypeEnabled]]) -> FALSE | D9: =IF(LEN(SCHTYPE[[#This Row],[SchoolTypeCode]])<100,FALSE,TRUE) -> FALSE | E9: =IF(LEN(SCHTYPE[[#This Row],[Title]])<100,FALSE,TRUE) -> FALSE | F9: =COUNTIF(SCHTYPE[[#This Row],[Code is Blank]:[Title length check]],"TRUE") -> 0 | G9: OTHER | H9: Other | I9: TRUE
A10: =ISBLANK(SCHTYPE[[#This Row],[SchoolTypeCode]]) -> FALSE | B10: =ISBLANK(SCHTYPE[[#This Row],[Title]]) -> FALSE | C10: =ISBLANK(SCHTYPE[[#This Row],[SchoolTypeEnabled]]) -> FALSE | D10: =IF(LEN(SCHTYPE[[#This Row],[SchoolTypeCode]])<100,FALSE,TRUE) -> FALSE | E10: =IF(LEN(SCHTYPE[[#This Row],[Title]])<100,FALSE,TRUE) -> FALSE | F10: =COUNTIF(SCHTYPE[[#This Row],[Code is Blank]:[Title length check]],"TRUE") -> 0 | G10: LA | H10: LA | I10: TRUE

Sheet LocalAuth
G1: This grey section can be edited | H1: API - Do not edit
A2: Code is Blank | B2: Title is Blank | C2: Enabled is blank | D2: Code length Check | E2: Title length check | F2: Will import if zero | G2: LA | H2: SchoolLocalAuthorityCode | I2: Title | J2: SchoolLocalAuthorityEnabled
A3: =ISBLANK(LocalAuth[[#This Row],[SchoolLocalAuthorityCode]]) -> FALSE | B3: =ISBLANK(LocalAuth[[#This Row],[Title]]) -> FALSE | C3: =ISBLANK(LocalAuth[[#This Row],[SchoolLocalAuthorityEnabled]]) -> FALSE | D3: =IF(LEN(LocalAuth[[#This Row],[SchoolLocalAuthorityCode]])<100,FALSE,TRUE) -> FALSE | E3: =IF(LEN(LocalAuth[[#This Row],[Title]])<100,FALSE,TRUE) -> FALSE | F3: =COUNTIF(LocalAuth[[#This Row],[Code is Blank]:[Title length check]],"TRUE") -> 0 | G3: LA0 | H3: DEFAULT | I3: Default (no) Activity | J3: TRUE
A4: =ISBLANK(LocalAuth[[#This Row],[SchoolLocalAuthorityCode]]) -> FALSE | B4: =ISBLANK(LocalAuth[[#This Row],[Title]]) -> FALSE | C4: =ISBLANK(LocalAuth[[#This Row],[SchoolLocalAuthorityEnabled]]) -> FALSE | D4: =IF(LEN(LocalAuth[[#This Row],[SchoolLocalAuthorityCode]])<100,FALSE,TRUE) -> FALSE | E4: =IF(LEN(LocalAuth[[#This Row],[Title]])<100,FALSE,TRUE) -> FALSE | F4: =COUNTIF(LocalAuth[[#This Row],[Code is Blank]:[Title length check]],"TRUE") -> 0 | G4: LA1 | H4: DEV | I4: Devon | J4: TRUE
A5: =ISBLANK(LocalAuth[[#This Row],[SchoolLocalAuthorityCode]]) -> FALSE | B5: =ISBLANK(LocalAuth[[#This Row],[Title]]) -> FALSE | C5: =ISBLANK(LocalAuth[[#This Row],[SchoolLocalAuthorityEnabled]]) -> FALSE | D5: =IF(LEN(LocalAuth[[#This Row],[SchoolLocalAuthorityCode]])<100,FALSE,TRUE) -> FALSE | E5: =IF(LEN(LocalAuth[[#This Row],[Title]])<100,FALSE,TRUE) -> FALSE | F5: =COUNTIF(LocalAuth[[#This Row],[Code is Blank]:[Title length check]],"TRUE") -> 0 | G5: LA2 | H5: COR | I5: Cornwall | J5: TRUE

Sheet Schools
G1: This grey section can be edited | J1: API - Do not edit
A2: HubIssues | B2: SchTypeIssue | C2: Blank Data | D2: Code length Check | E2: Title length check | F2: Will Import if 0 | G2: London Weighting Type | H2: LA | I2: School Type | J2: SchoolLocalAuthority | K2: SchoolCode | L2: SchoolHub | M2: SchoolType | N2: Title | O2: LondonWeighting | P2: UniqueReferenceNumber | Q2: TeachingHours | R2: SchoolEnabled
A3: =IF(COUNTIF(SCHHUB[SchoolHubCode],SCHOOLS[[#This Row],[SchoolHub]])>0,0,1) -> 0 | B3: =IF(COUNTIF(SCHTYPE[SchoolTypeCode],SCHOOLS[[#This Row],[SchoolType]])>0,0,1) -> 0 | C3: =COUNTBLANK(SCHOOLS[[#This Row],[SchoolLocalAuthority]:[SchoolEnabled]]) -> 0 | D3: =IF(LEN(SCHOOLS[[#This Row],[SchoolCode]])<100,0,1) -> 0 | E3: =IF(LEN(SCHOOLS[[#This Row],[Title]])<100,0,1) -> 0 | F3: =SUM(SCHOOLS[[#This Row],[HubIssues]:[Title length check]]) -> 0 | G3: England & Wales | H3: =_xlfn.XLOOKUP(SCHOOLS[[#This Row],[SchoolLocalAuthority]],LocalAuth[SchoolLocalAuthorityCode],LocalAuth[LA]) -> LA2 | I3: Central | J3: COR | K3: ALL | L3: MAT | M3: ALLTHROUGH | N3: Allthrough | O3: FALSE | P3: 0 | Q3: 32.5 | R3: TRUE
A4: =IF(COUNTIF(SCHHUB[SchoolHubCode],SCHOOLS[[#This Row],[SchoolHub]])>0,0,1) -> 0 | B4: =IF(COUNTIF(SCHTYPE[SchoolTypeCode],SCHOOLS[[#This Row],[SchoolType]])>0,0,1) -> 0 | C4: =COUNTBLANK(SCHOOLS[[#This Row],[SchoolLocalAuthority]:[SchoolEnabled]]) -> 0 | D4: =IF(LEN(SCHOOLS[[#This Row],[SchoolCode]])<100,0,1) -> 0 | E4: =IF(LEN(SCHOOLS[[#This Row],[Title]])<100,0,1) -> 0 | F4: =SUM(SCHOOLS[[#This Row],[HubIssues]:[Title length check]]) -> 0 | G4: England & Wales | H4: =_xlfn.XLOOKUP(SCHOOLS[[#This Row],[SchoolLocalAuthority]],LocalAuth[SchoolLocalAuthorityCode],LocalAuth[LA]) -> LA1 | I4: Secondary | J4: DEV | K4: MAT | L4: MAT | M4: CENTRAL | N4: Central Services | O4: FALSE | P4: 0 | Q4: 32.5 | R4: TRUE
A5: =IF(COUNTIF(SCHHUB[SchoolHubCode],SCHOOLS[[#This Row],[SchoolHub]])>0,0,1) -> 0 | B5: =IF(COUNTIF(SCHTYPE[SchoolTypeCode],SCHOOLS[[#This Row],[SchoolType]])>0,0,1) -> 0 | C5: =COUNTBLANK(SCHOOLS[[#This Row],[SchoolLocalAuthority]:[SchoolEnabled]]) -> 0 | D5: =IF(LEN(SCHOOLS[[#This Row],[SchoolCode]])<100,0,1) -> 0 | E5: =IF(LEN(SCHOOLS[[#This Row],[Title]])<100,0,1) -> 0 | F5: =SUM(SCHOOLS[[#This Row],[HubIssues]:[Title length check]]) -> 0 | G5: England & Wales | H5: =_xlfn.XLOOKUP(SCHOOLS[[#This Row],[SchoolLocalAuthority]],LocalAuth[SchoolLocalAuthorityCode],LocalAuth[LA]) -> LA1 | I5: Primary | J5: DEV | K5: PRI | L5: MAT | M5: PRIMARY | N5: Primary | O5: FALSE | P5: 0 | Q5: 32.5 | R5: TRUE
A6: =IF(COUNTIF(SCHHUB[SchoolHubCode],SCHOOLS[[#This Row],[SchoolHub]])>0,0,1) -> 0 | B6: =IF(COUNTIF(SCHTYPE[SchoolTypeCode],SCHOOLS[[#This Row],[SchoolType]])>0,0,1) -> 0 | C6: =COUNTBLANK(SCHOOLS[[#This Row],[SchoolLocalAuthority]:[SchoolEnabled]]) -> 0 | D6: =IF(LEN(SCHOOLS[[#This Row],[SchoolCode]])<100,0,1) -> 0 | E6: =IF(LEN(SCHOOLS[[#This Row],[Title]])<100,0,1) -> 0 | F6: =SUM(SCHOOLS[[#This Row],[HubIssues]:[Title length check]]) -> 0 | G6: England & Wales | H6: =_xlfn.XLOOKUP(SCHOOLS[[#This Row],[SchoolLocalAuthority]],LocalAuth[SchoolLocalAuthorityCode],LocalAuth[LA]) -> LA1 | I6: AllThrough | J6: DEV | K6: SEC | L6: MAT | M6: SECONDARY | N6: Secondary | O6: FALSE | P6: 0 | Q6: 32.5 | R6: TRUE
A7: =IF(COUNTIF(SCHHUB[SchoolHubCode],SCHOOLS[[#This Row],[SchoolHub]])>0,0,1) -> 0 | B7: =IF(COUNTIF(SCHTYPE[SchoolTypeCode],SCHOOLS[[#This Row],[SchoolType]])>0,0,1) -> 0 | C7: =COUNTBLANK(SCHOOLS[[#This Row],[SchoolLocalAuthority]:[SchoolEnabled]]) -> 0 | D7: =IF(LEN(SCHOOLS[[#This Row],[SchoolCode]])<100,0,1) -> 0 | E7: =IF(LEN(SCHOOLS[[#This Row],[Title]])<100,0,1) -> 0 | F7: =SUM(SCHOOLS[[#This Row],[HubIssues]:[Title length check]]) -> 0 | G7: England & Wales | H7: =_xlfn.XLOOKUP(SCHOOLS[[#This Row],[SchoolLocalAuthority]],LocalAuth[SchoolLocalAuthorityCode],LocalAuth[LA]) -> LA2 | J7: COR | K7: SPE | L7: MAT | M7: SPECIAL | N7: Special | O7: FALSE | P7: 0 | Q7: 32.5 | R7: TRUE

Sheet Depts
G1: API - Do not edit
A2: FundIssue | B2: ActivityIssue | C2: LedgerIssue | D2: Code length Check | E2: Title length check | F2: Will Import if 0 | G2: DepartmentCode | H2: Title | I2: AvailableToAllSchools | J2: SchoolCodes | K2: ActivityCode | L2: FundCode | M2: LedgerCode | N2: DefaultFinanceCode | O2: DepartmentEnabled
A3: =IF(COUNTIF(FUNDS[FundCode],DEPTS[[#This Row],[FundCode]])>0,0,1) -> 1 | B3: =IF(COUNTIF(ACTIVITIES[ActivityCode],DEPTS[[#This Row],[ActivityCode]])>0,0,1) -> 0 | C3: =IF(COUNTIF(LEDGER[LedgerCode],DEPTS[[#This Row],[LedgerCode]])>0,0,1) -> 1 | D3: =IF(LEN(DEPTS[[#This Row],[DepartmentCode]])<100,0,1) -> 0 | E3: =IF(LEN(DEPTS[[#This Row],[Title]])<100,0,1) -> 0 | F3: =SUM(DEPTS[[#This Row],[FundIssue]:[Title length check]]) -> 2 | G3: AADM | H3: Academy - Admin | I3: TRUE | K3: DEFAULT | L3: GAG | M3: COSTCTR | O3: TRUE

Sheet SourceFinanceCodes
A1: School Type | B1: LA | C1: London Weighting | D1: Key stage | E1: FinanceCode | F1: Title | G1: FinanceCodeTypeCode | H1: GroupingCode2 | I1: CustomGrouping | J1: LedgerCode | K1: AvailableToAllSchools | L1: SchoolCodes | M1: FinanceCodeEnabled | N1: BalanceToScenario
A2: All | E2: A_FTE_ADM | F2: Finance Admin Annual FTE | G2: STATISTICS | H2: Z05 | I2: ZZZ | K2: TRUE | M2: TRUE | N2: FALSE
A3: All | E3: A_FTE_CAT | F3: Catering Annual FTE | G3: STATISTICS | H3: Z05 | I3: ZZZ | K3: TRUE | M3: TRUE | N3: FALSE
A4: All | E4: A_FTE_CLE | F4: Cleaning Annual FTE | G4: STATISTICS | H4: Z05 | I4: ZZZ | K4: TRUE | M4: TRUE | N4: FALSE
A5: All | E5: A_FTE_COM | F5: Community Facilities Annual FTE | G5: STATISTICS | H5: Z05 | I5: ZZZ | K5: TRUE | M5: TRUE | N5: FALSE
A6: All | E6: A_FTE_COV | F6: Cover Annual FTE | G6: STATISTICS | H6: Z05 | I6: ZZZ | K6: TRUE | M6: TRUE | N6: FALSE
A7: All | E7: A_FTE_EDS | F7: Education Support Annual FTE | G7: STATISTICS | H7: Z05 | I7: ZZZ | K7: TRUE | M7: TRUE | N7: FALSE
A8: All | E8: A_FTE_ESTF | F8: External Staff Annual FTE | G8: STATISTICS | H8: ZZZ | I8: ZZZ | K8: TRUE | M8: TRUE | N8: FALSE
A9: All | E9: A_FTE_EXT | F9: Extended Schools Annual FTE | G9: STATISTICS | H9: Z05 | I9: ZZZ | K9: TRUE | M9: TRUE | N9: FALSE
A10: All | E10: A_FTE_FLA | F10: FLA Annual FTE | G10: STATISTICS | H10: Z05 | I10: ZZZ | K10: TRUE | M10: TRUE | N10: FALSE
A11: All | E11: A_FTE_FSW | F11: Family Support Annual FTE | G11: STATISTICS | H11: Z05 | I11: ZZZ | K11: TRUE | M11: TRUE | N11: FALSE
A12: All | E12: A_FTE_INV | F12: Invigilator Annual FTE | G12: STATISTICS | H12: Z05 | I12: ZZZ | K12: TRUE | M12: TRUE | N12: FALSE
A13: All | E13: A_FTE_LEAVE_ADJ_ADM | F13: Finance Admin Annual FTE Leave Adjustment | G13: STATISTICS | H13: Z17 | I13: ZZZ | K13: TRUE | M13: TRUE | N13: FALSE
... A92: All | E92: WK_FTE_TEC | F92: Technicians Weekly FTE | G92: STATISTICS | H92: Z03 | I92: ZZZ | K92: TRUE | M92: TRUE | N92: FALSE

Sheet 11_Finance Codes S2
A1: LedgerIssue | B1: GroupingCodeIssue | C1: CustGrIssue | D1: SchCodeIssue | E1: DupCode | F1: DupDesc | G1: FCTypeIss | H1: TRUE/FALSE Check | I1: Code length Check | J1: Blank Title Check | K1: Blank Code Check | L1: Title length check | M1: Balance to Scenario Blank | N1: Space in code | O1: Will Import if 0 | P1: FinanceCode | Q1: Title | R1: FinanceCodeTypeCode | S1: GroupingCode | T1: CustomGrouping | U1: LedgerCode | V1: AvailableToAllSchools | W1: SchoolCodes | X1: FinanceCodeEnabled | Y1: BalanceToScenario | Z1: IsBalanceSheet
A2: =IF(COUNTIF(LEDGER[LedgerCode],FC_import[[#This Row],[LedgerCode]])>0,0,1) -> 1 | B2: =IF(COUNTIF(Table_System_Grouping_Codes[groupingCodeCode],FC_import[[#This Row],[GroupingCode]])>0,0,1) -> 0 | C2: =IF(COUNTIF(CUSTGROUP[CustomGroupingCode],FC_import[[#This Row],[CustomGrouping]])>0,0,1) -> 0 | D2: {=IF(FC_import[[#This Row],[AvailableToAllSchools]]=TRUE,0,COUNTA(_xlfn.TEXTSPLIT(FC_import[[#This Row],[SchoolCodes]],",",,TRUE))-SUM(COUNTIF(SCHOOLS[SchoolCode],_xlfn.TEXTSPLIT(FC_import[[#This Row],[SchoolCodes]],",",,TRUE))))} -> 0 | E2: =IF(FC_import[[#This Row],[FinanceCodeTypeCode]]="BUDGET",0,COUNTIF(P:P,P2)-1) -> 0 | F2: =IF(FC_import[[#This Row],[FinanceCodeTypeCode]]="BUDGET",0,COUNTIF(Q:Q,Q2)-1) -> 0 | G2: =COUNTIF(Lookup!$A$2:$A$7,R2)-1 -> 0 | H2: =IF(OR(FC_import[[#This Row],[FinanceCodeEnabled]]=TRUE,FC_import[[#This Row],[FinanceCodeEnabled]]=FALSE),0,1) -> 0 | I2: =IF(LEN(FC_import[[#This Row],[FinanceCode]])<100,0,1) -> 0 | J2: =IF(TRIM(FC_import[[#This Row],[Title]])="",1,0) -> 0 | K2: =IF(TRIM(FC_import[[#This Row],[FinanceCode]])="",1,0) -> 0 | L2: =IF(LEN(FC_import[[#This Row],[Title]])<100,0,1) -> 0 | M2: =IF(ISBLANK(FC_import[[#This Row],[BalanceToScenario]]),1,0) -> 0 | N2: =IF(SUBSTITUTE(TEXT(FC_import[[#This Row],[FinanceCode]],10)," ","")=TEXT(FC_import[[#This Row],[FinanceCode]],10),0,1) -> 0 | O2: =SUM(A2:C2,E2:N2) -> 1 | P2: A_FTE_ADM | Q2: Finance Admin Annual FTE | R2: STATISTICS | S2: Z05 | T2: ZZZ | V2: TRUE | X2: TRUE | Y2: FALSE | Z2: =FALSE -> FALSE
A3: =IF(COUNTIF(LEDGER[LedgerCode],FC_import[[#This Row],[LedgerCode]])>0,0,1) -> 1 | B3: =IF(COUNTIF(Table_System_Grouping_Codes[groupingCodeCode],FC_import[[#This Row],[GroupingCode]])>0,0,1) -> 0 | C3: =IF(COUNTIF(CUSTGROUP[CustomGroupingCode],FC_import[[#This Row],[CustomGrouping]])>0,0,1) -> 0 | D3: {=IF(FC_import[[#This Row],[AvailableToAllSchools]]=TRUE,0,COUNTA(_xlfn.TEXTSPLIT(FC_import[[#This Row],[SchoolCodes]],",",,TRUE))-SUM(COUNTIF(SCHOOLS[SchoolCode],_xlfn.TEXTSPLIT(FC_import[[#This Row],[SchoolCodes]],",",,TRUE))))} -> 0 | E3: =IF(FC_import[[#This Row],[FinanceCodeTypeCode]]="BUDGET",0,COUNTIF(P:P,P3)-1) -> 0 | F3: =IF(FC_import[[#This Row],[FinanceCodeTypeCode]]="BUDGET",0,COUNTIF(Q:Q,Q3)-1) -> 0 | G3: =COUNTIF(Lookup!$A$2:$A$7,R3)-1 -> 0 | H3: =IF(OR(FC_import[[#This Row],[FinanceCodeEnabled]]=TRUE,FC_import[[#This Row],[FinanceCodeEnabled]]=FALSE),0,1) -> 0 | I3: =IF(LEN(FC_import[[#This Row],[FinanceCode]])<100,0,1) -> 0 | J3: =IF(TRIM(FC_import[[#This Row],[Title]])="",1,0) -> 0 | K3: =IF(TRIM(FC_import[[#This Row],[FinanceCode]])="",1,0) -> 0 | L3: =IF(LEN(FC_import[[#This Row],[Title]])<100,0,1) -> 0 | M3: =IF(ISBLANK(FC_import[[#This Row],[BalanceToScenario]]),1,0) -> 0 | N3: =IF(SUBSTITUTE(TEXT(FC_import[[#This Row],[FinanceCode]],10)," ","")=TEXT(FC_import[[#This Row],[FinanceCode]],10),0,1) -> 0 | O3: =SUM(A3:C3,E3:N3) -> 1 | P3: A_FTE_CAT | Q3: Catering Annual FTE | R3: STATISTICS | S3: Z05 | T3: ZZZ | V3: TRUE | X3: TRUE | Y3: FALSE | Z3: =FALSE -> FALSE
A4: =IF(COUNTIF(LEDGER[LedgerCode],FC_import[[#This Row],[LedgerCode]])>0,0,1) -> 1 | B4: =IF(COUNTIF(Table_System_Grouping_Codes[groupingCodeCode],FC_import[[#This Row],[GroupingCode]])>0,0,1) -> 0 | C4: =IF(COUNTIF(CUSTGROUP[CustomGroupingCode],FC_import[[#This Row],[CustomGrouping]])>0,0,1) -> 0 | D4: {=IF(FC_import[[#This Row],[AvailableToAllSchools]]=TRUE,0,COUNTA(_xlfn.TEXTSPLIT(FC_import[[#This Row],[SchoolCodes]],",",,TRUE))-SUM(COUNTIF(SCHOOLS[SchoolCode],_xlfn.TEXTSPLIT(FC_import[[#This Row],[SchoolCodes]],",",,TRUE))))} -> 0 | E4: =IF(FC_import[[#This Row],[FinanceCodeTypeCode]]="BUDGET",0,COUNTIF(P:P,P4)-1) -> 0 | F4: =IF(FC_import[[#This Row],[FinanceCodeTypeCode]]="BUDGET",0,COUNTIF(Q:Q,Q4)-1) -> 0 | G4: =COUNTIF(Lookup!$A$2:$A$7,R4)-1 -> 0 | H4: =IF(OR(FC_import[[#This Row],[FinanceCodeEnabled]]=TRUE,FC_import[[#This Row],[FinanceCodeEnabled]]=FALSE),0,1) -> 0 | I4: =IF(LEN(FC_import[[#This Row],[FinanceCode]])<100,0,1) -> 0 | J4: =IF(TRIM(FC_import[[#This Row],[Title]])="",1,0) -> 0 | K4: =IF(TRIM(FC_import[[#This Row],[FinanceCode]])="",1,0) -> 0 | L4: =IF(LEN(FC_import[[#This Row],[Title]])<100,0,1) -> 0 | M4: =IF(ISBLANK(FC_import[[#This Row],[BalanceToScenario]]),1,0) -> 0 | N4: =IF(SUBSTITUTE(TEXT(FC_import[[#This Row],[FinanceCode]],10)," ","")=TEXT(FC_import[[#This Row],[FinanceCode]],10),0,1) -> 0 | O4: =SUM(A4:C4,E4:N4) -> 1 | P4: A_FTE_CLE | Q4: Cleaning Annual FTE | R4: STATISTICS | S4: Z05 | T4: ZZZ | V4: TRUE | X4: TRUE | Y4: FALSE | Z4: =FALSE -> FALSE
A5: =IF(COUNTIF(LEDGER[LedgerCode],FC_import[[#This Row],[LedgerCode]])>0,0,1) -> 1 | B5: =IF(COUNTIF(Table_System_Grouping_Codes[groupingCodeCode],FC_import[[#This Row],[GroupingCode]])>0,0,1) -> 0 | C5: =IF(COUNTIF(CUSTGROUP[CustomGroupingCode],FC_import[[#This Row],[CustomGrouping]])>0,0,1) -> 0 | D5: {=IF(FC_import[[#This Row],[AvailableToAllSchools]]=TRUE,0,COUNTA(_xlfn.TEXTSPLIT(FC_import[[#This Row],[SchoolCodes]],",",,TRUE))-SUM(COUNTIF(SCHOOLS[SchoolCode],_xlfn.TEXTSPLIT(FC_import[[#This Row],[SchoolCodes]],",",,TRUE))))} -> 0 | E5: =IF(FC_import[[#This Row],[FinanceCodeTypeCode]]="BUDGET",0,COUNTIF(P:P,P5)-1) -> 0 | F5: =IF(FC_import[[#This Row],[FinanceCodeTypeCode]]="BUDGET",0,COUNTIF(Q:Q,Q5)-1) -> 0 | G5: =COUNTIF(Lookup!$A$2:$A$7,R5)-1 -> 0 | H5: =IF(OR(FC_import[[#This Row],[FinanceCodeEnabled]]=TRUE,FC_import[[#This Row],[FinanceCodeEnabled]]=FALSE),0,1) -> 0 | I5: =IF(LEN(FC_import[[#This Row],[FinanceCode]])<100,0,1) -> 0 | J5: =IF(TRIM(FC_import[[#This Row],[Title]])="",1,0) -> 0 | K5: =IF(TRIM(FC_import[[#This Row],[FinanceCode]])="",1,0) -> 0 | L5: =IF(LEN(FC_import[[#This Row],[Title]])<100,0,1) -> 0 | M5: =IF(ISBLANK(FC_import[[#This Row],[BalanceToScenario]]),1,0) -> 0 | N5: =IF(SUBSTITUTE(TEXT(FC_import[[#This Row],[FinanceCode]],10)," ","")=TEXT(FC_import[[#This Row],[FinanceCode]],10),0,1) -> 0 | O5: =SUM(A5:C5,E5:N5) -> 1 | P5: A_FTE_COM | Q5: Community Facilities Annual FTE | R5: STATISTICS | S5: Z05 | T5: ZZZ | V5: TRUE | X5: TRUE | Y5: FALSE | Z5: =FALSE -> FALSE
A6: =IF(COUNTIF(LEDGER[LedgerCode],FC_import[[#This Row],[LedgerCode]])>0,0,1) -> 1 | B6: =IF(COUNTIF(Table_System_Grouping_Codes[groupingCodeCode],FC_import[[#This Row],[GroupingCode]])>0,0,1) -> 0 | C6: =IF(COUNTIF(CUSTGROUP[CustomGroupingCode],FC_import[[#This Row],[CustomGrouping]])>0,0,1) -> 0 | D6: {=IF(FC_import[[#This Row],[AvailableToAllSchools]]=TRUE,0,COUNTA(_xlfn.TEXTSPLIT(FC_import[[#This Row],[SchoolCodes]],",",,TRUE))-SUM(COUNTIF(SCHOOLS[SchoolCode],_xlfn.TEXTSPLIT(FC_import[[#This Row],[SchoolCodes]],",",,TRUE))))} -> 0 | E6: =IF(FC_import[[#This Row],[FinanceCodeTypeCode]]="BUDGET",0,COUNTIF(P:P,P6)-1) -> 0 | F6: =IF(FC_import[[#This Row],[FinanceCodeTypeCode]]="BUDGET",0,COUNTIF(Q:Q,Q6)-1) -> 0 | G6: =COUNTIF(Lookup!$A$2:$A$7,R6)-1 -> 0 | H6: =IF(OR(FC_import[[#This Row],[FinanceCodeEnabled]]=TRUE,FC_import[[#This Row],[FinanceCodeEnabled]]=FALSE),0,1) -> 0 | I6: =IF(LEN(FC_import[[#This Row],[FinanceCode]])<100,0,1) -> 0 | J6: =IF(TRIM(FC_import[[#This Row],[Title]])="",1,0) -> 0 | K6: =IF(TRIM(FC_import[[#This Row],[FinanceCode]])="",1,0) -> 0 | L6: =IF(LEN(FC_import[[#This Row],[Title]])<100,0,1) -> 0 | M6: =IF(ISBLANK(FC_import[[#This Row],[BalanceToScenario]]),1,0) -> 0 | N6: =IF(SUBSTITUTE(TEXT(FC_import[[#This Row],[FinanceCode]],10)," ","")=TEXT(FC_import[[#This Row],[FinanceCode]],10),0,1) -> 0 | O6: =SUM(A6:C6,E6:N6) -> 1 | P6: A_FTE_COV | Q6: Cover Annual FTE | R6: STATISTICS | S6: Z05 | T6: ZZZ | V6: TRUE | X6: TRUE | Y6: FALSE | Z6: =FALSE -> FALSE
A7: =IF(COUNTIF(LEDGER[LedgerCode],FC_import[[#This Row],[LedgerCode]])>0,0,1) -> 1 | B7: =IF(COUNTIF(Table_System_Grouping_Codes[groupingCodeCode],FC_import[[#This Row],[GroupingCode]])>0,0,1) -> 0 | C7: =IF(COUNTIF(CUSTGROUP[CustomGroupingCode],FC_import[[#This Row],[CustomGrouping]])>0,0,1) -> 0 | D7: {=IF(FC_import[[#This Row],[AvailableToAllSchools]]=TRUE,0,COUNTA(_xlfn.TEXTSPLIT(FC_import[[#This Row],[SchoolCodes]],",",,TRUE))-SUM(COUNTIF(SCHOOLS[SchoolCode],_xlfn.TEXTSPLIT(FC_import[[#This Row],[SchoolCodes]],",",,TRUE))))} -> 0 | E7: =IF(FC_import[[#This Row],[FinanceCodeTypeCode]]="BUDGET",0,COUNTIF(P:P,P7)-1) -> 0 | F7: =IF(FC_import[[#This Row],[FinanceCodeTypeCode]]="BUDGET",0,COUNTIF(Q:Q,Q7)-1) -> 0 | G7: =COUNTIF(Lookup!$A$2:$A$7,R7)-1 -> 0 | H7: =IF(OR(FC_import[[#This Row],[FinanceCodeEnabled]]=TRUE,FC_import[[#This Row],[FinanceCodeEnabled]]=FALSE),0,1) -> 0 | I7: =IF(LEN(FC_import[[#This Row],[FinanceCode]])<100,0,1) -> 0 | J7: =IF(TRIM(FC_import[[#This Row],[Title]])="",1,0) -> 0 | K7: =IF(TRIM(FC_import[[#This Row],[FinanceCode]])="",1,0) -> 0 | L7: =IF(LEN(FC_import[[#This Row],[Title]])<100,0,1) -> 0 | M7: =IF(ISBLANK(FC_import[[#This Row],[BalanceToScenario]]),1,0) -> 0 | N7: =IF(SUBSTITUTE(TEXT(FC_import[[#This Row],[FinanceCode]],10)," ","")=TEXT(FC_import[[#This Row],[FinanceCode]],10),0,1) -> 0 | O7: =SUM(A7:C7,E7:N7) -> 1 | P7: A_FTE_EDS | Q7: Education Support Annual FTE | R7: STATISTICS | S7: Z05 | T7: ZZZ | V7: TRUE | X7: TRUE | Y7: FALSE | Z7: =FALSE -> FALSE
A8: =IF(COUNTIF(LEDGER[LedgerCode],FC_import[[#This Row],[LedgerCode]])>0,0,1) -> 1 | B8: =IF(COUNTIF(Table_System_Grouping_Codes[groupingCodeCode],FC_import[[#This Row],[GroupingCode]])>0,0,1) -> 0 | C8: =IF(COUNTIF(CUSTGROUP[CustomGroupingCode],FC_import[[#This Row],[CustomGrouping]])>0,0,1) -> 0 | D8: {=IF(FC_import[[#This Row],[AvailableToAllSchools]]=TRUE,0,COUNTA(_xlfn.TEXTSPLIT(FC_import[[#This Row],[SchoolCodes]],",",,TRUE))-SUM(COUNTIF(SCHOOLS[SchoolCode],_xlfn.TEXTSPLIT(FC_import[[#This Row],[SchoolCodes]],",",,TRUE))))} -> 0 | E8: =IF(FC_import[[#This Row],[FinanceCodeTypeCode]]="BUDGET",0,COUNTIF(P:P,P8)-1) -> 0 | F8: =IF(FC_import[[#This Row],[FinanceCodeTypeCode]]="BUDGET",0,COUNTIF(Q:Q,Q8)-1) -> 0 | G8: =COUNTIF(Lookup!$A$2:$A$7,R8)-1 -> 0 | H8: =IF(OR(FC_import[[#This Row],[FinanceCodeEnabled]]=TRUE,FC_import[[#This Row],[FinanceCodeEnabled]]=FALSE),0,1) -> 0 | I8: =IF(LEN(FC_import[[#This Row],[FinanceCode]])<100,0,1) -> 0 | J8: =IF(TRIM(FC_import[[#This Row],[Title]])="",1,0) -> 0 | K8: =IF(TRIM(FC_import[[#This Row],[FinanceCode]])="",1,0) -> 0 | L8: =IF(LEN(FC_import[[#This Row],[Title]])<100,0,1) -> 0 | M8: =IF(ISBLANK(FC_import[[#This Row],[BalanceToScenario]]),1,0) -> 0 | N8: =IF(SUBSTITUTE(TEXT(FC_import[[#This Row],[FinanceCode]],10)," ","")=TEXT(FC_import[[#This Row],[FinanceCode]],10),0,1) -> 0 | O8: =SUM(A8:C8,E8:N8) -> 1 | P8: A_FTE_ESTF | Q8: External Staff Annual FTE | R8: STATISTICS | S8: ZZZ | T8: ZZZ | V8: TRUE | X8: TRUE | Y8: FALSE | Z8: =FALSE -> FALSE
A9: =IF(COUNTIF(LEDGER[LedgerCode],FC_import[[#This Row],[LedgerCode]])>0,0,1) -> 1 | B9: =IF(COUNTIF(Table_System_Grouping_Codes[groupingCodeCode],FC_import[[#This Row],[GroupingCode]])>0,0,1) -> 0 | C9: =IF(COUNTIF(CUSTGROUP[CustomGroupingCode],FC_import[[#This Row],[CustomGrouping]])>0,0,1) -> 0 | D9: {=IF(FC_import[[#This Row],[AvailableToAllSchools]]=TRUE,0,COUNTA(_xlfn.TEXTSPLIT(FC_import[[#This Row],[SchoolCodes]],",",,TRUE))-SUM(COUNTIF(SCHOOLS[SchoolCode],_xlfn.TEXTSPLIT(FC_import[[#This Row],[SchoolCodes]],",",,TRUE))))} -> 0 | E9: =IF(FC_import[[#This Row],[FinanceCodeTypeCode]]="BUDGET",0,COUNTIF(P:P,P9)-1) -> 0 | F9: =IF(FC_import[[#This Row],[FinanceCodeTypeCode]]="BUDGET",0,COUNTIF(Q:Q,Q9)-1) -> 0 | G9: =COUNTIF(Lookup!$A$2:$A$7,R9)-1 -> 0 | H9: =IF(OR(FC_import[[#This Row],[FinanceCodeEnabled]]=TRUE,FC_import[[#This Row],[FinanceCodeEnabled]]=FALSE),0,1) -> 0 | I9: =IF(LEN(FC_import[[#This Row],[FinanceCode]])<100,0,1) -> 0 | J9: =IF(TRIM(FC_import[[#This Row],[Title]])="",1,0) -> 0 | K9: =IF(TRIM(FC_import[[#This Row],[FinanceCode]])="",1,0) -> 0 | L9: =IF(LEN(FC_import[[#This Row],[Title]])<100,0,1) -> 0 | M9: =IF(ISBLANK(FC_import[[#This Row],[BalanceToScenario]]),1,0) -> 0 | N9: =IF(SUBSTITUTE(TEXT(FC_import[[#This Row],[FinanceCode]],10)," ","")=TEXT(FC_import[[#This Row],[FinanceCode]],10),0,1) -> 0 | O9: =SUM(A9:C9,E9:N9) -> 1 | P9: A_FTE_EXT | Q9: Extended Schools Annual FTE | R9: STATISTICS | S9: Z05 | T9: ZZZ | V9: TRUE | X9: TRUE | Y9: FALSE | Z9: =FALSE -> FALSE
A10: =IF(COUNTIF(LEDGER[LedgerCode],FC_import[[#This Row],[LedgerCode]])>0,0,1) -> 1 | B10: =IF(COUNTIF(Table_System_Grouping_Codes[groupingCodeCode],FC_import[[#This Row],[GroupingCode]])>0,0,1) -> 0 | C10: =IF(COUNTIF(CUSTGROUP[CustomGroupingCode],FC_import[[#This Row],[CustomGrouping]])>0,0,1) -> 0 | D10: {=IF(FC_import[[#This Row],[AvailableToAllSchools]]=TRUE,0,COUNTA(_xlfn.TEXTSPLIT(FC_import[[#This Row],[SchoolCodes]],",",,TRUE))-SUM(COUNTIF(SCHOOLS[SchoolCode],_xlfn.TEXTSPLIT(FC_import[[#This Row],[SchoolCodes]],",",,TRUE))))} -> 0 | E10: =IF(FC_import[[#This Row],[FinanceCodeTypeCode]]="BUDGET",0,COUNTIF(P:P,P10)-1) -> 0 | F10: =IF(FC_import[[#This Row],[FinanceCodeTypeCode]]="BUDGET",0,COUNTIF(Q:Q,Q10)-1) -> 0 | G10: =COUNTIF(Lookup!$A$2:$A$7,R10)-1 -> 0 | H10: =IF(OR(FC_import[[#This Row],[FinanceCodeEnabled]]=TRUE,FC_import[[#This Row],[FinanceCodeEnabled]]=FALSE),0,1) -> 0 | I10: =IF(LEN(FC_import[[#This Row],[FinanceCode]])<100,0,1) -> 0 | J10: =IF(TRIM(FC_import[[#This Row],[Title]])="",1,0) -> 0 | K10: =IF(TRIM(FC_import[[#This Row],[FinanceCode]])="",1,0) -> 0 | L10: =IF(LEN(FC_import[[#This Row],[Title]])<100,0,1) -> 0 | M10: =IF(ISBLANK(FC_import[[#This Row],[BalanceToScenario]]),1,0) -> 0 | N10: =IF(SUBSTITUTE(TEXT(FC_import[[#This Row],[FinanceCode]],10)," ","")=TEXT(FC_import[[#This Row],[FinanceCode]],10),0,1) -> 0 | O10: =SUM(A10:C10,E10:N10) -> 1 | P10: A_FTE_FLA | Q10: FLA Annual FTE | R10: STATISTICS | S10: Z05 | T10: ZZZ | V10: TRUE | X10: TRUE | Y10: FALSE | Z10: =FALSE -> FALSE
A11: =IF(COUNTIF(LEDGER[LedgerCode],FC_import[[#This Row],[LedgerCode]])>0,0,1) -> 1 | B11: =IF(COUNTIF(Table_System_Grouping_Codes[groupingCodeCode],FC_import[[#This Row],[GroupingCode]])>0,0,1) -> 0 | C11: =IF(COUNTIF(CUSTGROUP[CustomGroupingCode],FC_import[[#This Row],[CustomGrouping]])>0,0,1) -> 0 | D11: {=IF(FC_import[[#This Row],[AvailableToAllSchools]]=TRUE,0,COUNTA(_xlfn.TEXTSPLIT(FC_import[[#This Row],[SchoolCodes]],",",,TRUE))-SUM(COUNTIF(SCHOOLS[SchoolCode],_xlfn.TEXTSPLIT(FC_import[[#This Row],[SchoolCodes]],",",,TRUE))))} -> 0 | E11: =IF(FC_import[[#This Row],[FinanceCodeTypeCode]]="BUDGET",0,COUNTIF(P:P,P11)-1) -> 0 | F11: =IF(FC_import[[#This Row],[FinanceCodeTypeCode]]="BUDGET",0,COUNTIF(Q:Q,Q11)-1) -> 0 | G11: =COUNTIF(Lookup!$A$2:$A$7,R11)-1 -> 0 | H11: =IF(OR(FC_import[[#This Row],[FinanceCodeEnabled]]=TRUE,FC_import[[#This Row],[FinanceCodeEnabled]]=FALSE),0,1) -> 0 | I11: =IF(LEN(FC_import[[#This Row],[FinanceCode]])<100,0,1) -> 0 | J11: =IF(TRIM(FC_import[[#This Row],[Title]])="",1,0) -> 0 | K11: =IF(TRIM(FC_import[[#This Row],[FinanceCode]])="",1,0) -> 0 | L11: =IF(LEN(FC_import[[#This Row],[Title]])<100,0,1) -> 0 | M11: =IF(ISBLANK(FC_import[[#This Row],[BalanceToScenario]]),1,0) -> 0 | N11: =IF(SUBSTITUTE(TEXT(FC_import[[#This Row],[FinanceCode]],10)," ","")=TEXT(FC_import[[#This Row],[FinanceCode]],10),0,1) -> 0 | O11: =SUM(A11:C11,E11:N11) -> 1 | P11: A_FTE_FSW | Q11: Family Support Annual FTE | R11: STATISTICS | S11: Z05 | T11: ZZZ | V11: TRUE | X11: TRUE | Y11: FALSE | Z11: =FALSE -> FALSE
A12: =IF(COUNTIF(LEDGER[LedgerCode],FC_import[[#This Row],[LedgerCode]])>0,0,1) -> 1 | B12: =IF(COUNTIF(Table_System_Grouping_Codes[groupingCodeCode],FC_import[[#This Row],[GroupingCode]])>0,0,1) -> 0 | C12: =IF(COUNTIF(CUSTGROUP[CustomGroupingCode],FC_import[[#This Row],[CustomGrouping]])>0,0,1) -> 0 | D12: {=IF(FC_import[[#This Row],[AvailableToAllSchools]]=TRUE,0,COUNTA(_xlfn.TEXTSPLIT(FC_import[[#This Row],[SchoolCodes]],",",,TRUE))-SUM(COUNTIF(SCHOOLS[SchoolCode],_xlfn.TEXTSPLIT(FC_import[[#This Row],[SchoolCodes]],",",,TRUE))))} -> 0 | E12: =IF(FC_import[[#This Row],[FinanceCodeTypeCode]]="BUDGET",0,COUNTIF(P:P,P12)-1) -> 0 | F12: =IF(FC_import[[#This Row],[FinanceCodeTypeCode]]="BUDGET",0,COUNTIF(Q:Q,Q12)-1) -> 0 | G12: =COUNTIF(Lookup!$A$2:$A$7,R12)-1 -> 0 | H12: =IF(OR(FC_import[[#This Row],[FinanceCodeEnabled]]=TRUE,FC_import[[#This Row],[FinanceCodeEnabled]]=FALSE),0,1) -> 0 | I12: =IF(LEN(FC_import[[#This Row],[FinanceCode]])<100,0,1) -> 0 | J12: =IF(TRIM(FC_import[[#This Row],[Title]])="",1,0) -> 0 | K12: =IF(TRIM(FC_import[[#This Row],[FinanceCode]])="",1,0) -> 0 | L12: =IF(LEN(FC_import[[#This Row],[Title]])<100,0,1) -> 0 | M12: =IF(ISBLANK(FC_import[[#This Row],[BalanceToScenario]]),1,0) -> 0 | N12: =IF(SUBSTITUTE(TEXT(FC_import[[#This Row],[FinanceCode]],10)," ","")=TEXT(FC_import[[#This Row],[FinanceCode]],10),0,1) -> 0 | O12: =SUM(A12:C12,E12:N12) -> 1 | P12: A_FTE_INV | Q12: Invigilator Annual FTE | R12: STATISTICS | S12: Z05 | T12: ZZZ | V12: TRUE | X12: TRUE | Y12: FALSE | Z12: =FALSE -> FALSE
A13: =IF(COUNTIF(LEDGER[LedgerCode],FC_import[[#This Row],[LedgerCode]])>0,0,1) -> 1 | B13: =IF(COUNTIF(Table_System_Grouping_Codes[groupingCodeCode],FC_import[[#This Row],[GroupingCode]])>0,0,1) -> 0 | C13: =IF(COUNTIF(CUSTGROUP[CustomGroupingCode],FC_import[[#This Row],[CustomGrouping]])>0,0,1) -> 0 | D13: {=IF(FC_import[[#This Row],[AvailableToAllSchools]]=TRUE,0,COUNTA(_xlfn.TEXTSPLIT(FC_import[[#This Row],[SchoolCodes]],",",,TRUE))-SUM(COUNTIF(SCHOOLS[SchoolCode],_xlfn.TEXTSPLIT(FC_import[[#This Row],[SchoolCodes]],",",,TRUE))))} -> 0 | E13: =IF(FC_import[[#This Row],[FinanceCodeTypeCode]]="BUDGET",0,COUNTIF(P:P,P13)-1) -> 0 | F13: =IF(FC_import[[#This Row],[FinanceCodeTypeCode]]="BUDGET",0,COUNTIF(Q:Q,Q13)-1) -> 0 | G13: =COUNTIF(Lookup!$A$2:$A$7,R13)-1 -> 0 | H13: =IF(OR(FC_import[[#This Row],[FinanceCodeEnabled]]=TRUE,FC_import[[#This Row],[FinanceCodeEnabled]]=FALSE),0,1) -> 0 | I13: =IF(LEN(FC_import[[#This Row],[FinanceCode]])<100,0,1) -> 0 | J13: =IF(TRIM(FC_import[[#This Row],[Title]])="",1,0) -> 0 | K13: =IF(TRIM(FC_import[[#This Row],[FinanceCode]])="",1,0) -> 0 | L13: =IF(LEN(FC_import[[#This Row],[Title]])<100,0,1) -> 0 | M13: =IF(ISBLANK(FC_import[[#This Row],[BalanceToScenario]]),1,0) -> 0 | N13: =IF(SUBSTITUTE(TEXT(FC_import[[#This Row],[FinanceCode]],10)," ","")=TEXT(FC_import[[#This Row],[FinanceCode]],10),0,1) -> 0 | O13: =SUM(A13:C13,E13:N13) -> 1 | P13: A_FTE_LEAVE_ADJ_ADM | Q13: Finance Admin Annual FTE Leave Adjustment | R13: STATISTICS | S13: Z17 | T13: ZZZ | V13: TRUE | X13: TRUE | Y13: FALSE | Z13: =FALSE -> FALSE
... A92: =IF(COUNTIF(LEDGER[LedgerCode],FC_import[[#This Row],[LedgerCode]])>0,0,1) -> 1 | B92: =IF(COUNTIF(Table_System_Grouping_Codes[groupingCodeCode],FC_import[[#This Row],[GroupingCode]])>0,0,1) -> 0 | C92: =IF(COUNTIF(CUSTGROUP[CustomGroupingCode],FC_import[[#This Row],[CustomGrouping]])>0,0,1) -> 0 | D92: {=IF(FC_import[[#This Row],[AvailableToAllSchools]]=TRUE,0,COUNTA(_xlfn.TEXTSPLIT(FC_import[[#This Row],[SchoolCodes]],",",,TRUE))-SUM(COUNTIF(SCHOOLS[SchoolCode],_xlfn.TEXTSPLIT(FC_import[[#This Row],[SchoolCodes]],",",,TRUE))))} -> 0 | E92: =IF(FC_import[[#This Row],[FinanceCodeTypeCode]]="BUDGET",0,COUNTIF(P:P,P92)-1) -> 0 | F92: =IF(FC_import[[#This Row],[FinanceCodeTypeCode]]="BUDGET",0,COUNTIF(Q:Q,Q92)-1) -> 0 | G92: =COUNTIF(Lookup!$A$2:$A$7,R92)-1 -> 0 | H92: =IF(OR(FC_import[[#This Row],[FinanceCodeEnabled]]=TRUE,FC_import[[#This Row],[FinanceCodeEnabled]]=FALSE),0,1) -> 0 | I92: =IF(LEN(FC_import[[#This Row],[FinanceCode]])<100,0,1) -> 0 | J92: =IF(TRIM(FC_import[[#This Row],[Title]])="",1,0) -> 0 | K92: =IF(TRIM(FC_import[[#This Row],[FinanceCode]])="",1,0) -> 0 | L92: =IF(LEN(FC_import[[#This Row],[Title]])<100,0,1) -> 0 | M92: =IF(ISBLANK(FC_import[[#This Row],[BalanceToScenario]]),1,0) -> 0 | N92: =IF(SUBSTITUTE(TEXT(FC_import[[#This Row],[FinanceCode]],10)," ","")=TEXT(FC_import[[#This Row],[FinanceCode]],10),0,1) -> 0 | O92: =SUM(A92:C92,E92:N92) -> 1 | P92: WK_FTE_TEC | Q92: Technicians Weekly FTE | R92: STATISTICS | S92: Z03 | T92: ZZZ | V92: TRUE | X92: TRUE | Y92: FALSE | Z92: =FALSE -> FALSE

Sheet FinanceCodes Budget
N1: API - Do not edit
A2: LedgerIssue | B2: GroupingCodeIssue | C2: CustGrIssue | D2: SchCodeIssue | E2: DupCode | F2: DupDesc | G2: FCTypeIss | H2: Blank Title Check | I2: Blank Code Check | J2: Code length Check | K2: Title length check | L2: Balance to Scenario Blank | M2: Will Import if 0 | N2: FinanceCode | O2: Title | P2: GroupingCode | Q2: CustomGrouping | R2: AvailableToAllSchools | S2: SchoolCodes | T2: FinanceCodeTypeCode | U2: LedgerCode | V2: FinanceCodeEnabled | W2: BalanceToScenario
A3: =IF(COUNTIF(LEDGER[LedgerCode],FinanceCodesBudget[[#This Row],[LedgerCode]])>0,0,1) -> 1 | B3: =IF(COUNTIF(Table_System_Grouping_Codes[groupingCodeCode],FinanceCodesBudget[[#This Row],[GroupingCode]])>0,0,1) -> 0 | C3: =IF(COUNTIF(CUSTGROUP[CustomGroupingCode],FinanceCodesBudget[[#This Row],[CustomGrouping]])>0,0,1) -> 1 | D3: {=IF(FinanceCodesBudget[[#This Row],[AvailableToAllSchools]]=TRUE,0,COUNTA(_xlfn.TEXTSPLIT(FinanceCodesBudget[[#This Row],[SchoolCodes]],",",,TRUE))-SUM(COUNTIF(SCHOOLS[SchoolCode],_xlfn.TEXTSPLIT(FinanceCodesBudget[[#This Row],[SchoolCodes]],",",,TRUE))))} -> 0 | E3: =IF(FinanceCodesBudget[[#This Row],[FinanceCodeTypeCode]]="BUDGET",0,COUNTIF(FinanceCodesBudget[FinanceCode],FinanceCodesBudget[[#This Row],[FinanceCode]])-1) -> 0 | F3: =IF(FinanceCodesBudget[[#This Row],[FinanceCodeTypeCode]]="BUDGET",0,COUNTIF(FinanceCodesBudget[Title],FinanceCodesBudget[[#This Row],[Title]])-1) -> 0 | G3: =COUNTIF(Lookup!$A$2:$A$7,FinanceCodesBudget[[#This Row],[FinanceCodeTypeCode]])-1 -> 0 | H3: =IF(TRIM(FinanceCodesBudget[[#This Row],[Title]])="",1,0) -> 0 | I3: =IF(TRIM(FinanceCodesBudget[[#This Row],[FinanceCode]])="",1,0) -> 0 | J3: =IF(LEN(FinanceCodesBudget[[#This Row],[FinanceCode]])<100,0,1) -> 0 | K3: =IF(LEN(FinanceCodesBudget[[#This Row],[Title]])<100,0,1) -> 0 | L3: =IF(ISBLANK(FinanceCodesBudget[[#This Row],[BalanceToScenario]]),1,0) -> 0 | M3: =SUM(FinanceCodesBudget[[#This Row],[LedgerIssue]:[CustGrIssue]],FinanceCodesBudget[[#This Row],[DupCode]:[Balance to Scenario Blank]]) -> 2 | N3: 510100 | O3: IN: DfE Revenue Grants: GAG (not stud supp and trust grants) | P3: 510100 | Q3: A0 | R3: TRUE | T3: BUDGET | U3: COSTCTR | V3: TRUE | W3: FALSE

Sheet 19_PayScales
A1: Duplicate Scale Code | B1: Schools Check | C1: School Code Exists | D1: TRUE /FALSE Typo | E1: Code Length | F1: Title Length | G1: Blank in column | H1: Space in Code | I1: Will Import if 0 | J1: London Weighting | K1: Increment Date | L1: Increase Date | M1: ScenarioCode | N1: PayScaleCode | O1: PayScaleTitle | P1: ServiceIncrementDateEnabled | Q1: IncrementDate | R1: IncreaseDate | S1: IncreasePercentage | T1: AvailableToAllSchools | U1: SchoolCodes | V1: PayScaleEnabled | W1: ExcludeNationalInsurance | X1: ExcludePension
A2: =COUNTIF(PAYSCALES[PayScaleCode],PAYSCALES[[#This Row],[PayScaleCode]])-1 -> 0 | B2: =IF(PAYSCALES[[#This Row],[AvailableToAllSchools]]=FALSE,IF(ISBLANK(PAYSCALES[[#This Row],[SchoolCodes]]),1,0),IF(PAYSCALES[[#This Row],[AvailableToAllSchools]]=TRUE,IF(ISBLANK(PAYSCALES[[#This Row],[SchoolCodes]]),0,1))) -> 0 | C2: {=IF(PAYSCALES[[#This Row],[AvailableToAllSchools]]=TRUE,0,COUNTA(_xlfn.TEXTSPLIT(PAYSCALES[[#This Row],[SchoolCodes]],",",,TRUE))-SUM(COUNTIF(SCHOOLS[SchoolCode],_xlfn.TEXTSPLIT(PAYSCALES[[#This Row],[SchoolCodes]],",",,TRUE))))} -> 0 | D2: =IF(OR(PAYSCALES[[#This Row],[PayScaleEnabled]]=TRUE,PAYSCALES[[#This Row],[PayScaleEnabled]]=FALSE),IF(OR(PAYSCALES[[#This Row],[ServiceIncrementDateEnabled]]=TRUE,PAYSCALES[[#This Row],[ServiceIncrementDateEnabled]]=FALSE),IF(OR(PAYSCALES[[#This Row],[AvailableToAllSchools]]=TRUE,PAYSCALES[[#This Row],[AvailableToAllSchools]]=FALSE),IF(OR(PAYSCALES[[#This Row],[ExcludeNationalInsurance]]=TRUE,PAYSCALES[[#This Row],[ExcludeNationalInsurance]]=FALSE),IF(OR(PAYSCALES[[#This Row],[ExcludePension]]=TRUE,PAYSCALES[[#This Row],[ExcludePension]]=FALSE),0,1),1),1),1),1) -> 0 | E2: =IF(LEN(PAYSCALES[[#This Row],[PayScaleCode]])<100,0,1) -> 0 | F2: =IF(LEN(PAYSCALES[[#This Row],[PayScaleTitle]])<100,0,1) -> 0 | G2: =COUNTBLANK(PAYSCALES[[#This Row],[PayScaleCode]:[AvailableToAllSchools]])+COUNTBLANK(PAYSCALES[[#This Row],[PayScaleEnabled]:[ExcludePension]]) -> 0 | H2: =IF(SUBSTITUTE(TEXT(PAYSCALES[[#This Row],[PayScaleCode]],10)," ","")=TEXT(PAYSCALES[[#This Row],[PayScaleCode]],10),0,1) -> 0 | I2: =SUM(PAYSCALES[[#This Row],[Duplicate Scale Code]:[Space in Code]]) -> 0 | J2: England & Wales | K2: =PAYSCALES[[#This Row],[IncrementDate]] -> 44440 | L2: =PAYSCALES[[#This Row],[IncreaseDate]] -> 44440 | N2: MAIN_EW | O2: Teachers Main EW | P2: FALSE | Q2: 44440 | R2: 44440 | S2: 2.75 | T2: TRUE | V2: TRUE | W2: FALSE | X2: FALSE | Z2: Note: This tab is for pay scale default % uplift (per scope)
A3: =COUNTIF(PAYSCALES[PayScaleCode],PAYSCALES[[#This Row],[PayScaleCode]])-1 -> 0 | B3: =IF(PAYSCALES[[#This Row],[AvailableToAllSchools]]=FALSE,IF(ISBLANK(PAYSCALES[[#This Row],[SchoolCodes]]),1,0),IF(PAYSCALES[[#This Row],[AvailableToAllSchools]]=TRUE,IF(ISBLANK(PAYSCALES[[#This Row],[SchoolCodes]]),0,1))) -> 0 | C3: {=IF(PAYSCALES[[#This Row],[AvailableToAllSchools]]=TRUE,0,COUNTA(_xlfn.TEXTSPLIT(PAYSCALES[[#This Row],[SchoolCodes]],",",,TRUE))-SUM(COUNTIF(SCHOOLS[SchoolCode],_xlfn.TEXTSPLIT(PAYSCALES[[#This Row],[SchoolCodes]],",",,TRUE))))} -> 0 | D3: =IF(OR(PAYSCALES[[#This Row],[PayScaleEnabled]]=TRUE,PAYSCALES[[#This Row],[PayScaleEnabled]]=FALSE),IF(OR(PAYSCALES[[#This Row],[ServiceIncrementDateEnabled]]=TRUE,PAYSCALES[[#This Row],[ServiceIncrementDateEnabled]]=FALSE),IF(OR(PAYSCALES[[#This Row],[AvailableToAllSchools]]=TRUE,PAYSCALES[[#This Row],[AvailableToAllSchools]]=FALSE),IF(OR(PAYSCALES[[#This Row],[ExcludeNationalInsurance]]=TRUE,PAYSCALES[[#This Row],[ExcludeNationalInsurance]]=FALSE),IF(OR(PAYSCALES[[#This Row],[ExcludePension]]=TRUE,PAYSCALES[[#This Row],[ExcludePension]]=FALSE),0,1),1),1),1),1) -> 0 | E3: =IF(LEN(PAYSCALES[[#This Row],[PayScaleCode]])<100,0,1) -> 0 | F3: =IF(LEN(PAYSCALES[[#This Row],[PayScaleTitle]])<100,0,1) -> 0 | G3: =COUNTBLANK(PAYSCALES[[#This Row],[PayScaleCode]:[AvailableToAllSchools]])+COUNTBLANK(PAYSCALES[[#This Row],[PayScaleEnabled]:[ExcludePension]]) -> 0 | H3: =IF(SUBSTITUTE(TEXT(PAYSCALES[[#This Row],[PayScaleCode]],10)," ","")=TEXT(PAYSCALES[[#This Row],[PayScaleCode]],10),0,1) -> 0 | I3: =SUM(PAYSCALES[[#This Row],[Duplicate Scale Code]:[Space in Code]]) -> 0 | J3: England & Wales | K3: =PAYSCALES[[#This Row],[IncrementDate]] -> 44440 | L3: =PAYSCALES[[#This Row],[IncreaseDate]] -> 44440 | N3: LP_EW | O3: Lead Practitioner EW | P3: FALSE | Q3: 44440 | R3: 44440 | S3: 2.75 | T3: TRUE | V3: TRUE | W3: FALSE | X3: FALSE
A4: =COUNTIF(PAYSCALES[PayScaleCode],PAYSCALES[[#This Row],[PayScaleCode]])-1 -> 0 | B4: =IF(PAYSCALES[[#This Row],[AvailableToAllSchools]]=FALSE,IF(ISBLANK(PAYSCALES[[#This Row],[SchoolCodes]]),1,0),IF(PAYSCALES[[#This Row],[AvailableToAllSchools]]=TRUE,IF(ISBLANK(PAYSCALES[[#This Row],[SchoolCodes]]),0,1))) -> 0 | C4: {=IF(PAYSCALES[[#This Row],[AvailableToAllSchools]]=TRUE,0,COUNTA(_xlfn.TEXTSPLIT(PAYSCALES[[#This Row],[SchoolCodes]],",",,TRUE))-SUM(COUNTIF(SCHOOLS[SchoolCode],_xlfn.TEXTSPLIT(PAYSCALES[[#This Row],[SchoolCodes]],",",,TRUE))))} -> 0 | D4: =IF(OR(PAYSCALES[[#This Row],[PayScaleEnabled]]=TRUE,PAYSCALES[[#This Row],[PayScaleEnabled]]=FALSE),IF(OR(PAYSCALES[[#This Row],[ServiceIncrementDateEnabled]]=TRUE,PAYSCALES[[#This Row],[ServiceIncrementDateEnabled]]=FALSE),IF(OR(PAYSCALES[[#This Row],[AvailableToAllSchools]]=TRUE,PAYSCALES[[#This Row],[AvailableToAllSchools]]=FALSE),IF(OR(PAYSCALES[[#This Row],[ExcludeNationalInsurance]]=TRUE,PAYSCALES[[#This Row],[ExcludeNationalInsurance]]=FALSE),IF(OR(PAYSCALES[[#This Row],[ExcludePension]]=TRUE,PAYSCALES[[#This Row],[ExcludePension]]=FALSE),0,1),1),1),1),1) -> 0 | E4: =IF(LEN(PAYSCALES[[#This Row],[PayScaleCode]])<100,0,1) -> 0 | F4: =IF(LEN(PAYSCALES[[#This Row],[PayScaleTitle]])<100,0,1) -> 0 | G4: =COUNTBLANK(PAYSCALES[[#This Row],[PayScaleCode]:[AvailableToAllSchools]])+COUNTBLANK(PAYSCALES[[#This Row],[PayScaleEnabled]:[ExcludePension]]) -> 0 | H4: =IF(SUBSTITUTE(TEXT(PAYSCALES[[#This Row],[PayScaleCode]],10)," ","")=TEXT(PAYSCALES[[#This Row],[PayScaleCode]],10),0,1) -> 0 | I4: =SUM(PAYSCALES[[#This Row],[Duplicate Scale Code]:[Space in Code]]) -> 0 | J4: England & Wales | K4: =PAYSCALES[[#This Row],[IncrementDate]] -> 44440 | L4: =PAYSCALES[[#This Row],[IncreaseDate]] -> 44440 | N4: UQ_EW | O4: Teachers Unqualified EW | P4: FALSE | Q4: 44440 | R4: 44440 | S4: 2.75 | T4: TRUE | V4: TRUE | W4: FALSE | X4: FALSE
A5: =COUNTIF(PAYSCALES[PayScaleCode],PAYSCALES[[#This Row],[PayScaleCode]])-1 -> 0 | B5: =IF(PAYSCALES[[#This Row],[AvailableToAllSchools]]=FALSE,IF(ISBLANK(PAYSCALES[[#This Row],[SchoolCodes]]),1,0),IF(PAYSCALES[[#This Row],[AvailableToAllSchools]]=TRUE,IF(ISBLANK(PAYSCALES[[#This Row],[SchoolCodes]]),0,1))) -> 0 | C5: {=IF(PAYSCALES[[#This Row],[AvailableToAllSchools]]=TRUE,0,COUNTA(_xlfn.TEXTSPLIT(PAYSCALES[[#This Row],[SchoolCodes]],",",,TRUE))-SUM(COUNTIF(SCHOOLS[SchoolCode],_xlfn.TEXTSPLIT(PAYSCALES[[#This Row],[SchoolCodes]],",",,TRUE))))} -> 0 | D5: =IF(OR(PAYSCALES[[#This Row],[PayScaleEnabled]]=TRUE,PAYSCALES[[#This Row],[PayScaleEnabled]]=FALSE),IF(OR(PAYSCALES[[#This Row],[ServiceIncrementDateEnabled]]=TRUE,PAYSCALES[[#This Row],[ServiceIncrementDateEnabled]]=FALSE),IF(OR(PAYSCALES[[#This Row],[AvailableToAllSchools]]=TRUE,PAYSCALES[[#This Row],[AvailableToAllSchools]]=FALSE),IF(OR(PAYSCALES[[#This Row],[ExcludeNationalInsurance]]=TRUE,PAYSCALES[[#This Row],[ExcludeNationalInsurance]]=FALSE),IF(OR(PAYSCALES[[#This Row],[ExcludePension]]=TRUE,PAYSCALES[[#This Row],[ExcludePension]]=FALSE),0,1),1),1),1),1) -> 0 | E5: =IF(LEN(PAYSCALES[[#This Row],[PayScaleCode]])<100,0,1) -> 0 | F5: =IF(LEN(PAYSCALES[[#This Row],[PayScaleTitle]])<100,0,1) -> 0 | G5: =COUNTBLANK(PAYSCALES[[#This Row],[PayScaleCode]:[AvailableToAllSchools]])+COUNTBLANK(PAYSCALES[[#This Row],[PayScaleEnabled]:[ExcludePension]]) -> 0 | H5: =IF(SUBSTITUTE(TEXT(PAYSCALES[[#This Row],[PayScaleCode]],10)," ","")=TEXT(PAYSCALES[[#This Row],[PayScaleCode]],10),0,1) -> 0 | I5: =SUM(PAYSCALES[[#This Row],[Duplicate Scale Code]:[Space in Code]]) -> 0 | J5: England & Wales | K5: =PAYSCALES[[#This Row],[IncrementDate]] -> 44440 | L5: =PAYSCALES[[#This Row],[IncreaseDate]] -> 44440 | N5: LS_EW | O5: Leadership Group EW | P5: FALSE | Q5: 44440 | R5: 44440 | S5: 2.75 | T5: TRUE | V5: TRUE | W5: FALSE | X5: FALSE
A6: =COUNTIF(PAYSCALES[PayScaleCode],PAYSCALES[[#This Row],[PayScaleCode]])-1 -> 0 | B6: =IF(PAYSCALES[[#This Row],[AvailableToAllSchools]]=FALSE,IF(ISBLANK(PAYSCALES[[#This Row],[SchoolCodes]]),1,0),IF(PAYSCALES[[#This Row],[AvailableToAllSchools]]=TRUE,IF(ISBLANK(PAYSCALES[[#This Row],[SchoolCodes]]),0,1))) -> 0 | C6: {=IF(PAYSCALES[[#This Row],[AvailableToAllSchools]]=TRUE,0,COUNTA(_xlfn.TEXTSPLIT(PAYSCALES[[#This Row],[SchoolCodes]],",",,TRUE))-SUM(COUNTIF(SCHOOLS[SchoolCode],_xlfn.TEXTSPLIT(PAYSCALES[[#This Row],[SchoolCodes]],",",,TRUE))))} -> 0 | D6: =IF(OR(PAYSCALES[[#This Row],[PayScaleEnabled]]=TRUE,PAYSCALES[[#This Row],[PayScaleEnabled]]=FALSE),IF(OR(PAYSCALES[[#This Row],[ServiceIncrementDateEnabled]]=TRUE,PAYSCALES[[#This Row],[ServiceIncrementDateEnabled]]=FALSE),IF(OR(PAYSCALES[[#This Row],[AvailableToAllSchools]]=TRUE,PAYSCALES[[#This Row],[AvailableToAllSchools]]=FALSE),IF(OR(PAYSCALES[[#This Row],[ExcludeNationalInsurance]]=TRUE,PAYSCALES[[#This Row],[ExcludeNationalInsurance]]=FALSE),IF(OR(PAYSCALES[[#This Row],[ExcludePension]]=TRUE,PAYSCALES[[#This Row],[ExcludePension]]=FALSE),0,1),1),1),1),1) -> 0 | E6: =IF(LEN(PAYSCALES[[#This Row],[PayScaleCode]])<100,0,1) -> 0 | F6: =IF(LEN(PAYSCALES[[#This Row],[PayScaleTitle]])<100,0,1) -> 0 | G6: =COUNTBLANK(PAYSCALES[[#This Row],[PayScaleCode]:[AvailableToAllSchools]])+COUNTBLANK(PAYSCALES[[#This Row],[PayScaleEnabled]:[ExcludePension]]) -> 0 | H6: =IF(SUBSTITUTE(TEXT(PAYSCALES[[#This Row],[PayScaleCode]],10)," ","")=TEXT(PAYSCALES[[#This Row],[PayScaleCode]],10),0,1) -> 0 | I6: =SUM(PAYSCALES[[#This Row],[Duplicate Scale Code]:[Space in Code]]) -> 0 | J6: England & Wales | K6: =PAYSCALES[[#This Row],[IncrementDate]] -> 44287 | L6: =PAYSCALES[[#This Row],[IncreaseDate]] -> 44287 | N6: NJC_EW | O6: NJC EW | P6: FALSE | Q6: 44287 | R6: 44287 | S6: 2 | T6: TRUE | V6: TRUE | W6: FALSE | X6: FALSE
A7: =COUNTIF(PAYSCALES[PayScaleCode],PAYSCALES[[#This Row],[PayScaleCode]])-1 -> 0 | B7: =IF(PAYSCALES[[#This Row],[AvailableToAllSchools]]=FALSE,IF(ISBLANK(PAYSCALES[[#This Row],[SchoolCodes]]),1,0),IF(PAYSCALES[[#This Row],[AvailableToAllSchools]]=TRUE,IF(ISBLANK(PAYSCALES[[#This Row],[SchoolCodes]]),0,1))) -> 0 | C7: {=IF(PAYSCALES[[#This Row],[AvailableToAllSchools]]=TRUE,0,COUNTA(_xlfn.TEXTSPLIT(PAYSCALES[[#This Row],[SchoolCodes]],",",,TRUE))-SUM(COUNTIF(SCHOOLS[SchoolCode],_xlfn.TEXTSPLIT(PAYSCALES[[#This Row],[SchoolCodes]],",",,TRUE))))} -> 0 | D7: =IF(OR(PAYSCALES[[#This Row],[PayScaleEnabled]]=TRUE,PAYSCALES[[#This Row],[PayScaleEnabled]]=FALSE),IF(OR(PAYSCALES[[#This Row],[ServiceIncrementDateEnabled]]=TRUE,PAYSCALES[[#This Row],[ServiceIncrementDateEnabled]]=FALSE),IF(OR(PAYSCALES[[#This Row],[AvailableToAllSchools]]=TRUE,PAYSCALES[[#This Row],[AvailableToAllSchools]]=FALSE),IF(OR(PAYSCALES[[#This Row],[ExcludeNationalInsurance]]=TRUE,PAYSCALES[[#This Row],[ExcludeNationalInsurance]]=FALSE),IF(OR(PAYSCALES[[#This Row],[ExcludePension]]=TRUE,PAYSCALES[[#This Row],[ExcludePension]]=FALSE),0,1),1),1),1),1) -> 0 | E7: =IF(LEN(PAYSCALES[[#This Row],[PayScaleCode]])<100,0,1) -> 0 | F7: =IF(LEN(PAYSCALES[[#This Row],[PayScaleTitle]])<100,0,1) -> 0 | G7: =COUNTBLANK(PAYSCALES[[#This Row],[PayScaleCode]:[AvailableToAllSchools]])+COUNTBLANK(PAYSCALES[[#This Row],[PayScaleEnabled]:[ExcludePension]]) -> 0 | H7: =IF(SUBSTITUTE(TEXT(PAYSCALES[[#This Row],[PayScaleCode]],10)," ","")=TEXT(PAYSCALES[[#This Row],[PayScaleCode]],10),0,1) -> 0 | I7: =SUM(PAYSCALES[[#This Row],[Duplicate Scale Code]:[Space in Code]]) -> 0 | J7: Fringe | K7: =PAYSCALES[[#This Row],[IncrementDate]] -> 44440 | L7: =PAYSCALES[[#This Row],[IncreaseDate]] -> 44440 | N7: MAIN_FRI | O7: Teachers Main Fringe | P7: FALSE | Q7: 44440 | R7: 44440 | S7: 2.75 | T7: TRUE | V7: TRUE | W7: FALSE | X7: FALSE
